Workbook

Sheet 2
A1: قطعات تعمیری و ساخته شده | M1: Date | N1: 1405
M2: weeks | N2: 2
B3: نام قطعه | C3: دستگاه / قالب | D3: درخواست کننده | E3: تعداد درخواست | F3: نو ع قطعه | G3: علت ساخت / تعمیر | H3: شماره نامه | I3: کد دستگاه | J3: تاریخ شروع | K3: تاریخ تحویل | L3: مقدار نفر ساعت کار شده | M3: عملیات در حال انجام | N3: هزینه ساخت/تعمیر (تومان)
A4: 1 | B4: محافظ تیغه | C4: برش جمعی عقب ریو | D4: جهان لنت | E4: 19 | F4: جدید | G4: درخواست ساخت | H4: 14046 | J4: 1404/12/19 | L4: =SUMIFS([1]فروردین!$AD$2:$AD$57,[1]فروردین!$C$2:$C$57,"قطعه نو",[1]فروردین!$B$2:$B$57,C4,[1]فروردین!$O$2:$O$57,B4) -> 0 | M4: در حال انجام | N4: =L4*(500000*1.5) -> 0
A5: 2 | B5: تیغه | C5: دستگاه پشم فلز چینی | D5: تولید پشم فلز | E5: 24 | F5: جدید | G5: درخواست ساخت | J5: 1404/12/02 | L5: =SUMIFS([1]فروردین!$AD$2:$AD$57,[1]فروردین!$C$2:$C$57,"قطعه نو",[1]فروردین!$B$2:$B$57,C5,[1]فروردین!$O$2:$O$57,B5) -> 0 | M5: در حال انجام | N5: =L5*(500000*1.5) -> 0
A6: 3 | B6: Blade Holder | C6: دستگاه پشم فلز چینی | D6: تولید پشم فلز | E6: 8 | F6: جدید | G6: درخواست ساخت | H6: 04/د/13047 | J6: 1404/12/02 | L6: =SUMIFS([1]فروردین!$AD$2:$AD$57,[1]فروردین!$C$2:$C$57,"قطعه نو",[1]فروردین!$B$2:$B$57,C6,[1]فروردین!$O$2:$O$57,B6) -> 0 | M6: در حال انجام | N6: =L6*(500000*1.5) -> 0
A7: 4 | B7: فولی | C7: کوره ابزار زنی | D7: جهان لنت | E7: 1 | F7: تعمیری | G7: اصلاح | H7: 15503 | J7: 1405/01/10 | K7: 1404/01/11 | L7: =SUMIFS([1]فروردین!$AD$2:$AD$57,[1]فروردین!$C$2:$C$57,"قطعه تعمیری",[1]فروردین!$B$2:$B$57,C7,[1]فروردین!$O$2:$O$57,B7) -> 0 | M7: تحویل | N7: =L7*(500000*1.5) -> 0
A8: 5 | B8: صفحه آلمینیوم | C8: کوره ابزار زنی | D8: جهان لنت | E8: 1 | F8: تعمیری | G8: اصلاح | H8: 14575 | J8: 1404/01/11 | K8: 1404/01/12 | L8: =SUMIFS([1]فروردین!$AD$2:$AD$57,[1]فروردین!$C$2:$C$57,"قطعه تعمیری",[1]فروردین!$B$2:$B$57,C8,[1]فروردین!$O$2:$O$57,B8) -> 0 | M8: تحویل | N8: =L8*(500000*1.5) -> 0
A9: 6 | B9: Shaft | C9: کوره ابزار زنی | D9: جهان لنت | E9: 1 | F9: تعمیری | G9: اصلاح | H9: 14575 | J9: 1404/01/11 | K9: 1404/01/12 | L9: =SUMIFS([1]فروردین!$AD$2:$AD$57,[1]فروردین!$C$2:$C$57,"قطعه تعمیری",[1]فروردین!$B$2:$B$57,C9,[1]فروردین!$O$2:$O$57,B9) -> 0 | M9: تحویل | N9: =L9*(500000*1.5) -> 0
B10: مجموع | C10: تحویل | D10: جدید | E10: =SUMIFS(E4:E9,F4:F9,D10,M4:M9,M8) -> 0 | I10: Total | J10: جدید | K10: =SUMIFS(E4:E9,F4:F9,J10) -> 51 | L10: =SUM(L4:L9) -> 0 | N10: =SUM(N4:N9) -> 0
D11: تعمیری | E11: =SUMIFS(E4:E9,F4:F9,D11,M4:M9,"تحویل") -> 3 | J11: تعمیری | K11: =SUMIFS(E5:E10,F5:F10,J11) -> 3

Sheet 3
A1: قطعات تعمیری و ساخته شده | M1: Date | N1: 1405
M2: weeks | N2: 3
B3: نام قطعه | C3: دستگاه / قالب | D3: درخواست کننده | E3: تعداد درخواست | F3: نو ع قطعه | G3: علت ساخت / تعمیر | H3: شماره نامه | I3: کد دستگاه | J3: تاریخ شروع | K3: تاریخ تحویل | L3: مقدار نفر ساعت کار شده | M3: عملیات در حال انجام | N3: هزینه ساخت/تعمیر (تومان)
A4: 1 | B4: محافظ تیغه | C4: برش جمعی عقب ریو | D4: جهان لنت | E4: 19 | F4: جدید | G4: درخواست ساخت | H4: 14046 | J4: 1404/12/19 | L4: =SUMIFS([1]فروردین!$AD$27:$AD$175,[1]فروردین!$C$27:$C$175,"قطعه نو",[1]فروردین!$B$27:$B$175,C4,[1]فروردین!$O$27:$O$175,B4) -> 0 | M4: در حال انجام | N4: =L4*(500000*1.5) -> 0
A5: 2 | B5: Shaft | C5: برش جمعی عقب ریو | D5: جهان لنت | E5: 1 | F5: جدید | G5: درخواست ساخت | H5: 14046 | J5: 1404/12/19 | L5: =SUMIFS([1]فروردین!$AD$27:$AD$175,[1]فروردین!$C$27:$C$175,"قطعه نو",[1]فروردین!$B$27:$B$175,C5,[1]فروردین!$O$27:$O$175,B5) -> 0 | M5: در حال انجام | N5: =L5*(500000*1.5) -> 0
A6: 3 | B6: بوش | C6: برش جمعی عقب ریو | D6: جهان لنت | E6: 1 | F6: جدید | G6: درخواست ساخت | H6: 14046 | J6: 1404/12/19 | L6: =SUMIFS([1]فروردین!$AD$27:$AD$175,[1]فروردین!$C$27:$C$175,"قطعه نو",[1]فروردین!$B$27:$B$175,C6,[1]فروردین!$O$27:$O$175,B6) -> 0 | M6: در حال انجام | N6: =L6*(500000*1.5) -> 0
A7: 4 | B7: برش جمعی | C7: برش جمعی عقب ریو | D7: جهان لنت | E7: 1 | F7: جدید | G7: درخواست ساخت | H7: 14046 | J7: 1404/12/19 | L7: =SUMIFS([1]فروردین!$AD$27:$AD$175,[1]فروردین!$C$27:$C$175,"قطعه نو",[1]فروردین!$B$27:$B$175,C7,[1]فروردین!$O$27:$O$175,B7) -> 0 | M7: در حال انجام | N7: =L7*(500000*1.5) -> 0
A8: 5 | B8: Shaft | C8: دستگاه پرس پخت | D8: نت/جهان لنت | E8: 1 | F8: جدید | G8: شکستن شافت | H8: 14591 | I8: 2064 | J8: 1405/02/18 | K8: 1405/02/19 | L8: =SUMIFS([1]فروردین!$AD$27:$AD$175,[1]فروردین!$C$27:$C$175,"قطعه نو",[1]فروردین!$B$27:$B$175,C8,[1]فروردین!$O$27:$O$175,B8) -> 0 | M8: تحویل | N8: =L8*(500000*1.5) -> 0
A9: 6 | B9: مهره | C9: دستگاه پرس پخت | D9: نت/جهان لنت | E9: 1 | F9: جدید | G9: شکستن شافت | H9: 14591 | I9: 2064 | J9: 1405/02/18 | K9: 1405/02/19 | L9: =SUMIFS([1]فروردین!$AD$27:$AD$175,[1]فروردین!$C$27:$C$175,"قطعه نو",[1]فروردین!$B$27:$B$175,C9,[1]فروردین!$O$27:$O$175,B9) -> 0 | M9: تحویل | N9: =L9*(500000*1.5) -> 0
A10: 7 | B10: whell | C10: دستگاه پشم فلز آلمانی | D10: تولید پشم فلز | E10: 1 | F10: جدید | G10: درخواست ساخت | H10: 04/د/13047 | J10: 1404/12/02 | L10: =SUMIFS([1]فروردین!$AD$27:$AD$175,[1]فروردین!$C$27:$C$175,"قطعه نو",[1]فروردین!$B$27:$B$175,C10,[1]فروردین!$O$27:$O$175,B10) -> 0 | M10: در حال انجام | N10: =L10*(500000*1.5) -> 0
A11: 8 | B11: mahak | C11: دستگاه پشم فلز آلمانی | D11: تولید پشم فلز | E11: 1 | F11: جدید | G11: درخواست ساخت | H11: 04/د/13047 | J11: 1404/12/02 | L11: =SUMIFS([1]فروردین!$AD$27:$AD$175,[1]فروردین!$C$27:$C$175,"قطعه نو",[1]فروردین!$B$27:$B$175,C11,[1]فروردین!$O$27:$O$175,B11) -> 0 | M11: در حال انجام | N11: =L11*(500000*1.5) -> 0
A12: 9 | B12: تفلن | C12: دستگاه پشم فلز آلمانی | D12: تولید پشم فلز | E12: 1 | F12: جدید | G12: درخواست ساخت | H12: 04/د/13047 | J12: 1404/12/02 | L12: =SUMIFS([1]فروردین!$AD$27:$AD$175,[1]فروردین!$C$27:$C$175,"قطعه نو",[1]فروردین!$B$27:$B$175,C12,[1]فروردین!$O$27:$O$175,B12) -> 0 | M12: در حال انجام | N12: =L12*(500000*1.5) -> 0
A13: 10 | B13: تیغه بند | C13: دستگاه پشم فلز آلمانی | D13: تولید پشم فلز | E13: 4 | F13: جدید | G13: درخواست ساخت | H13: 04/د/13047 | J13: 1404/12/02 | L13: =SUMIFS([1]فروردین!$AD$27:$AD$175,[1]فروردین!$C$27:$C$175,"قطعه نو",[1]فروردین!$B$27:$B$175,C13,[1]فروردین!$O$27:$O$175,B13) -> 0 | M13: در حال انجام | N13: =L13*(500000*1.5) -> 0
A14: 11 | B14: تیغه | C14: دستگاه پشم فلز چینی | D14: تولید پشم فلز | E14: 4 | F14: جدید | G14: درخواست ساخت | H14: 04/د/13047 | J14: 1404/12/02 | L14: =SUMIFS([1]فروردین!$AD$27:$AD$175,[1]فروردین!$C$27:$C$175,"قطعه نو",[1]فروردین!$B$27:$B$175,C14,[1]فروردین!$O$27:$O$175,B14) -> 0 | M14: در حال انجام | N14: =L14*(500000*1.5) -> 0
A15: 12 | B15: Blade Holder | C15: دستگاه پشم فلز چینی | D15: تولید پشم فلز | E15: 3 | F15: جدید | G15: درخواست ساخت | H15: 04/د/13047 | J15: 1404/12/02 | L15: =SUMIFS([1]فروردین!$AD$27:$AD$175,[1]فروردین!$C$27:$C$175,"قطعه نو",[1]فروردین!$B$27:$B$175,C15,[1]فروردین!$O$27:$O$175,B15) -> 0 | M15: در حال انجام | N15: =L15*(500000*1.5) -> 0
A16: 13 | B16: چوبی | C16: شابلون پراید بی خار | D16: جهان لنت | E16: 1 | F16: جدید | G16: درخواست ساخت | J16: 1404/12/23 | L16: =SUMIFS([1]فروردین!$AD$27:$AD$175,[1]فروردین!$C$27:$C$175,"قطعه نو",[1]فروردین!$B$27:$B$175,C16,[1]فروردین!$O$27:$O$175,B16) -> 0 | M16: در حال انجام | N16: =L16*(500000*1.5) -> 0
A17: 14 | B17: شابلون | C17: شابلون پراید خاردار | D17: جهان لنت | E17: 1 | F17: جدید | G17: درخواست ساخت | J17: 1404/12/23 | K17: 1405/01/20 | L17: =SUMIFS([1]فروردین!$AD$27:$AD$175,[1]فروردین!$C$27:$C$175,"قطعه نو",[1]فروردین!$B$27:$B$175,C17,[1]فروردین!$O$27:$O$175,B17) -> 0 | M17: تحویل | N17: =L17*(500000*1.5) -> 0
A18: 15 | B18: weaving wheal | C18: ویوینگ | D18: جهان ترمز | E18: 1 | F18: جدید | G18: درخواست ساخت | J18: 1405/01/15 | L18: =SUMIFS([1]فروردین!$AD$27:$AD$175,[1]فروردین!$C$27:$C$175,"قطعه نو",[1]فروردین!$B$27:$B$175,C18,[1]فروردین!$O$27:$O$175,B18) -> 0 | M18: در حال انجام | N18: =L18*(500000*1.5) -> 0
A19: 16 | B19: تفلون | C19: ابزار زنی | D19: جهان لنت | E19: 1 | F19: تعمیری | G19: خرابی | H19: 15027 | J19: 1405/01/18 | L19: =SUMIFS([1]فروردین!$AD$27:$AD$175,[1]فروردین!$C$27:$C$175,"قطعه تعمیری",[1]فروردین!$B$27:$B$175,C19,[1]فروردین!$O$27:$O$175,B19) -> 0 | M19: در حال انجام | N19: =L19*(500000*1.5) -> 0
A20: 17 | B20: صفحه کفی | C20: دستگاه پرس پخت کلاچ | D20: جهان ترمز | E20: 1 | F20: تعمیری | G20: نیاز به سوراخکاری و قلاویز | H20: 14593 | J20: 1405/01/19 | K20: 1405/01/20 | L20: =SUMIFS([1]فروردین!$AD$27:$AD$175,[1]فروردین!$C$27:$C$175,"قطعه تعمیری",[1]فروردین!$B$27:$B$175,C20,[1]فروردین!$O$27:$O$175,B20) -> 0 | M20: تحویل | N20: =L20*(500000*1.5) -> 0
A21: 18 | B21: Shaft | C21: دستگاه پشم فلز آلمانی | D21: تولید پشم فلز | E21: 1 | F21: تعمیری | G21: جوشکاری | J21: 1405/01/20 | K21: 1405/01/20 | L21: =SUMIFS([1]فروردین!$AD$27:$AD$175,[1]فروردین!$C$27:$C$175,"قطعه تعمیری",[1]فروردین!$B$27:$B$175,C21,[1]فروردین!$O$27:$O$175,B21) -> 0 | M21: تحویل | N21: =L21*(500000*1.5) -> 0
A22: 19 | B22: کمربند | C22: دستگاه پشم فلز آلمانی | D22: تولید پشم فلز | E22: 1 | F22: تعمیری | G22: سوراخکاری و قلاویز | J22: 1405/01/20 | K22: 1405/01/20 | L22: =SUMIFS([1]فروردین!$AD$27:$AD$175,[1]فروردین!$C$27:$C$175,"قطعه تعمیری",[1]فروردین!$B$27:$B$175,C22,[1]فروردین!$O$27:$O$175,B22) -> 0 | M22: تحویل | N22: =L22*(500000*1.5) -> 0
A23: 20 | B23: Shaft | C23: ساب سمباده ای | D23: جهان لنت | E23: 1 | F23: تعمیری | G23: تراش جا بلبرینگ | H23: 15513 | I23: 2512 | J23: 1405/01/15 | K23: 1405/01/20 | L23: =SUMIFS([1]فروردین!$AD$27:$AD$175,[1]فروردین!$C$27:$C$175,"قطعه تعمیری",[1]فروردین!$B$27:$B$175,C23,[1]فروردین!$O$27:$O$175,B23) -> 0 | M23: تحویل | N23: =L23*(500000*1.5) -> 0
A24: 21 | B24: پیچ ساب | C24: ساب سمباده ای | D24: جهان لنت | E24: 1 | F24: تعمیری | G24: اصلاح | H24: 15513 | I24: 2512 | J24: 1405/01/15 | K24: 1405/01/20 | L24: =SUMIFS([1]فروردین!$AD$27:$AD$175,[1]فروردین!$C$27:$C$175,"قطعه تعمیری",[1]فروردین!$B$27:$B$175,C24,[1]فروردین!$O$27:$O$175,B24) -> 0 | M24: تحویل | N24: =L24*(500000*1.5) -> 0
A25: 22 | B25: توپی | C25: ساب سمباده ای | D25: جهان لنت | E25: 1 | F25: تعمیری | G25: اصلاح | H25: 15513 | I25: 2512 | J25: 1405/01/15 | K25: 1405/01/20 | L25: =SUMIFS([1]فروردین!$AD$27:$AD$175,[1]فروردین!$C$27:$C$175,"قطعه تعمیری",[1]فروردین!$B$27:$B$175,C25,[1]فروردین!$O$27:$O$175,B25) -> 0 | M25: تحویل | N25: =L25*(500000*1.5) -> 0
A26: 23 | B26: Shaft | C26: کوره ابزار زنی | D26: جهان لنت | E26: 1 | F26: تعمیری | G26: اصلاح | H26: 14575 | J26: 1405/01/15 | K26: 1405/01/16 | L26: =SUMIFS([1]فروردین!$AD$27:$AD$175,[1]فروردین!$C$27:$C$175,"قطعه تعمیری",[1]فروردین!$B$27:$B$175,C26,[1]فروردین!$O$27:$O$175,B26) -> 0 | M26: تحویل | N26: =L26*(500000*1.5) -> 0
A27: 24 | B27: فولی | C27: همزن آغشته کاری | D27: جهان ترمز | E27: 1 | F27: تعمیری | G27: اصلاح | H27: 14594 | I27: 6508 | J27: 1405/01/19 | K27: 1405/01/20 | L27: =SUMIFS([1]فروردین!$AD$27:$AD$175,[1]فروردین!$C$27:$C$175,"قطعه تعمیری",[1]فروردین!$B$27:$B$175,C27,[1]فروردین!$O$27:$O$175,B27) -> 0 | M27: تحویل | N27: =L27*(500000*1.5) -> 0
A28: 25 | B28: Shaft | C28: همزن آغشته کاری | D28: جهان ترمز | E28: 1 | F28: تعمیری | G28: اصلاح | H28: 14594 | I28: 6508 | J28: 1405/01/19 | K28: 1405/01/20 | L28: =SUMIFS([1]فروردین!$AD$27:$AD$175,[1]فروردین!$C$27:$C$175,"قطعه تعمیری",[1]فروردین!$B$27:$B$175,C28,[1]فروردین!$O$27:$O$175,B28) -> 0 | M28: تحویل | N28: =L28*(500000*1.5) -> 0
A29: 26 | B29: weaving wheal | C29: ویوینگ | D29: جهان ترمز | E29: 1 | F29: تعمیری | G29: اصلاح | J29: 1405/01/17 | L29: =SUMIFS([1]فروردین!$AD$27:$AD$175,[1]فروردین!$C$27:$C$175,"قطعه تعمیری",[1]فروردین!$B$27:$B$175,C29,[1]فروردین!$O$27:$O$175,B29) -> 0 | M29: در حال انجام | N29: =L29*(500000*1.5) -> 0
A30: 27 | B30: تیغه | C30: ویوینگ | D30: جهان ترمز | E30: 1 | F30: تعمیری | G30: اصلاح | J30: 1405/01/17 | L30: =SUMIFS([1]فروردین!$AD$27:$AD$175,[1]فروردین!$C$27:$C$175,"قطعه تعمیری",[1]فروردین!$B$27:$B$175,C30,[1]فروردین!$O$27:$O$175,B30) -> 0 | M30: در حال انجام | N30: =L30*(500000*1.5) -> 0
B31: مجموع | C31: تحویل | D31: جدید | E31: =SUMIFS(E4:E30,F4:F30,D31,M4:M30,"تحویل") -> 3 | I31: Total | J31: جدید | K31: =SUMIFS(E4:E30,F4:F30,J31) -> 41 | L31: =SUM(L4:L30) -> 0 | N31: =SUM(N4:N30) -> 0
D32: تعمیری | E32: =SUMIFS(E4:E30,F4:F30,D32,M4:M30,"تحویل") -> 9 | J32: تعمیری | K32: =SUMIFS(E5:E31,F5:F31,J32) -> 12

Sheet 4
A1: قطعات تعمیری و ساخته شده | M1: Date | N1: 1405
M2: weeks | N2: 4
B3: نام قطعه | C3: دستگاه / قالب | D3: درخواست کننده | E3: تعداد درخواست | F3: نو ع قطعه | G3: علت ساخت / تعمیر | H3: شماره نامه | I3: کد دستگاه | J3: تاریخ شروع | K3: تاریخ تحویل | L3: مقدار نفر ساعت کار شده | M3: عملیات در حال انجام | N3: هزینه ساخت/تعمیر (تومان)
A4: 1 | B4: محافظ تیغه | C4: برش جمعی عقب ریو | D4: جهان لنت | E4: 19 | F4: جدید | G4: درخواست ساخت | H4: 14046 | J4: 1404/12/19 | L4: =SUMIFS([1]فروردین!$AD$176:$AD$361,[1]فروردین!$C$176:$C$361,"قطعه نو",[1]فروردین!$B$176:$B$361,C4,[1]فروردین!$O$176:$O$361,B4) -> 0 | M4: در حال انجام | N4: =L4*(500000*1.5) -> 0
A5: 2 | B5: بوش | C5: برش جمعی عقب ریو | D5: جهان لنت | E5: 1 | F5: جدید | G5: درخواست ساخت | H5: 14046 | J5: 1404/12/19 | L5: =SUMIFS([1]فروردین!$AD$176:$AD$361,[1]فروردین!$C$176:$C$361,"قطعه نو",[1]فروردین!$B$176:$B$361,C5,[1]فروردین!$O$176:$O$361,B5) -> 0 | M5: در حال انجام | N5: =L5*(500000*1.5) -> 0
A6: 3 | B6: برش جمعی | C6: برش جمعی عقب ریو | D6: جهان لنت | E6: 1 | F6: جدید | G6: درخواست ساخت | H6: 14046 | J6: 1404/12/19 | L6: =SUMIFS([1]فروردین!$AD$176:$AD$361,[1]فروردین!$C$176:$C$361,"قطعه نو",[1]فروردین!$B$176:$B$361,C6,[1]فروردین!$O$176:$O$361,B6) -> 0 | M6: در حال انجام | N6: =L6*(500000*1.5) -> 0
A7: 4 | B7: پولکی | C7: برش جمعی عقب ریو | D7: جهان لنت | E7: 4 | F7: جدید | G7: درخواست ساخت | H7: 14046 | J7: 1404/12/19 | L7: =SUMIFS([1]فروردین!$AD$176:$AD$361,[1]فروردین!$C$176:$C$361,"قطعه نو",[1]فروردین!$B$176:$B$361,C7,[1]فروردین!$O$176:$O$361,B7) -> 0 | M7: در حال انجام | N7: =L7*(500000*1.5) -> 0
A8: 5 | B8: پین برلیانس | C8: پین برلیانس | D8: برنامه ریزی تولید | E8: 1 | F8: جدید | G8: درخواست ساخت | J8: 1405/01/24 | L8: =SUMIFS([1]فروردین!$AD$176:$AD$361,[1]فروردین!$C$176:$C$361,"قطعه نو",[1]فروردین!$B$176:$B$361,C8,[1]فروردین!$O$176:$O$361,B8) -> 0 | M8: در حال انجام | N8: =L8*(500000*1.5) -> 0
A9: 6 | B9: جک | C9: دستگاه پرس پخت | D9: جهان ترمز | E9: 1 | F9: جدید | G9: درخواست ساخت | H9: 15528 | I9: 2024 | J9: 1405/01/22 | K9: 1405/01/22 | L9: =SUMIFS([1]فروردین!$AD$176:$AD$361,[1]فروردین!$C$176:$C$361,"قطعه نو",[1]فروردین!$B$176:$B$361,C9,[1]فروردین!$O$176:$O$361,B9) -> 0 | M9: تحویل | N9: =L9*(500000*1.5) -> 0
A10: 7 | B10: مهره | C10: دستگاه پرس پخت | D10: جهان ترمز | E10: 1 | F10: جدید | G10: درخواست ساخت | H10: 15528 | I10: 2024 | J10: 1405/01/22 | K10: 1405/01/22 | L10: =SUMIFS([1]فروردین!$AD$176:$AD$361,[1]فروردین!$C$176:$C$361,"قطعه نو",[1]فروردین!$B$176:$B$361,C10,[1]فروردین!$O$176:$O$361,B10) -> 0 | M10: تحویل | N10: =L10*(500000*1.5) -> 0
A11: 8 | B11: تیغه بند | C11: دستگاه پشم فلز آلمانی | D11: تولید پشم فلز | E11: 4 | F11: جدید | G11: درخواست ساخت | H11: 04/د/13047 | J11: 1404/12/02 | L11: =SUMIFS([1]فروردین!$AD$176:$AD$361,[1]فروردین!$C$176:$C$361,"قطعه نو",[1]فروردین!$B$176:$B$361,C11,[1]فروردین!$O$176:$O$361,B11) -> 0 | M11: در حال انجام | N11: =L11*(500000*1.5) -> 0
A12: 9 | B12: main Blead Shaft | C12: دستگاه پشم فلز آلمانی | D12: تولید پشم فلز | E12: 4 | F12: جدید | G12: درخواست ساخت | H12: 04/د/13047 | J12: 1404/12/02 | L12: =SUMIFS([1]فروردین!$AD$176:$AD$361,[1]فروردین!$C$176:$C$361,"قطعه نو",[1]فروردین!$B$176:$B$361,C12,[1]فروردین!$O$176:$O$361,B12) -> 0 | M12: در حال انجام | N12: =L12*(500000*1.5) -> 0
A13: 10 | B13: اسپرینگ | C13: دستگاه پشم فلز آلمانی | D13: تولید پشم فلز | E13: 1 | F13: جدید | G13: درخواست ساخت | H13: 04/د/13047 | J13: 1404/12/02 | L13: =SUMIFS([1]فروردین!$AD$176:$AD$361,[1]فروردین!$C$176:$C$361,"قطعه نو",[1]فروردین!$B$176:$B$361,C13,[1]فروردین!$O$176:$O$361,B13) -> 0 | M13: در حال انجام | N13: =L13*(500000*1.5) -> 0
A14: 11 | B14: Blade Holder | C14: دستگاه پشم فلز چینی | D14: تولید پشم فلز | E14: 4 | F14: جدید | G14: درخواست ساخت | H14: 04/د/13047 | J14: 1404/12/02 | L14: =SUMIFS([1]فروردین!$AD$176:$AD$361,[1]فروردین!$C$176:$C$361,"قطعه نو",[1]فروردین!$B$176:$B$361,C14,[1]فروردین!$O$176:$O$361,B14) -> 0 | M14: در حال انجام | N14: =L14*(500000*1.5) -> 0
A15: 12 | B15: تیغه | C15: دستگاه پشم فلز چینی | D15: تولید پشم فلز | E15: 3 | F15: جدید | G15: درخواست ساخت | H15: 04/د/13047 | J15: 1404/12/02 | L15: =SUMIFS([1]فروردین!$AD$176:$AD$361,[1]فروردین!$C$176:$C$361,"قطعه نو",[1]فروردین!$B$176:$B$361,C15,[1]فروردین!$O$176:$O$361,B15) -> 0 | M15: در حال انجام | N15: =L15*(500000*1.5) -> 0
A16: 13 | B16: توپی | C16: دستگاه ساب سمباده ای | D16: جهان لنت | E16: 1 | F16: جدید | G16: درخواست ساخت | J16: 1405/01/26 | K16: 1405/01/27 | L16: =SUMIFS([1]فروردین!$AD$176:$AD$361,[1]فروردین!$C$176:$C$361,"قطعه نو",[1]فروردین!$B$176:$B$361,C16,[1]فروردین!$O$176:$O$361,B16) -> 0 | M16: تحویل | N16: =L16*(500000*1.5) -> 0
A17: 14 | B17: Bush | C17: دستگاه کشش پشم فلز | D17: تولید پشم فلز | E17: 1 | F17: جدید | G17: ساخت بوش یاتاقان | H17: 14596 | J17: 1405/01/23 | K17: 1405/01/25 | L17: =SUMIFS([1]فروردین!$AD$176:$AD$361,[1]فروردین!$C$176:$C$361,"قطعه نو",[1]فروردین!$B$176:$B$361,C17,[1]فروردین!$O$176:$O$361,B17) -> 0 | M17: تحویل | N17: =L17*(500000*1.5) -> 0
A18: 15 | B18: کاسه رنگ | C18: دستگاه مهر زنی | D18: جهان ترمز | E18: 2 | F18: جدید | G18: خرابی نگهدارنده | H18: 15413 | I18: 4203 4204 | J18: 1405/01/24 | L18: =SUMIFS([1]فروردین!$AD$176:$AD$361,[1]فروردین!$C$176:$C$361,"قطعه نو",[1]فروردین!$B$176:$B$361,C18,[1]فروردین!$O$176:$O$361,B18) -> 0 | M18: در حال انجام | N18: =L18*(500000*1.5) -> 0
A19: 16 | B19: پیچ راهنما | C19: ویوینگ | D19: جهان ترمز | E19: 1 | F19: جدید | G19: خرابی | H19: 14597 | I19: 6404 | J19: 1405/01/23 | K19: 1405/01/25 | L19: =SUMIFS([1]فروردین!$AD$176:$AD$361,[1]فروردین!$C$176:$C$361,"قطعه نو",[1]فروردین!$B$176:$B$361,C19,[1]فروردین!$O$176:$O$361,B19) -> 0 | M19: تحویل | N19: =L19*(500000*1.5) -> 0
A20: 17 | B20: Shaft | C20: ویوینگ | D20: جهان ترمز | E20: 1 | F20: جدید | G20: خرابی | H20: 14597 | I20: 6404 | J20: 1405/01/23 | K20: 1405/01/25 | L20: =SUMIFS([1]فروردین!$AD$176:$AD$361,[1]فروردین!$C$176:$C$361,"قطعه نو",[1]فروردین!$B$176:$B$361,C20,[1]فروردین!$O$176:$O$361,B20) -> 0 | M20: تحویل | N20: =L20*(500000*1.5) -> 0
A21: 18 | B21: bush | C21: ویوینگ | D21: جهان ترمز | E21: 1 | F21: جدید | G21: خرابی | H21: 14597 | I21: 6404 | J21: 1405/01/23 | K21: 1405/01/25 | L21: =SUMIFS([1]فروردین!$AD$176:$AD$361,[1]فروردین!$C$176:$C$361,"قطعه نو",[1]فروردین!$B$176:$B$361,C21,[1]فروردین!$O$176:$O$361,B21) -> 0 | M21: تحویل | N21: =L21*(500000*1.5) -> 0
A22: 19 | B22: فیکسچر | C22: دریل سوراخکاری کلاچ | D22: جهان ترمز | E22: 1 | F22: تعمیری | G22: اصلاح | H22: 14598 | J22: 1405/01/26 | K22: 1405/01/26 | L22: =SUMIFS([1]فروردین!$AD$176:$AD$361,[1]فروردین!$C$176:$C$361,"قطعه تعمیری",[1]فروردین!$B$176:$B$361,C22,[1]فروردین!$O$176:$O$361,B22) -> 0 | M22: تحویل | N22: =L22*(500000*1.5) -> 0
A23: 20 | B23: دستگاه برش | C23: دستگاه آسیاب پرت کلاچ | D23: آزمایشگاه | E23: 1 | F23: تعمیری | G23: اصلاح | H23: 12686 | J23: 1405/01/27 | K23: 1405/01/27 | L23: =SUMIFS([1]فروردین!$AD$176:$AD$361,[1]فروردین!$C$176:$C$361,"قطعه تعمیری",[1]فروردین!$B$176:$B$361,C23,[1]فروردین!$O$176:$O$361,B23) -> 0 | M23: تحویل | N23: =L23*(500000*1.5) -> 0
A24: 21 | B24: کفی پخت | C24: دستگاه پخت کلاچ | D24: جهان ترمز | E24: 1 | F24: تعمیری | G24: اصلاح | H24: 14599 | I24: 2070 | J24: 1405/01/26 | K24: 1405/01/27 | L24: =SUMIFS([1]فروردین!$AD$176:$AD$361,[1]فروردین!$C$176:$C$361,"قطعه تعمیری",[1]فروردین!$B$176:$B$361,C24,[1]فروردین!$O$176:$O$361,B24) -> 0 | M24: تحویل | N24: =L24*(500000*1.5) -> 0
A25: 22 | B25: Shaft | C25: دستگاه پرچ زنی | D25: جهان لنت | E25: 1 | F25: تعمیری | G25: درآوردن جای پیچ زیر قالبی | J25: 1405/01/22 | K25: 1405/01/22 | L25: =SUMIFS([1]فروردین!$AD$176:$AD$361,[1]فروردین!$C$176:$C$361,"قطعه تعمیری",[1]فروردین!$B$176:$B$361,C25,[1]فروردین!$O$176:$O$361,B25) -> 0 | M25: تحویل | N25: =L25*(500000*1.5) -> 0
A26: 23 | B26: لنت | C26: دستگاه پرس 250 تن | D26: جهان لنت | E26: 32 | F26: تعمیری | G26: سایز کردن | H26: 14600 | J26: 1405/01/26 | K26: 1405/01/27 | L26: =SUMIFS([1]فروردین!$AD$176:$AD$361,[1]فروردین!$C$176:$C$361,"قطعه تعمیری",[1]فروردین!$B$176:$B$361,C26,[1]فروردین!$O$176:$O$361,B26) -> 0 | M26: تحویل | N26: =L26*(500000*1.5) -> 0
A27: 24 | B27: فنر | C27: دستگاه پرس 250 تن | D27: جهان لنت | E27: 1 | F27: تعمیری | G27: اصلاح | H27: 15542 | J27: 1405/01/27 | L27: =SUMIFS([1]فروردین!$AD$176:$AD$361,[1]فروردین!$C$176:$C$361,"قطعه تعمیری",[1]فروردین!$B$176:$B$361,C27,[1]فروردین!$O$176:$O$361,B27) -> 0 | M27: در حال انجام | N27: =L27*(500000*1.5) -> 0
A28: 25 | B28: نگهدارنده فنر | C28: دستگاه پرس 250 تن | D28: جهان لنت | E28: 1 | F28: تعمیری | G28: اصلاح | H28: 15542 | J28: 1405/01/27 | L28: =SUMIFS([1]فروردین!$AD$176:$AD$361,[1]فروردین!$C$176:$C$361,"قطعه تعمیری",[1]فروردین!$B$176:$B$361,C28,[1]فروردین!$O$176:$O$361,B28) -> 0 | M28: در حال انجام | N28: =L28*(500000*1.5) -> 0
A29: 26 | B29: Shaft | C29: دستگاه پرس 250 تن | D29: جهان لنت | E29: 1 | F29: تعمیری | G29: اصلاح | H29: 15542 | J29: 1405/01/27 | L29: =SUMIFS([1]فروردین!$AD$176:$AD$361,[1]فروردین!$C$176:$C$361,"قطعه تعمیری",[1]فروردین!$B$176:$B$361,C29,[1]فروردین!$O$176:$O$361,B29) -> 0 | M29: در حال انجام | N29: =L29*(500000*1.5) -> 0
A30: 27 | B30: کمربند | C30: دستگاه پشم فلز آلمانی | D30: تولید پشم فلز | E30: 1 | F30: تعمیری | G30: سوراخکاری و قلاویز | J30: 1405/01/22 | K30: 1405/01/22 | L30: =SUMIFS([1]فروردین!$AD$176:$AD$361,[1]فروردین!$C$176:$C$361,"قطعه تعمیری",[1]فروردین!$B$176:$B$361,C30,[1]فروردین!$O$176:$O$361,B30) -> 0 | M30: تحویل | N30: =L30*(500000*1.5) -> 0
A31: 28 | B31: main Blead Shaft | C31: دستگاه پشم فلز آلمانی | D31: تولید پشم فلز | E31: 1 | F31: تعمیری | G31: سوراخکاری و قلاویز | J31: 1405/01/22 | K31: 1405/01/23 | L31: =SUMIFS([1]فروردین!$AD$176:$AD$361,[1]فروردین!$C$176:$C$361,"قطعه تعمیری",[1]فروردین!$B$176:$B$361,C31,[1]فروردین!$O$176:$O$361,B31) -> 0 | M31: تحویل | N31: =L31*(500000*1.5) -> 0
A32: 29 | B32: تیغه | C32: دستگاه تسمه کش | D32: جهان ترمز | E32: 1 | F32: تعمیری | G32: اصلاح | H32: 14595 | J32: 1405/01/22 | K32: 1405/01/27 | L32: =SUMIFS([1]فروردین!$AD$176:$AD$361,[1]فروردین!$C$176:$C$361,"قطعه تعمیری",[1]فروردین!$B$176:$B$361,C32,[1]فروردین!$O$176:$O$361,B32) -> 0 | M32: تحویل | N32: =L32*(500000*1.5) -> 0
A33: 30 | B33: Shaft | C33: دستگاه ساب دیسکی چینی | D33: جهان لنت | E33: 1 | F33: تعمیری | G33: اصلاح | H33: 15541 | J33: 1405/01/26 | K33: 1405/01/27 | L33: =SUMIFS([1]فروردین!$AD$176:$AD$361,[1]فروردین!$C$176:$C$361,"قطعه تعمیری",[1]فروردین!$B$176:$B$361,C33,[1]فروردین!$O$176:$O$361,B33) -> 0 | M33: تحویل | N33: =L33*(500000*1.5) -> 0
A34: 31 | B34: میز | C34: ساب سمباده ای | D34: جهان ترمز | E34: 1 | F34: تعمیری | G34: موجدار شدن کف میز | H34: 15410 | I34: 2905 | J34: 1405/01/24 | L34: =SUMIFS([1]فروردین!$AD$176:$AD$361,[1]فروردین!$C$176:$C$361,"قطعه تعمیری",[1]فروردین!$B$176:$B$361,C34,[1]فروردین!$O$176:$O$361,B34) -> 0 | M34: در حال انجام | N34: =L34*(500000*1.5) -> 0
A35: 32 | B35: فلانچ | C35: قالب خشاب زنی | D35: جهان ترمز | E35: 20 | F35: تعمیری | G35: اصلاح جا فنر | J35: 1405/01/26 | L35: =SUMIFS([1]فروردین!$AD$176:$AD$361,[1]فروردین!$C$176:$C$361,"قطعه تعمیری",[1]فروردین!$B$176:$B$361,C35,[1]فروردین!$O$176:$O$361,B35) -> 0 | M35: در حال انجام | N35: =L35*(500000*1.5) -> 0
A36: 33 | B36: قلم | C36: قلم پین برلیانس | D36: تراشکاری | E36: 1 | F36: تعمیری | G36: اصلاح | I36: 8002 | J36: 1405/01/22 | K36: 1405/01/22 | L36: =SUMIFS([1]فروردین!$AD$176:$AD$361,[1]فروردین!$C$176:$C$361,"قطعه تعمیری",[1]فروردین!$B$176:$B$361,C36,[1]فروردین!$O$176:$O$361,B36) -> 0 | M36: تحویل | N36: =L36*(500000*1.5) -> 0
A37: 34 | B37: فولی | C37: همزن آغشته کاری | D37: جهان ترمز | E37: 1 | F37: تعمیری | G37: تراش شافت ... | H37: 14594 | I37: 6508 | J37: 1405/01/22 | K37: 1405/01/22 | L37: =SUMIFS([1]فروردین!$AD$176:$AD$361,[1]فروردین!$C$176:$C$361,"قطعه تعمیری",[1]فروردین!$B$176:$B$361,C37,[1]فروردین!$O$176:$O$361,B37) -> 0 | M37: تحویل | N37: =L37*(500000*1.5) -> 0
A38: 35 | B38: روتور | C38: هواکش | D38: جهان لنت | E38: 2 | F38: تعمیری | G38: اصلاح ... | H38: 15530 | J38: 1405/01/22 | K38: 1405/01/22 | L38: =SUMIFS([1]فروردین!$AD$176:$AD$361,[1]فروردین!$C$176:$C$361,"قطعه تعمیری",[1]فروردین!$B$176:$B$361,C38,[1]فروردین!$O$176:$O$361,"*") -> 0 | M38: تحویل | N38: =L38*(500000*1.5) -> 0
B39: مجموع | C39: تحویل | D39: جدید | E39: =SUMIFS(E4:E38,F4:F38,D39,M4:M38,"تحویل") -> 7 | I39: Total | J39: جدید | K39: =SUMIFS(E4:E38,F4:F38,J39) -> 51 | L39: =SUM(L4:L38) -> 0 | N39: =SUM(N4:N38) -> 0
D40: تعمیری | E40: =SUMIFS(E4:E38,F4:F38,D40,M4:M38,"تحویل") -> 44 | J40: تعمیری | K40: =SUMIFS(E5:E39,F5:F39,J40) -> 68

Sheet 5
A1: قطعات تعمیری و ساخته شده | M1: Date | N1: 1405
M2: weeks | N2: 5
B3: نام قطعه | C3: دستگاه / قالب | D3: درخواست کننده | E3: تعداد درخواست | F3: نو ع قطعه | G3: علت ساخت / تعمیر | H3: شماره نامه | I3: کد دستگاه | J3: تاریخ شروع | K3: تاریخ تحویل | L3: مقدار نفر ساعت کار شده | M3: عملیات در حال انجام | N3: هزینه ساخت/تعمیر (تومان)
A4: 1 | B4: main Blead Shaft | C4: دستگاه پشم فلز آلمانی | D4: تولید پشم فلز | E4: 4 | F4: جدید | G4: درخواست ساخت | H4: 04/د/13047 | J4: 1404/12/02 | K4: 1405/02/03 | L4: =SUMIFS([1]فروردین!$AD$282:$AD$400,[1]فروردین!$C$282:$C$400,"قطعه نو",[1]فروردین!$B$282:$B$400,C4,[1]فروردین!$O$282:$O$400,B4) -> 0 | M4: تحویل | N4: =L4*(500000*1.5) -> 0
A5: 2 | B5: تفلن | C5: دستگاه پشم فلز آلمانی | D5: تولید پشم فلز | E5: 2 | F5: جدید | G5: درخواست ساخت | H5: 04/د/13047 | J5: 1404/12/02 | K5: 1405/02/03 | L5: =SUMIFS([1]فروردین!$AD$282:$AD$400,[1]فروردین!$C$282:$C$400,"قطعه نو",[1]فروردین!$B$282:$B$400,C5,[1]فروردین!$O$282:$O$400,B5) -> 0 | M5: تحویل | N5: =L5*(500000*1.5) -> 0
A6: 3 | B6: تیغه | C6: دستگاه پشم فلز آلمانی | D6: تولید پشم فلز | E6: 8 | F6: جدید | G6: درخواست ساخت | H6: 04/د/13047 | J6: 1404/12/02 | L6: =SUMIFS([1]فروردین!$AD$282:$AD$400,[1]فروردین!$C$282:$C$400,"قطعه نو",[1]فروردین!$B$282:$B$400,C6,[1]فروردین!$O$282:$O$400,B6)+37 -> 37 | M6: در حال انجام | N6: =L6*(500000*1.5) -> 27750000
A7: 4 | B7: Bush | C7: دستگاه پشم فلز آلمانی | D7: تولید پشم فلز | E7: 1 | F7: جدید | G7: درخواست ساخت | H7: 04/د/13047 | J7: 1404/12/02 | K7: 1405/02/03 | L7: =SUMIFS([1]فروردین!$AD$282:$AD$400,[1]فروردین!$C$282:$C$400,"قطعه نو",[1]فروردین!$B$282:$B$400,C7,[1]فروردین!$O$282:$O$400,B7)+10 -> 10 | M7: تحویل | N7: =L7*(500000*1.5) -> 7500000
A8: 5 | B8: تیغچه بند | C8: دستگاه پشم فلز چینی | D8: تولید پشم فلز | E8: 4 | F8: جدید | G8: درخواست ساخت | H8: 04/د/13047 | J8: 1404/12/02 | L8: =SUMIFS([1]فروردین!$AD$282:$AD$400,[1]فروردین!$C$282:$C$400,"قطعه نو",[1]فروردین!$B$282:$B$400,C8,[1]فروردین!$O$282:$O$400,B8)+36 -> 36 | M8: در حال انجام | N8: =L8*(500000*1.5) -> 27000000
A9: 6 | B9: main Blead Shaft | C9: دستگاه پشم فلز چینی | D9: تولید پشم فلز | E9: 4 | F9: جدید | G9: درخواست ساخت | H9: 04/د/13048 | J9: 1404/12/03 | L9: =SUMIFS([1]فروردین!$AD$282:$AD$400,[1]فروردین!$C$282:$C$400,"قطعه نو",[1]فروردین!$B$282:$B$400,C9,[1]فروردین!$O$282:$O$400,B9)+2 -> 2 | M9: در حال انجام | N9: =L9*(500000*1.5) -> 1500000
A10: 7 | B10: تیغه | C10: دستگاه پشم فلز چینی | D10: تولید پشم فلز | E10: 8 | F10: جدید | G10: درخواست ساخت | H10: 04/د/13049 | J10: 1404/12/04 | L10: =SUMIFS([1]فروردین!$AD$282:$AD$400,[1]فروردین!$C$282:$C$400,"قطعه نو",[1]فروردین!$B$282:$B$400,C10,[1]فروردین!$O$282:$O$400,B10) -> 0 | M10: در حال انجام | N10: =L10*(500000*1.5) -> 0
A11: 8 | B11: Shaft | C11: ابزار زنی | D11: جهان لنت | E11: 1 | F11: جدید | G11: ساخت SHAFT غلطک | J11: 1405/02/02 | K11: 1405/02/04 | L11: =SUMIFS([1]اردیبهشت!$AD$2:$AD$75,[1]اردیبهشت!$C$2:$C$75,"قطعه نو",[1]اردیبهشت!$B$2:$B$75,C11,[1]اردیبهشت!$O$2:$O$75,B11) -> 0 | M11: تحویل | N11: =L11*(500000*1.5) -> 0
A12: 9 | B12: Shaft | C12: دستگاه پرس 600 تن | D12: جهان لنت | E12: 1 | F12: جدید | G12: ساخت Shaft جک گازگیری | H12: 14579 | J12: 1405/02/02 | K12: 1405/02/04 | L12: =SUMIFS([1]اردیبهشت!$AD$2:$AD$75,[1]اردیبهشت!$C$2:$C$75,"قطعه نو",[1]اردیبهشت!$B$2:$B$75,C12,[1]اردیبهشت!$O$2:$O$75,B12)+3 -> 3 | M12: در حال انجام | N12: =L12*(500000*1.5) -> 2250000
A13: 10 | B13: واسطه سرجک | C13: دستگاه پرس پخت | D13: جهان لنت | E13: 2 | F13: جدید | G13: درخواست ساخت | J13: 1405/02/01 | K13: 1405/02/04 | L13: =SUMIFS([1]اردیبهشت!$AD$2:$AD$75,[1]اردیبهشت!$C$2:$C$75,"قطعه نو",[1]اردیبهشت!$B$2:$B$75,C13,[1]اردیبهشت!$O$2:$O$75,B13) -> 0 | M13: تحویل | N13: =L13*(500000*1.5) -> 0
A14: 11 | B14: بلوکه | C14: دستگاه ساب جدید | D14: جهان لنت | E14: 1 | F14: جدید | G14: درخواست ساخت | J14: 1405/02/01 | K14: 1405/02/04 | L14: =SUMIFS([1]اردیبهشت!$AD$2:$AD$75,[1]اردیبهشت!$C$2:$C$75,"قطعه نو",[1]اردیبهشت!$B$2:$B$75,C14,[1]اردیبهشت!$O$2:$O$75,B14) -> 0 | M14: تحویل | N14: =L14*(500000*1.5) -> 0
A15: 12 | B15: بوش | C15: دستگاه ساب جدید | D15: جهان لنت | E15: 1 | F15: جدید | G15: درخواست ساخت | J15: 1405/02/01 | K15: 1405/02/04 | L15: =SUMIFS([1]اردیبهشت!$AD$2:$AD$75,[1]اردیبهشت!$C$2:$C$75,"قطعه نو",[1]اردیبهشت!$B$2:$B$75,C15,[1]اردیبهشت!$O$2:$O$75,B15) -> 0 | M15: تحویل | N15: =L15*(500000*1.5) -> 0
A16: 13 | B16: Shaft | C16: دستگاه ساب جدید | D16: جهان لنت | E16: 1 | F16: جدید | G16: درخواست ساخت | J16: 1405/02/01 | K16: 1405/02/04 | L16: =SUMIFS([1]اردیبهشت!$AD$2:$AD$75,[1]اردیبهشت!$C$2:$C$75,"قطعه نو",[1]اردیبهشت!$B$2:$B$75,C16,[1]اردیبهشت!$O$2:$O$75,B16) -> 0 | M16: تحویل | N16: =L16*(500000*1.5) -> 0
A17: 14 | B17: Bush | C17: دستگاه شیرینگ | D17: جهان ترمز | E17: 1 | F17: جدید | G17: درخواست ساخت | J17: 1405/02/03 | K17: 1405/02/03 | L17: =SUMIFS([1]اردیبهشت!$AD$2:$AD$75,[1]اردیبهشت!$C$2:$C$75,"قطعه نو",[1]اردیبهشت!$B$2:$B$75,C17,[1]اردیبهشت!$O$2:$O$75,B17) -> 0 | M17: تحویل | N17: =L17*(500000*1.5) -> 0
A18: 15 | B18: تسمه | C18: دستگاه مهر زنی | D18: جهان ترمز | E18: 1 | F18: جدید | G18: خرابی نگهدارنده کاسه | H18: 15413 | J18: 1405/01/24 | K18: 1405/02/01 | L18: =SUMIFS([1]اردیبهشت!$AD$2:$AD$75,[1]اردیبهشت!$C$2:$C$75,"قطعه نو",[1]اردیبهشت!$B$2:$B$75,C18,[1]اردیبهشت!$O$2:$O$75,B18)+30 -> 30 | M18: تحویل | N18: =L18*(500000*1.5) -> 22500000
A19: 16 | B19: U نگهدارنده | C19: ساب کلاچ | D19: جهان ترمز | E19: 20 | F19: جدید | G19: درخواست ساخت | J19: 1405/02/03 | L19: =SUMIFS([1]اردیبهشت!$AD$2:$AD$75,[1]اردیبهشت!$C$2:$C$75,"قطعه نو",[1]اردیبهشت!$B$2:$B$75,C19,[1]اردیبهشت!$O$2:$O$75,B19) -> 0 | M19: در حال انجام | N19: =L19*(500000*1.5) -> 0
A20: 17 | B20: Shaft | C20: ساب کونیک | D20: جهان لنت | E20: 2 | F20: جدید | G20: درخواست ساخت | H20: 15585 | I20: 2501 | J20: 1405/02/03 | K20: 1405/02/04 | L20: =SUMIFS([1]اردیبهشت!$AD$2:$AD$75,[1]اردیبهشت!$C$2:$C$75,"قطعه نو",[1]اردیبهشت!$B$2:$B$75,C20,[1]اردیبهشت!$O$2:$O$75,B20) -> 0 | M20: تحویل | N20: =L20*(500000*1.5) -> 0
A21: 18 | B21: weaving wheal | C21: ویوینگ | D21: جهان ترمز | E21: 1 | F21: جدید | G21: درخواست ساخت | H21: 14580 | I21: 6403 | J21: 1405/01/29 | L21: =SUMIFS([1]اردیبهشت!$AD$2:$AD$75,[1]اردیبهشت!$C$2:$C$75,"قطعه نو",[1]اردیبهشت!$B$2:$B$75,C21,[1]اردیبهشت!$O$2:$O$75,B21)+3 -> 3 | M21: در حال انجام | N21: =L21*(500000*1.5) -> 2250000
A22: 19 | B22: پین برلیانس | C22: پین برلیانس | D22: برنامه ریزی تولید | E22: 2930 | F22: جدید | G22: درخواست ساخت | J22: 1405/01/24 | K22: 1405/02/03 | L22: =SUMIFS([1]فروردین!$AD$282:$AD$400,[1]فروردین!$C$282:$C$400,"قطعه نو",[1]فروردین!$B$282:$B$400,C22,[1]فروردین!$O$282:$O$400,B22) -> 0 | M22: تحویل | N22: =L22*(500000*1.5) -> 0
A23: 20 | B23: پولکی | C23: برش جمعی عقب ریو | D23: جهان لنت | E23: 4 | F23: جدید | G23: درخواست ساخت | H23: 14046 | J23: 1404/12/19 | L23: =SUMIFS([1]فروردین!$AD$282:$AD$400,[1]فروردین!$C$282:$C$400,"قطعه نو",[1]فروردین!$B$282:$B$400,C23,[1]فروردین!$O$282:$O$400,B23) -> 0 | M23: در حال انجام | N23: =L23*(500000*1.5) -> 0
A24: 21 | B24: محافظ تیغه | C24: برش جمعی عقب ریو | D24: جهان لنت | E24: 4 | F24: جدید | G24: درخواست ساخت | H24: 14046 | J24: 1404/12/19 | L24: =SUMIFS([1]فروردین!$AD$282:$AD$400,[1]فروردین!$C$282:$C$400,"قطعه نو",[1]فروردین!$B$282:$B$400,C24,[1]فروردین!$O$282:$O$400,B24) -> 0 | M24: در حال انجام | N24: =L24*(500000*1.5) -> 0
A25: 22 | B25: تیغه | C25: خط مصرف | D25: جهان لنت | E25: 1 | F25: تعمیری | G25: اصلاح تیغه | H25: 15337 | I25: 3001 | J25: 1405/01/29 | K25: 1405/01/29 | L25: =SUMIFS([1]فروردین!$AD$282:$AD$400,[1]فروردین!$C$282:$C$400,"قطعه تعمیری",[1]فروردین!$B$282:$B$400,C25,[1]فروردین!$O$282:$O$400,B25) -> 0 | M25: تحویل | N25: =L25*(500000*1.5) -> 0
A26: 23 | B26: Shaft | C26: دستگاه پشم فلز آلمانی | D26: تولید پشم فلز | E26: 1 | F26: تعمیری | G26: اصلاح شافت 3 متری | J26: 1405/01/31 | L26: =SUMIFS([1]فروردین!$AD$282:$AD$400,[1]فروردین!$C$282:$C$400,"قطعه تعمیری",[1]فروردین!$B$282:$B$400,C26,[1]فروردین!$O$282:$O$400,B26) -> 0 | M26: در حال انجام | N26: =L26*(500000*1.5) -> 0
A27: 24 | B27: Shaft | C27: دستگاه ساب سمباده ای | D27: جهان لنت | E27: 4 | F27: تعمیری | G27: اصلاح شافت | H27: 15651 | I27: 2508 | J27: 1405/01/30 | K27: 1405/02/02 | L27: =SUMIFS([1]فروردین!$AD$282:$AD$400,[1]فروردین!$C$282:$C$400,"قطعه تعمیری",[1]فروردین!$B$282:$B$400,C27,[1]فروردین!$O$282:$O$400,B27) -> 0 | M27: تحویل | N27: =L27*(500000*1.5) -> 0
A28: 25 | B28: جک | C28: دستگاه ساب سمباده ای | D28: جهان لنت | E28: 4 | F28: تعمیری | G28: اصلاح شافت | H28: 15651 | I28: 2508 | J28: 1405/01/30 | K28: 1405/02/02 | L28: =SUMIFS([1]فروردین!$AD$282:$AD$400,[1]فروردین!$C$282:$C$400,"قطعه تعمیری",[1]فروردین!$B$282:$B$400,C28,[1]فروردین!$O$282:$O$400,B28)+1 -> 1 | M28: تحویل | N28: =L28*(500000*1.5) -> 750000
A29: 26 | B29: Shaft | C29: دستگاه کمپرسور باد | D29: جهان ترمز | E29: 2 | F29: تعمیری | G29: اصلاح | H29: 14433 | J29: 1405/01/31 | K29: 1405/02/01 | L29: =SUMIFS([1]فروردین!$AD$282:$AD$400,[1]فروردین!$C$282:$C$400,"قطعه تعمیری",[1]فروردین!$B$282:$B$400,C29,[1]فروردین!$O$282:$O$400,B29) -> 0 | M29: تحویل | N29: =L29*(500000*1.5) -> 0
A30: 27 | B30: Shaft توپی | C30: ساب کونیک | D30: جهان لنت | E30: 1 | F30: تعمیری | G30: اصلاح | H30: 15652 | J30: 1405/01/30 | K30: 1405/01/30 | L30: =SUMIFS([1]فروردین!$AD$282:$AD$400,[1]فروردین!$C$282:$C$400,"قطعه تعمیری",[1]فروردین!$B$282:$B$400,C30,[1]فروردین!$O$282:$O$400,B30) -> 0 | M30: تحویل | N30: =L30*(500000*1.5) -> 0
A31: 28 | B31: فیکسچر | C31: دریل کلاچ | D31: جهان ترمز | E31: 1 | F31: تعمیری | G31: تراش فیکسچر | H31: 14581 | J31: 1405/01/29 | K31: 1405/02/01 | L31: =SUMIFS([1]فروردین!$AD$282:$AD$400,[1]فروردین!$C$282:$C$400,"قطعه تعمیری",[1]فروردین!$B$282:$B$400,C31,[1]فروردین!$O$282:$O$400,B31)+2 -> 2 | M31: تحویل | N31: =L31*(500000*1.5) -> 1500000
A32: 29 | B32: واسطه سر جک | C32: دستگاه پرس پخت | D32: جهان لنت | E32: 2 | F32: تعمیری | G32: اصلاح | J32: 1405/02/02 | K32: 1405/02/02 | L32: =SUMIFS([1]اردیبهشت!$AD$2:$AD$75,[1]اردیبهشت!$C$2:$C$75,"قطعه تعمیری",[1]اردیبهشت!$B$2:$B$75,C32,[1]اردیبهشت!$O$2:$O$75,B32) -> 0 | M32: تحویل | N32: =L32*(500000*1.5) -> 0
A33: 30 | B33: جک | C33: دستگاه ساب سمباده ای | D33: جهان لنت | E33: 1 | F33: تعمیری | G33: اصلاح | J33: 1405/02/02 | K33: 1405/02/02 | L33: =SUMIFS([1]اردیبهشت!$AD$2:$AD$75,[1]اردیبهشت!$C$2:$C$75,"قطعه تعمیری",[1]اردیبهشت!$B$2:$B$75,C33,[1]اردیبهشت!$O$2:$O$75,B33) -> 0 | M33: تحویل | N33: =L33*(500000*1.5) -> 0
A34: 31 | B34: فلانچ | C34: قالب خشاب زنی | D34: جهان ترمز | E34: 20 | F34: تعمیری | G34: اصلاح جا فنر | J34: 1405/01/26 | L34: =SUMIFS([1]اردیبهشت!$AD$2:$AD$75,[1]اردیبهشت!$C$2:$C$75,"قطعه تعمیری",[1]اردیبهشت!$B$2:$B$75,C34,[1]اردیبهشت!$O$2:$O$75,B34) -> 0 | M34: در حال انجام | N34: =L34*(500000*1.5) -> 0
A35: 32 | B35: Shaft | C35: همزن مواد | D35: جهان لنت | E35: 1 | F35: تعمیری | G35: اصلاح | H35: 15587 | I35: 6508 | J35: 1405/02/01 | K35: 1405/02/03 | L35: =SUMIFS([1]اردیبهشت!$AD$2:$AD$75,[1]اردیبهشت!$C$2:$C$75,"قطعه تعمیری",[1]اردیبهشت!$B$2:$B$75,C35,[1]اردیبهشت!$O$2:$O$75,B35) -> 0 | M35: تحویل | N35: =L35*(500000*1.5) -> 0
A36: 33 | B36: تیغه | C36: ویوینگ | D36: جهان ترمز | E36: 5 | F36: تعمیری | G36: اصلاح | J36: 1405/02/03 | L36: =SUMIFS([1]اردیبهشت!$AD$2:$AD$75,[1]اردیبهشت!$C$2:$C$75,"قطعه تعمیری",[1]اردیبهشت!$B$2:$B$75,C36,[1]اردیبهشت!$O$2:$O$75,B36) -> 0 | M36: در حال انجام | N36: =L36*(500000*1.5) -> 0
A37: 34 | L37: =SUMIFS([1]اردیبهشت!$AD$2:$AD$75,[1]اردیبهشت!$C$2:$C$75,"قطعه تعمیری",[1]اردیبهشت!$B$2:$B$75,C37,[1]اردیبهشت!$O$2:$O$75,B37) -> 0 | N37: =L37*(500000*1.5) -> 0
B38: مجموع | C38: √ | D38: جدید | E38: =SUMIFS(E4:E37,F4:F37,D38,M4:M37,"تحویل") -> 2947 | F38: √ | I38: Total | J38: جدید | K38: =SUMIFS(E4:E37,F4:F37,J38) -> 3001 | L38: =SUM(L24:L37) -> 3 | N38: =SUM(N4:N37) -> 93000000
C39: √ | D39: تعمیری | E39: =SUMIFS(E4:E37,F4:F37,D39,M4:M37,"تحویل") -> 17 | J39: تعمیری | K39: =SUMIFS(E4:E37,F4:F37,J39) -> 43

Sheet 6
A1: قطعات تعمیری و ساخته شده | M1: Date | N1: 1405
M2: weeks | N2: 6
B3: نام قطعه | C3: دستگاه / قالب | D3: درخواست کننده | E3: تعداد درخواست | F3: نو ع قطعه | G3: علت ساخت / تعمیر | H3: شماره نامه | I3: کد دستگاه | J3: تاریخ شروع | K3: تاریخ تحویل | L3: مقدار نفر ساعت کار شده | M3: عملیات در حال انجام | N3: هزینه ساخت/تعمیر (تومان)
A4: 1 | B4: تیغچه | C4: دستگاه پشم فلز آلمانی | D4: تولید پشم فلز | E4: 8 | F4: جدید | G4: درخواست ساخت | H4: 04/د/13047 | J4: 1404/12/02 | K4: 1405/02/10 | L4: =SUMIFS([1]اردیبهشت!$AD$76:$AD$257,[1]اردیبهشت!$C$76:$C$257,"قطعه نو",[1]اردیبهشت!$B$76:$B$257,C4,[1]اردیبهشت!$O$76:$O$257,B4) -> 0 | M4: تحویل | N4: =L4*(500000*1.5) -> 0
A5: 2 | B5: Shaft | C5: برش جمعی عقب ریو | D5: جهان لنت | E5: 1 | F5: جدید | G5: درخواست ساخت | H5: 14046 | J5: 1404/12/19 | K5: 1405/02/10 | L5: =SUMIFS([1]اردیبهشت!$AD$76:$AD$257,[1]اردیبهشت!$C$76:$C$257,"قطعه نو",[1]اردیبهشت!$B$76:$B$257,C5,[1]اردیبهشت!$O$76:$O$257,B5) -> 0 | M5: تحویل | N5: =L5*(500000*1.5) -> 0
A6: 3 | B6: مهره | C6: برش جمعی عقب ریو | D6: جهان لنت | E6: 0 | F6: جدید | G6: درخواست ساخت | H6: 14046 | J6: 1404/12/19 | K6: 1405/02/10 | L6: =SUMIFS([1]اردیبهشت!$AD$76:$AD$257,[1]اردیبهشت!$C$76:$C$257,"قطعه نو",[1]اردیبهشت!$B$76:$B$257,C6,[1]اردیبهشت!$O$76:$O$257,B6) -> 0 | M6: تحویل | N6: =L6*(500000*1.5) -> 0
A7: 4 | B7: پولکی | C7: پمپ | D7: جهان ترمز | E7: 1 | F7: جدید | G7: درخواست ساخت | J7: 1405/02/06 | K7: 1405/02/07 | L7: =SUMIFS([1]اردیبهشت!$AD$76:$AD$257,[1]اردیبهشت!$C$76:$C$257,"قطعه نو",[1]اردیبهشت!$B$76:$B$257,C7,[1]اردیبهشت!$O$76:$O$257,B7) -> 0 | M7: تحویل | N7: =L7*(500000*1.5) -> 0
A8: 5 | B8: عقب پژو 405 | C8: پین عقب پژو 405 | D8: جهان لنت | E8: 1 | F8: جدید | G8: درخواست ساخت | J8: 1405/02/07 | L8: =SUMIFS([1]اردیبهشت!$AD$76:$AD$257,[1]اردیبهشت!$C$76:$C$257,"قطعه نو",[1]اردیبهشت!$B$76:$B$257,C8,[1]اردیبهشت!$O$76:$O$257,B8) -> 0 | M8: در حال انجام | N8: =L8*(500000*1.5) -> 0
A9: 6 | B9: Bush | C9: دریل کلاچ | D9: جهان ترمز | E9: 1 | F9: جدید | G9: درخواست ساخت | H9: 15657 | J9: 1405/02/06 | K9: 1405/02/06 | L9: =SUMIFS([1]اردیبهشت!$AD$76:$AD$257,[1]اردیبهشت!$C$76:$C$257,"قطعه نو",[1]اردیبهشت!$B$76:$B$257,C9,[1]اردیبهشت!$O$76:$O$257,B9)+8 -> 8 | M9: تحویل | N9: =L9*(500000*1.5) -> 6000000
A10: 7 | B10: تیغچه بند | C10: دستگاه پشم فلز چینی | D10: تولید پشم فلز | E10: 4 | F10: جدید | G10: درخواست ساخت | H10: 04/د/13047 | J10: 1404/12/02 | L10: =SUMIFS([1]اردیبهشت!$AD$76:$AD$257,[1]اردیبهشت!$C$76:$C$257,"قطعه نو",[1]اردیبهشت!$B$76:$B$257,C10,[1]اردیبهشت!$O$76:$O$257,B10) -> 0 | M10: در حال انجام | N10: =L10*(500000*1.5) -> 0
A11: 8 | B11: گاید | C11: دستگاه پشم فلز چینی | D11: تولید پشم فلز | E11: 4 | F11: جدید | G11: درخواست ساخت | H11: 04/د/13047 | J11: 1404/12/03 | K11: 1405/02/06 | L11: =SUMIFS([1]اردیبهشت!$AD$76:$AD$257,[1]اردیبهشت!$C$76:$C$257,"قطعه نو",[1]اردیبهشت!$B$76:$B$257,C11,[1]اردیبهشت!$O$76:$O$257,B11) -> 0 | M11: تحویل | N11: =L11*(500000*1.5) -> 0
A12: 9 | B12: شانه | C12: دستگاه چسب زنی | D12: جهان لنت | E12: 2 | F12: جدید | G12: درخواست ساخت | J12: 1405/02/10 | L12: =SUMIFS([1]اردیبهشت!$AD$76:$AD$257,[1]اردیبهشت!$C$76:$C$257,"قطعه نو",[1]اردیبهشت!$B$76:$B$257,C12,[1]اردیبهشت!$O$76:$O$257,B12) -> 0 | M12: در حال انجام | N12: =L12*(500000*1.5) -> 0
A13: 10 | B13: U نگهدارنده | C13: ساب کلاچ | D13: جهان ترمز | E13: 20 | F13: جدید | G13: درخواست ساخت | J13: 1405/02/03 | L13: =SUMIFS([1]اردیبهشت!$AD$76:$AD$257,[1]اردیبهشت!$C$76:$C$257,"قطعه نو",[1]اردیبهشت!$B$76:$B$257,C13,[1]اردیبهشت!$O$76:$O$257,B13) -> 0 | M13: در حال انجام | N13: =L13*(500000*1.5) -> 0
A14: 11 | B14: Shaft | C14: ساب کونیک | D14: جهان لنت | E14: 1 | F14: جدید | G14: درخواست ساخت | H14: 15656 | I14: 2508 | J14: 1405/02/05 | K14: 1405/02/06 | L14: =SUMIFS([1]اردیبهشت!$AD$76:$AD$257,[1]اردیبهشت!$C$76:$C$257,"قطعه نو",[1]اردیبهشت!$B$76:$B$257,C14,[1]اردیبهشت!$O$76:$O$257,B14) -> 0 | M14: تحویل | N14: =L14*(500000*1.5) -> 0
A15: 12 | B15: pin | C15: فرز 7103 | D15: قالب سازی | E15: 1 | F15: جدید | G15: درخواست ساخت | I15: 7103 | J15: 1405/02/06 | K15: 1405/02/06 | L15: =SUMIFS([1]اردیبهشت!$AD$76:$AD$257,[1]اردیبهشت!$C$76:$C$257,"قطعه نو",[1]اردیبهشت!$B$76:$B$257,C15,[1]اردیبهشت!$O$76:$O$257,B15) -> 0 | M15: تحویل | N15: =L15*(500000*1.5) -> 0
A16: 13 | B16: گوه | C16: ویوینگ | D16: جهان ترمز | E16: 1 | F16: جدید | G16: درخواست ساخت | H16: 14578 | J16: 1405/02/05 | K16: 1405/02/05 | L16: =SUMIFS([1]اردیبهشت!$AD$76:$AD$257,[1]اردیبهشت!$C$76:$C$257,"قطعه نو",[1]اردیبهشت!$B$76:$B$257,C16,[1]اردیبهشت!$O$76:$O$257,B16) -> 0 | M16: تحویل | N16: =L16*(500000*1.5) -> 0
A17: 14 | B17: Bush | C17: ویوینگ | D17: جهان ترمز | E17: 2 | F17: جدید | G17: درخواست ساخت | H17: 15589 | J17: 1405/02/07 | K17: 1405/02/07 | L17: =SUMIFS([1]اردیبهشت!$AD$76:$AD$257,[1]اردیبهشت!$C$76:$C$257,"قطعه نو",[1]اردیبهشت!$B$76:$B$257,C17,[1]اردیبهشت!$O$76:$O$257,B17) -> 0 | M17: تحویل | N17: =L17*(500000*1.5) -> 0
A18: 15 | B18: pin | C18: پرچ زنی | D18: جهان لنت | E18: 1 | F18: تعمیری | G18: اصلاح | J18: 1405/02/05 | K18: 1405/02/05 | L18: =SUMIFS([1]اردیبهشت!$AD$76:$AD$257,[1]اردیبهشت!$C$76:$C$257,"قطعه تعمیری",[1]اردیبهشت!$B$76:$B$257,C18,[1]اردیبهشت!$O$76:$O$257,B18) -> 0 | M18: تحویل | N18: =L18*(500000*1.5) -> 0
A19: 16 | B19: مهره سرجک | C19: پرس پخت | D19: جهان ترمز | E19: 1 | F19: تعمیری | G19: اصلاح | J19: 1405/02/05 | K19: 1405/02/06 | L19: =SUMIFS([1]اردیبهشت!$AD$76:$AD$257,[1]اردیبهشت!$C$76:$C$257,"قطعه تعمیری",[1]اردیبهشت!$B$76:$B$257,C19,[1]اردیبهشت!$O$76:$O$257,B19) -> 0 | M19: تحویل | N19: =L19*(500000*1.5) -> 0
A20: 17 | B20: Shaft | C20: دریل سوراخکاری | D20: جهان لنت | E20: 1 | F20: تعمیری | G20: اصلاح | H20: 15657 | J20: 1405/02/06 | K20: 1405/02/06 | L20: =SUMIFS([1]اردیبهشت!$AD$76:$AD$257,[1]اردیبهشت!$C$76:$C$257,"قطعه تعمیری",[1]اردیبهشت!$B$76:$B$257,C20,[1]اردیبهشت!$O$76:$O$257,B20) -> 0 | M20: تحویل | N20: =L20*(500000*1.5) -> 0
A21: 18 | B21: Shaft | C21: دستگاه پشم فلز آلمانی | D21: تولید پشم فلز | E21: 1 | F21: تعمیری | G21: اصلاح Shaft 3 متری | J21: 1405/01/31 | K21: 1405/02/07 | L21: =SUMIFS([1]اردیبهشت!$AD$76:$AD$257,[1]اردیبهشت!$C$76:$C$257,"قطعه تعمیری",[1]اردیبهشت!$B$76:$B$257,C21,[1]اردیبهشت!$O$76:$O$257,B21)+12 -> 12 | M21: تحویل | N21: =L21*(500000*1.5) -> 9000000
A22: 19 | B22: Shaft | C22: دستگاه ساب سمباده ای | D22: جهان لنت | E22: 1 | F22: تعمیری | G22: اصلاح Shaft توپی | J22: 1405/02/06 | K22: 1405/02/06 | L22: =SUMIFS([1]اردیبهشت!$AD$76:$AD$257,[1]اردیبهشت!$C$76:$C$257,"قطعه تعمیری",[1]اردیبهشت!$B$76:$B$257,C22,[1]اردیبهشت!$O$76:$O$257,B22) -> 0 | M22: تحویل | N22: =L22*(500000*1.5) -> 0
A23: 20 | B23: غلطک | C23: ساب کلاچ | D23: جهان ترمز | E23: 8 | F23: تعمیری | G23: برداشتن لاستیک دور غلطک | H23: 15588 | J23: 1405/02/07 | K23: 1405/02/07 | L23: =SUMIFS([1]اردیبهشت!$AD$76:$AD$257,[1]اردیبهشت!$C$76:$C$257,"قطعه تعمیری",[1]اردیبهشت!$B$76:$B$257,C23,[1]اردیبهشت!$O$76:$O$257,B23) -> 0 | M23: تحویل | N23: =L23*(500000*1.5) -> 0
A24: 21 | B24: پیچ توپی بلند | C24: لیفتراک | D24: نت | E24: 1 | F24: تعمیری | G24: تراش پیچ | H24: 16153 | I24: 2 | J24: 1405/02/07 | K24: 1405/02/07 | L24: =SUMIFS([1]اردیبهشت!$AD$76:$AD$257,[1]اردیبهشت!$C$76:$C$257,"قطعه تعمیری",[1]اردیبهشت!$B$76:$B$257,C24,[1]اردیبهشت!$O$76:$O$257,B24) -> 0 | M24: تحویل | N24: =L24*(500000*1.5) -> 0
A25: 22 | B25: پیچ رگلاتور گاز | C25: لیفتراک | D25: نت | E25: 1 | F25: تعمیری | G25: درآوردن پیچ | H25: 16152 | I25: 4 | J25: 1405/02/07 | K25: 1405/02/07 | L25: =SUMIFS([1]اردیبهشت!$AD$76:$AD$257,[1]اردیبهشت!$C$76:$C$257,"قطعه تعمیری",[1]اردیبهشت!$B$76:$B$257,C25,[1]اردیبهشت!$O$76:$O$257,B25) -> 0 | M25: تحویل | N25: =L25*(500000*1.5) -> 0
A26: 23 | B26: پین عقب اکسل | C26: لیفتراک | D26: نت | E26: 2 | F26: تعمیری | G26: روتراشی | H26: 16154 | I26: 2 | J26: 1405/02/09 | K26: 1405/02/09 | L26: =SUMIFS([1]اردیبهشت!$AD$76:$AD$257,[1]اردیبهشت!$C$76:$C$257,"قطعه تعمیری",[1]اردیبهشت!$B$76:$B$257,C26,[1]اردیبهشت!$O$76:$O$257,B26) -> 0 | M26: تحویل | N26: =L26*(500000*1.5) -> 0
A27: 24 | B27: Shaft | C27: ویوینگ | D27: جهان ترمز | E27: 1 | F27: تعمیری | G27: اصلاح | H27: 14584 | I27: 1 | J27: 1405/02/07 | K27: 1405/02/10 | L27: =SUMIFS([1]اردیبهشت!$AD$76:$AD$257,[1]اردیبهشت!$C$76:$C$257,"قطعه تعمیری",[1]اردیبهشت!$B$76:$B$257,C27,[1]اردیبهشت!$O$76:$O$257,B27) -> 0 | M27: تحویل | N27: =L27*(500000*1.5) -> 0
B28: مجموع | C28: √ | D28: جدید | E28: =SUMIFS(E4:E27,F4:F27,D28,M4:M27,"تحویل") -> 20 | I28: Total | J28: جدید | K28: =SUMIFS(E4:E27,F4:F27,J28) -> 47 | L28: =SUM(L4:L27) -> 20 | N28: =SUM(N4:N27) -> 15000000
C29: √ | D29: تعمیری | E29: =SUMIFS(E4:E27,F4:F27,D29,M4:M27,"تحویل") -> 18 | J29: تعمیری | K29: =SUMIFS(E5:E27,F5:F27,J29) -> 18

Sheet 7
A1: قطعات تعمیری و ساخته شده | M1: Date | N1: 1405
M2: weeks | N2: 7
B3: نام قطعه | C3: دستگاه / قالب | D3: درخواست کننده | E3: تعداد درخواست | F3: نو ع قطعه | G3: علت ساخت / تعمیر | H3: شماره نامه | I3: کد دستگاه | J3: تاریخ شروع | K3: تاریخ تحویل | L3: مقدار نفر ساعت کار شده | M3: عملیات در حال انجام | N3: هزینه ساخت/تعمیر (تومان)
A4: 1 | B4: Shaft | C4: برش جمعی جدید | D4: جهان لنت | E4: 1 | F4: جدید | G4: درخواست ساخت | H4: 14046 | J4: 1405/02/15 | L4: =SUMIFS([1]اردیبهشت!$AF$258:$AF$408,[1]اردیبهشت!$C$258:$C$408,"قطعه نو",[1]اردیبهشت!$B$258:$B$408,C4,[1]اردیبهشت!$P$258:$P$408,B4) -> 3 | M4: در حال انجام | N4: =L4*(500000*1.5) -> 2250000
A5: 2 | B5: عقب پژو 405 | C5: پین عقب پژو 405 | D5: جهان لنت | E5: 1 | F5: جدید | G5: درخواست ساخت | J5: 1405/02/07 | L5: =SUMIFS([1]اردیبهشت!$AF$258:$AF$408,[1]اردیبهشت!$C$258:$C$408,"قطعه نو",[1]اردیبهشت!$B$258:$B$408,C5,[1]اردیبهشت!$P$258:$P$408,B5) -> 30 | M5: در حال انجام | N5: =L5*(500000*1.5) -> 22500000
A6: 3 | B6: تسمه | C6: تسمه تست کششی | D6: آزمایشگاه | E6: 2 | F6: جدید | G6: درخواست ساخت | J6: 1405/02/17 | L6: =SUMIFS([1]اردیبهشت!$AF$258:$AF$408,[1]اردیبهشت!$C$258:$C$408,"قطعه نو",[1]اردیبهشت!$B$258:$B$408,C6,[1]اردیبهشت!$P$258:$P$408,B6) -> 8 | M6: در حال انجام | N6: =L6*(500000*1.5) -> 6000000
A7: 4 | B7: Shaft | C7: دستگاه پشم فلز آلمانی | D7: تولید پشم فلز | E7: 8 | F7: جدید | G7: درخواست ساخت | H7: 04/د/13047 | J7: 1404/12/02 | L7: =SUMIFS([1]اردیبهشت!$AF$258:$AF$408,[1]اردیبهشت!$C$258:$C$408,"قطعه نو",[1]اردیبهشت!$B$258:$B$408,C7,[1]اردیبهشت!$P$258:$P$408,B7) -> 3 | M7: در حال انجام | N7: =L7*(500000*1.5) -> 2250000
A8: 5 | B8: تسمه | C8: دستگاه مهر زنی | D8: جهان ترمز | E8: 2 | F8: جدید | G8: خرابی نگهدارنده | H8: 15413 | I8: 4203 4204 | J8: 1405/01/24 | K8: 1405/02/18 | L8: =SUMIFS([1]اردیبهشت!$AF$258:$AF$408,[1]اردیبهشت!$C$258:$C$408,"قطعه نو",[1]اردیبهشت!$B$258:$B$408,C8,[1]اردیبهشت!$P$258:$P$408,B8) -> 1.5 | M8: تحویل | N8: =L8*(500000*1.5) -> 1125000
A9: 6 | B9: U نگهدارنده | C9: ساب کلاچ | D9: جهان ترمز | E9: 20 | F9: جدید | G9: درخواست ساخت | J9: 1405/02/03 | L9: =SUMIFS([1]اردیبهشت!$AF$258:$AF$408,[1]اردیبهشت!$C$258:$C$408,"قطعه نو",[1]اردیبهشت!$B$258:$B$408,C9,[1]اردیبهشت!$P$258:$P$408,B9) -> 5 | M9: در حال انجام | N9: =L9*(500000*1.5) -> 3750000
A10: 7 | B10: واسطه سنگ | C10: ساب | D10: جهان لنت | E10: 2 | F10: جدید | G10: درخواست ساخت | H10: 15667 | J10: 1405/02/13 | K10: 1405/02/16 | L10: =SUMIFS([1]اردیبهشت!$AF$258:$AF$408,[1]اردیبهشت!$C$258:$C$408,"قطعه نو",[1]اردیبهشت!$B$258:$B$408,C10,[1]اردیبهشت!$P$258:$P$408,B10) -> 0 | M10: تحویل | N10: =L10*(500000*1.5) -> 0
A11: 8 | B11: پیچ | C11: ساب | D11: جهان لنت | E11: 1 | F11: جدید | G11: درخواست ساخت | H11: 15667 | J11: 1405/02/13 | K11: 1405/02/16 | L11: =SUMIFS([1]اردیبهشت!$AF$258:$AF$408,[1]اردیبهشت!$C$258:$C$408,"قطعه نو",[1]اردیبهشت!$B$258:$B$408,C11,[1]اردیبهشت!$P$258:$P$408,B11) -> 2 | M11: تحویل | N11: =L11*(500000*1.5) -> 1500000
A12: 9 | B12: فیکسچر خم | C12: لنت دنیای مس | D12: جهان لنت | E12: 1 | F12: جدید | G12: درخواست ساخت | J12: 1405/02/14 | L12: =SUMIFS([1]اردیبهشت!$AF$258:$AF$408,[1]اردیبهشت!$C$258:$C$408,"قطعه نو",[1]اردیبهشت!$B$258:$B$408,C12,[1]اردیبهشت!$P$258:$P$408,B12) -> 32 | M12: در حال انجام | N12: =L12*(500000*1.5) -> 24000000
A13: 10 | B13: Bush | C13: میکس چینی | D13: جهان لنت | E13: 1 | F13: جدید | G13: درخواست ساخت | H13: 15666 | J13: 1405/02/12 | K13: 1405/02/13 | L13: =SUMIFS([1]اردیبهشت!$AF$258:$AF$408,[1]اردیبهشت!$C$258:$C$408,"قطعه نو",[1]اردیبهشت!$B$258:$B$408,C13,[1]اردیبهشت!$P$258:$P$408,B13) -> 3.3333333 | M13: تحویل | N13: =L13*(500000*1.5) -> 2500000
A14: 11 | B14: Mandrel | C14: ابزار زنی | D14: جهان لنت | E14: 1 | F14: تعمیری | G14: خرابی Mandrel | H14: 15035 | J14: 1405/02/15 | K14: 1405/02/17 | L14: =SUMIFS([1]اردیبهشت!$AF$258:$AF$408,[1]اردیبهشت!$C$258:$C$408,"قطعه تعمیری",[1]اردیبهشت!$B$258:$B$408,C14,[1]اردیبهشت!$P$258:$P$408,B14) -> 2.5 | M14: تحویل | N14: =L14*(500000*1.5) -> 1875000
A15: 12 | B15: Shaft | C15: آسیاب پشم فلز | D15: تولید پشم فلز | E15: 1 | F15: تعمیری | G15: اصلاحShaftروتور | H15: 15591 | J15: 1405/02/16 | K15: 1405/02/16 | L15: =SUMIFS([1]اردیبهشت!$AF$258:$AF$408,[1]اردیبهشت!$C$258:$C$408,"قطعه تعمیری",[1]اردیبهشت!$B$258:$B$408,C15,[1]اردیبهشت!$P$258:$P$408,B15) -> 2.5 | M15: تحویل | N15: =L15*(500000*1.5) -> 1875000
A16: 13 | B16: فولی | C16: آغشته کاری | D16: جهان ترمز | E16: 1 | F16: تعمیری | G16: تراش | J16: 1405/02/15 | K16: 1405/02/16 | L16: =SUMIFS([1]اردیبهشت!$AF$258:$AF$408,[1]اردیبهشت!$C$258:$C$408,"قطعه تعمیری",[1]اردیبهشت!$B$258:$B$408,C16,[1]اردیبهشت!$P$258:$P$408,B16) -> 2 | M16: تحویل | N16: =L16*(500000*1.5) -> 1500000
A17: 14 | B17: تیغه | C17: برش جمعی عقب | D17: جهان لنت | E17: 5 | F17: تعمیری | G17: اصلاح | H17: 15862 | I17: 3207 | J17: 1405/02/14 | K17: 1405/02/14 | L17: =SUMIFS([1]اردیبهشت!$AF$258:$AF$408,[1]اردیبهشت!$C$258:$C$408,"قطعه تعمیری",[1]اردیبهشت!$B$258:$B$408,C17,[1]اردیبهشت!$P$258:$P$408,B17) -> 2.5 | M17: تحویل | N17: =L17*(500000*1.5) -> 1875000
A18: 15 | B18: فیکسچر پیکان | C18: دریل سوراخکاری | D18: جهان ترمز | E18: 1 | F18: تعمیری | G18: اصلاح | J18: 1405/02/14 | K18: 1405/02/14 | L18: =SUMIFS([1]اردیبهشت!$AF$258:$AF$408,[1]اردیبهشت!$C$258:$C$408,"قطعه تعمیری",[1]اردیبهشت!$B$258:$B$408,C18,[1]اردیبهشت!$P$258:$P$408,B18) -> 2 | M18: تحویل | N18: =L18*(500000*1.5) -> 1500000
A19: 16 | B19: Shaft | C19: دستگاه پشم فلز | D19: تولید پشم فلز | E19: 5 | F19: تعمیری | G19: اصلاح | H19: 15670 | J19: 1405/02/16 | L19: =SUMIFS([1]اردیبهشت!$AF$258:$AF$408,[1]اردیبهشت!$C$258:$C$408,"قطعه تعمیری",[1]اردیبهشت!$B$258:$B$408,C19,[1]اردیبهشت!$P$258:$P$408,B19) -> 2 | M19: در حال انجام | N19: =L19*(500000*1.5) -> 1500000
A20: 17 | B20: مسی | C20: سری نقطه جوش | D20: جهان لنت | E20: 6 | F20: تعمیری | G20: اصلاح | J20: 1405/02/14 | K20: 1405/02/15 | L20: =SUMIFS([1]اردیبهشت!$AF$258:$AF$408,[1]اردیبهشت!$C$258:$C$408,"قطعه تعمیری",[1]اردیبهشت!$B$258:$B$408,C20,[1]اردیبهشت!$P$258:$P$408,B20) -> 5.6666667 | M20: تحویل | N20: =L20*(500000*1.5) -> 4250000
A21: 18 | B21: واسطه سنگ | C21: سنگ ساب | D21: جهان لنت | E21: 1 | F21: تعمیری | G21: اصلاح | J21: 1405/02/12 | K21: 1405/02/12 | L21: =SUMIFS([1]اردیبهشت!$AF$258:$AF$408,[1]اردیبهشت!$C$258:$C$408,"قطعه تعمیری",[1]اردیبهشت!$B$258:$B$408,C21,[1]اردیبهشت!$P$258:$P$408,B21) -> 0 | M21: تحویل | N21: =L21*(500000*1.5) -> 0
A22: 19 | B22: Shaft | C22: ویوینگ | D22: جهان ترمز | E22: 1 | F22: تعمیری | G22: اصلاح | H22: 14586 | I22: 6503 | J22: 1405/02/13 | K22: 1405/02/16 | L22: =SUMIFS([1]اردیبهشت!$AF$258:$AF$408,[1]اردیبهشت!$C$258:$C$408,"قطعه تعمیری",[1]اردیبهشت!$B$258:$B$408,C22,[1]اردیبهشت!$P$258:$P$408,B22) -> 3.6666667 | M22: در حال انجام | N22: =L22*(500000*1.5) -> 2750000
A23: 20 | B23: پیچ | C23: ویوینگ | D23: جهان ترمز | E23: 1 | F23: تعمیری | G23: اصلاح | H23: 14586 | I23: 6503 | J23: 1405/02/13 | K23: 1405/02/16 | L23: =SUMIFS([1]اردیبهشت!$AF$258:$AF$408,[1]اردیبهشت!$C$258:$C$408,"قطعه تعمیری",[1]اردیبهشت!$B$258:$B$408,C23,[1]اردیبهشت!$P$258:$P$408,B23) -> 2 | M23: تحویل | N23: =L23*(500000*1.5) -> 1500000
A25: 21 | L25: =SUMIFS([1]اردیبهشت!$AF$258:$AF$408,[1]اردیبهشت!$C$258:$C$408,"قطعه تعمیری",[1]اردیبهشت!$B$258:$B$408,C25,[1]اردیبهشت!$P$258:$P$408,B25) -> 0 | N25: =L25*(500000*1.5) -> 0
B26: مجموع | C26: √ | D26: جدید | E26: =SUMIFS(E4:E25,F4:F25,D26,M4:M25,"تحویل") -> 6 | I26: Total | J26: جدید | K26: =SUMIFS(E4:E25,F4:F25,J26) -> 39 | L26: =SUM(L4:L25) -> 112.66667 | N26: =SUM(N4:N25) -> 84500000
C27: √ | D27: تعمیری | E27: =SUMIFS(E4:E25,F4:F25,D27,M4:M25,"تحویل") -> 17 | J27: تعمیری | K27: =SUMIFS(E5:E25,F5:F25,J27) -> 23

Sheet 8
A1: قطعات تعمیری و ساخته شده | M1: Date | N1: 1405
M2: weeks | N2: 8
B3: نام قطعه | C3: دستگاه / قالب | D3: درخواست کننده | E3: تعداد درخواست | F3: نو ع قطعه | G3: علت ساخت / تعمیر | H3: شماره نامه | I3: کد دستگاه | J3: تاریخ شروع | K3: تاریخ تحویل | L3: مقدار نفر ساعت کار شده | M3: عملیات در حال انجام | N3: هزینه ساخت/تعمیر (تومان)
A4: 1 | B4: عقب پژو 405 | C4: پین عقب پژو 405 | D4: جهان لنت | E4: 1 | F4: جدید | G4: درخواست ساخت | J4: 1405/02/07 | L4: =SUMIFS([1]اردیبهشت!$AF$409:$AF$648,[1]اردیبهشت!$C$409:$C$648,"قطعه نو",[1]اردیبهشت!$B$409:$B$648,C4,[1]اردیبهشت!$P$409:$P$648,B4) -> 26 | M4: در حال انجام | N4: =L4*(500000*1.5) -> 19500000
A5: 2 | B5: U نگهدارنده | C5: ساب کلاچ | D5: جهان ترمز | E5: 20 | F5: جدید | G5: درخواست ساخت | J5: 1405/02/03 | L5: =SUMIFS([1]اردیبهشت!$AF$409:$AF$648,[1]اردیبهشت!$C$409:$C$648,"قطعه نو",[1]اردیبهشت!$B$409:$B$648,C5,[1]اردیبهشت!$P$409:$P$648,B5) -> 4 | M5: در حال انجام | N5: =L5*(500000*1.5) -> 3000000
A6: 3 | B6: فیکسچر خم | C6: لنت دنیای مس | D6: جهان لنت | E6: 1 | F6: جدید | G6: درخواست ساخت | J6: 1405/02/14 | L6: =SUMIFS([1]اردیبهشت!$AF$409:$AF$648,[1]اردیبهشت!$C$409:$C$648,"قطعه نو",[1]اردیبهشت!$B$409:$B$648,C6,[1]اردیبهشت!$P$409:$P$648,B6) -> 40 | M6: در حال انجام | N6: =L6*(500000*1.5) -> 30000000
A7: 4 | B7: ابزار پیچ و مهره | C7: ابزار زنی | D7: جهان لنت | E7: 300 | F7: جدید | G7: درخواست ساخت | H7: 1197/د/05 | J7: 1405/02/24 | L7: =SUMIFS([1]اردیبهشت!$AF$409:$AF$648,[1]اردیبهشت!$C$409:$C$648,"قطعه نو",[1]اردیبهشت!$B$409:$B$648,C7,[1]اردیبهشت!$P$409:$P$648,B7) -> 6 | M7: در حال انجام | N7: =L7*(500000*1.5) -> 4500000
A8: 5 | B8: مهره | C8: پرس پخت | D8: جهان لنت | E8: 1 | F8: جدید | G8: درخواست ساخت | J8: 1405/02/22 | L8: =SUMIFS([1]اردیبهشت!$AF$409:$AF$648,[1]اردیبهشت!$C$409:$C$648,"قطعه نو",[1]اردیبهشت!$B$409:$B$648,C8,[1]اردیبهشت!$P$409:$P$648,B8) -> 4 | M8: تحویل | N8: =L8*(500000*1.5) -> 3000000
A9: 6 | B9: Shaft | C9: پرس پخت | D9: جهان ترمز | E9: 1 | F9: جدید | G9: شکستن Shaft | H9: 14589 | I9: 2063 | J9: 1405/02/23 | L9: =SUMIFS([1]اردیبهشت!$AF$409:$AF$648,[1]اردیبهشت!$C$409:$C$648,"قطعه نو",[1]اردیبهشت!$B$409:$B$648,C9,[1]اردیبهشت!$P$409:$P$648,B9) -> 6 | M9: در حال انجام | N9: =L9*(500000*1.5) -> 4500000
A10: 7 | B10: شانه | C10: دستگاه پشم فلز آلمانی | D10: پشم فلز | E10: 60 | F10: جدید | G10: درخواست ساخت | J10: 1405/02/19 | L10: =SUMIFS([1]اردیبهشت!$AF$409:$AF$648,[1]اردیبهشت!$C$409:$C$648,"قطعه نو",[1]اردیبهشت!$B$409:$B$648,C10,[1]اردیبهشت!$P$409:$P$648,B10) -> 50 | M10: در حال انجام | N10: =L10*(500000*1.5) -> 37500000
A11: 8 | B11: Shaft | C11: دستگاه پشم فلز | D11: پشم فلز | E11: 1 | F11: جدید | G11: درخواست ساخت | H11: 15670 | J11: 1405/02/19 | K11: 1405/02/25 | L11: =SUMIFS([1]اردیبهشت!$AF$409:$AF$648,[1]اردیبهشت!$C$409:$C$648,"قطعه نو",[1]اردیبهشت!$B$409:$B$648,C11,[1]اردیبهشت!$P$409:$P$648,B11) -> 2 | M11: تحویل | N11: =L11*(500000*1.5) -> 1500000
A12: 9 | B12: زیر پایه | C12: دستگاه پشم فلز | D12: پشم فلز | E12: 1 | F12: جدید | G12: درخواست ساخت | H12: 15670 | J12: 1405/02/19 | K12: 1405/02/25 | L12: =SUMIFS([1]اردیبهشت!$AF$409:$AF$648,[1]اردیبهشت!$C$409:$C$648,"قطعه نو",[1]اردیبهشت!$B$409:$B$648,C12,[1]اردیبهشت!$P$409:$P$648,B12) -> 3 | M12: تحویل | N12: =L12*(500000*1.5) -> 2250000
A13: 10 | B13: فلانچ بزرگ | C13: دستگاه پشم فلز | D13: پشم فلز | E13: 1 | F13: جدید | G13: درخواست ساخت | H13: 15670 | J13: 1405/02/19 | K13: 1405/02/25 | L13: =SUMIFS([1]اردیبهشت!$AF$409:$AF$648,[1]اردیبهشت!$C$409:$C$648,"قطعه نو",[1]اردیبهشت!$B$409:$B$648,C13,[1]اردیبهشت!$P$409:$P$648,B13) -> 4 | M13: تحویل | N13: =L13*(500000*1.5) -> 3000000
A14: 11 | B14: کوبلینگ | C14: دستگاه پشم فلز | D14: پشم فلز | E14: 1 | F14: جدید | G14: درخواست ساخت | H14: 15670 | J14: 1405/02/19 | K14: 1405/02/25 | L14: =SUMIFS([1]اردیبهشت!$AF$409:$AF$648,[1]اردیبهشت!$C$409:$C$648,"قطعه نو",[1]اردیبهشت!$B$409:$B$648,C14,[1]اردیبهشت!$P$409:$P$648,B14) -> 8 | M14: تحویل | N14: =L14*(500000*1.5) -> 6000000
A15: 12 | B15: روبند | C15: دستگاه ساب | D15: جهان لنت | E15: 1 | F15: جدید | G15: درخواست ساخت | J15: 1405/02/25 | L15: =SUMIFS([1]اردیبهشت!$AF$409:$AF$648,[1]اردیبهشت!$C$409:$C$648,"قطعه نو",[1]اردیبهشت!$B$409:$B$648,C15,[1]اردیبهشت!$P$409:$P$648,B15) -> 7 | M15: در حال انجام | N15: =L15*(500000*1.5) -> 5250000
A16: 13 | B16: واسطه سنگ | C16: دستگاه سنگ پشم فلز آلمانی | D16: پشم فلز | E16: 2 | F16: جدید | G16: درخواست ساخت | J16: 1405/02/20 | K16: 1405/02/25 | L16: =SUMIFS([1]اردیبهشت!$AF$409:$AF$648,[1]اردیبهشت!$C$409:$C$648,"قطعه نو",[1]اردیبهشت!$B$409:$B$648,C16,[1]اردیبهشت!$P$409:$P$648,B16) -> 2 | M16: تحویل | N16: =L16*(500000*1.5) -> 1500000
A17: 14 | B17: پولی تسمه | C17: دستگاه مهر زنی | D17: جهان ترمز | E17: 2 | F17: جدید | G17: خرابی نگهدارنده | H17: 15413 | I17: 4203 4204 | J17: 1405/02/14 | K17: 1405/02/25 | L17: =SUMIFS([1]اردیبهشت!$AF$409:$AF$648,[1]اردیبهشت!$C$409:$C$648,"قطعه نو",[1]اردیبهشت!$B$409:$B$648,C17,[1]اردیبهشت!$P$409:$P$648,B17) -> 1 | M17: تحویل | N17: =L17*(500000*1.5) -> 750000
A18: 15 | B18: پنجره ای | C18: ساب کونیک | D18: جهان لنت | E18: 1 | F18: جدید | G18: درخواست ساخت | J18: 1405/02/19 | K18: 1405/02/25 | L18: =SUMIFS([1]اردیبهشت!$AF$409:$AF$648,[1]اردیبهشت!$C$409:$C$648,"قطعه نو",[1]اردیبهشت!$B$409:$B$648,C18,[1]اردیبهشت!$P$409:$P$648,B18) -> 9 | M18: تحویل | N18: =L18*(500000*1.5) -> 6750000
A19: 16 | B19: فیکسچر خم | C19: لنت دنیای مس | D19: جهان لنت | E19: 1 | F19: جدید | G19: درخواست ساخت | J19: 1405/02/21 | L19: =SUMIFS([1]اردیبهشت!$AF$409:$AF$648,[1]اردیبهشت!$C$409:$C$648,"قطعه نو",[1]اردیبهشت!$B$409:$B$648,C19,[1]اردیبهشت!$P$409:$P$648,B19) -> 40 | M19: در حال انجام | N19: =L19*(500000*1.5) -> 30000000
A20: 17 | B20: Bush | C20: ویوینگ | D20: جهان ترمز | E20: 1 | F20: جدید | G20: درخواست ساخت | J20: 1405/02/20 | K20: 1405/02/25 | L20: =SUMIFS([1]اردیبهشت!$AF$409:$AF$648,[1]اردیبهشت!$C$409:$C$648,"قطعه نو",[1]اردیبهشت!$B$409:$B$648,C20,[1]اردیبهشت!$P$409:$P$648,B20) -> 6.5 | M20: تحویل | N20: =L20*(500000*1.5) -> 4875000
A21: 18 | B21: pin | C21: ویوینگ | D21: جهان ترمز | E21: 1 | F21: جدید | G21: درخواست ساخت | J21: 1405/02/20 | K21: 1405/02/25 | L21: =SUMIFS([1]اردیبهشت!$AF$409:$AF$648,[1]اردیبهشت!$C$409:$C$648,"قطعه نو",[1]اردیبهشت!$B$409:$B$648,C21,[1]اردیبهشت!$P$409:$P$648,B21) -> 1.5 | M21: تحویل | N21: =L21*(500000*1.5) -> 1125000
A22: 19 | B22: واشر لنگری | C22: ویوینگ | D22: جهان ترمز | E22: 1 | F22: جدید | G22: درخواست ساخت | H22: 15592 | J22: 1405/02/20 | K22: 1405/02/25 | L22: =SUMIFS([1]اردیبهشت!$AF$409:$AF$648,[1]اردیبهشت!$C$409:$C$648,"قطعه نو",[1]اردیبهشت!$B$409:$B$648,C22,[1]اردیبهشت!$P$409:$P$648,B22) -> 7.5 | M22: تحویل | N22: =L22*(500000*1.5) -> 5625000
A23: 20 | B23: Mandrel | C23: ابزار زنی | D23: جهان لنت | E23: 2 | F23: تعمیری | G23: اصلاح | J23: 1405/02/20 | K23: 1405/02/21 | L23: =SUMIFS([1]اردیبهشت!$AF$409:$AF$648,[1]اردیبهشت!$C$409:$C$648,"قطعه تعمیری",[1]اردیبهشت!$B$409:$B$648,C23,[1]اردیبهشت!$P$409:$P$648,B23) -> 1.5 | M23: تحویل | N23: =L23*(500000*1.5) -> 1125000
A24: 21 | B24: Shaft | C24: آسیاب پشم فلز | D24: پشم فلز | E24: 1 | F24: تعمیری | G24: اصلاح | H24: 15591 | J24: 1405/02/19 | K24: 1405/02/20 | L24: =SUMIFS([1]اردیبهشت!$AF$409:$AF$648,[1]اردیبهشت!$C$409:$C$648,"قطعه تعمیری",[1]اردیبهشت!$B$409:$B$648,C24,[1]اردیبهشت!$P$409:$P$648,B24) -> 1 | M24: تحویل | N24: =L24*(500000*1.5) -> 750000
A25: 22 | B25: پولی تسمه | C25: آغشته کاری | D25: جهان ترمز | E25: 1 | F25: تعمیری | G25: اصلاح | H25: 15687 | J25: 1405/02/23 | K25: 1405/02/25 | L25: =SUMIFS([1]اردیبهشت!$AF$409:$AF$648,[1]اردیبهشت!$C$409:$C$648,"قطعه تعمیری",[1]اردیبهشت!$B$409:$B$648,C25,[1]اردیبهشت!$P$409:$P$648,"*") -> 3 | M25: تحویل | N25: =L25*(500000*1.5) -> 2250000
A26: 23 | B26: Bush | C26: برش جمعی عقب | D26: جهان لنت | E26: 1 | F26: تعمیری | G26: اصلاح | J26: 1405/02/23 | K26: 1405/02/23 | L26: =SUMIFS([1]اردیبهشت!$AF$409:$AF$648,[1]اردیبهشت!$C$409:$C$648,"قطعه تعمیری",[1]اردیبهشت!$B$409:$B$648,C26,[1]اردیبهشت!$P$409:$P$648,B26) -> 1 | M26: تحویل | N26: =L26*(500000*1.5) -> 750000
