Workbook

Sheet 2
A1: New Project | I1: Date | J1: =#REF! -> #REF!
I2: Weeks | J2: =#REF! -> #REF!
B3: Name | C3: شماره فنی | D3: تاریخ شروع | E3: پیش بینی تاریخ تحویل1 | F3: تاریخ تحویل 2 | G3: علت تاخیر در تحویل بموقع | H3: فرایند OK | I3: فرایند NOT OK | J3: Baseline | K3: آخرین وظعیت
A4: 1 | B4: شمش ریو | C4: 9278/د/04 | D4: برون سپاری (اصفهان) امینی
A5: 2 | B5: شمش عقب پژو پایه کوتاه | C5: 9278/د/04 | D5: تامین متریال | E5: 1404/09/10 | F5: 1404/11/10 1405/02/10 | G5: خرابی سنگ | H5: CNC، وایر ، تراش ، کروم ، مونتاژ ، سختکاری | I5: CNC، وایر ، تراش ، کروم ، مونتاژ ، سختکاری | J5: 0.7 | K5: فرز
A6: 3 | B6: شمش عقب پژو پایه بلند | C6: 9278/د/04 | D6: 9278/د/04
A7: 4 | B7: قالب توری پگاسوز | C7: 12371/د/04 | E7: 1404/10/23 | F7: 1405/02/10 | H7: CNC، وایر ، تراش ، کروم ، مونتاژ ، سختکاری | I7: CNC، وایر ، تراش ، کروم ، مونتاژ ، سختکاری | J7: 0.67 | K7: فرز
A8: 5 | B8: شمشی عقب پیکان | C8: 9278/د/04 | D8: 9278/د/04
A9: 6 | B9: دیسکی ریو | D9: برون سپاری (اصفهان) امینی
A10: 7 | B10: دیسکی پژو 405 | D10: برون سپاری (اصفهان) امینی

Sheet 3
A1: New Project | I1: Date | J1: =#REF! -> #REF!
I2: Weeks | J2: 3
B3: Name | C3: شماره فنی | D3: تاریخ شروع | E3: پیش بینی تاریخ تحویل1 | F3: تاریخ تحویل 2 | G3: علت تاخیر در تحویل بموقع | H3: فرایند OK | I3: فرایند NOT OK | J3: Baseline | K3: آخرین وظعیت
A4: 1 | B4: شمش ریو | C4: 9278/د/04 | D4: برون سپاری (اصفهان) امینی
A5: 2 | B5: شمش عقب پژو پایه کوتاه | C5: 9278/د/04 | D5: تامین متریال | E5: 1404/09/10 | F5: 1404/11/10 1405/02/10 | G5: خرابی سنگ | H5: CNC، وایر ، تراش ، کروم ، مونتاژ ، سختکاری | I5: CNC، وایر ، تراش ، کروم ، مونتاژ ، سختکاری | J5: 0.75 | K5: فرز
A6: 3 | B6: شمش عقب پژو پایه بلند | C6: 9278/د/04 | D6: 9278/د/04
A7: 4 | B7: قالب توری پگاسوز | C7: 12371/د/04 | E7: 1404/10/23 | F7: 1405/02/10 | H7: CNC، وایر ، تراش ، کروم ، مونتاژ ، سختکاری | I7: CNC، وایر ، تراش ، کروم ، مونتاژ ، سختکاری | J7: 0.67 | K7: فرز
A8: 5 | B8: شمشی عقب پیکان | C8: 9278/د/04 | D8: 9278/د/04
A9: 6 | B9: دیسکی ریو | D9: برون سپاری (اصفهان) امینی
A10: 7 | B10: دیسکی پژو 405 | D10: برون سپاری (اصفهان) امینی

Sheet 4
A1: New Project | I1: Date | J1: =#REF! -> #REF!
I2: Weeks | J2: 4
B3: Name | C3: شماره فنی | D3: تاریخ شروع | E3: پیش بینی تاریخ تحویل1 | F3: تاریخ تحویل 2 | G3: علت تاخیر در تحویل بموقع | H3: فرایند OK | I3: فرایند NOT OK | J3: Baseline | K3: آخرین وظعیت
A4: 1 | B4: شمش ریو | C4: 9278/د/04 | D4: برون سپاری (اصفهان) امینی
A5: 2 | B5: شمش عقب پژو پایه کوتاه | C5: 9278/د/04 | D5: تامین متریال | E5: 1404/09/10 | F5: 1404/11/10 1405/02/10 | G5: خرابی سنگ | H5: CNC، وایر ، تراش ، کروم ، مونتاژ ، سختکاری | I5: CNC، وایر ، تراش ، کروم ، مونتاژ ، سختکاری | J5: 0.75 | K5: فرز
A6: 3 | B6: شمش عقب پژو پایه بلند | C6: 9278/د/04 | D6: 9278/د/04
A7: 4 | B7: قالب توری پگاسوز | C7: 12371/د/04 | E7: 1404/10/23 | F7: 1405/02/10 | H7: CNC، وایر ، تراش ، کروم ، مونتاژ ، سختکاری | I7: CNC، وایر ، تراش ، کروم ، مونتاژ ، سختکاری | J7: 0.67 | K7: فرز
A8: 5 | B8: شمشی عقب پیکان | C8: 9278/د/04 | D8: 9278/د/04
A9: 6 | B9: دیسکی ریو | D9: برون سپاری (اصفهان) امینی
A10: 7 | B10: دیسکی پژو 405 | D10: برون سپاری (اصفهان) امینی
A11: 8 | B11: قالب اصلاح دسته کفشک مترو K | D11: قالب سازی | E11: 1405/01/29 | F11: 1405/02/05 | H11: فرز ، سنگ ، وایر ، CNC | I11: فرز | J11: 0.58 | K11: فرز

Sheet 5
A1: New Project | I1: Date | J1: =#REF! -> #REF!
I2: Weeks | J2: 5
B3: Name | C3: شماره فنی | D3: تاریخ شروع | E3: پیش بینی تاریخ تحویل1 | F3: تاریخ تحویل 2 | G3: علت تاخیر در تحویل بموقع | H3: فرایند OK | I3: فرایند NOT OK | J3: Baseline | K3: آخرین وظعیت
A4: 1 | B4: شمش ریو | C4: 9278/د/04 | D4: برون سپاری (اصفهان) امینی
A5: 2 | B5: شمش عقب پژو پایه کوتاه | C5: 9278/د/04 | D5: تامین متریال | E5: 1404/09/10 | F5: 1404/11/10 1405/02/10 | G5: خرابی سنگ | H5: CNC، وایر ، تراش ، کروم ، مونتاژ ، سختکاری | I5: CNC، وایر ، تراش ، کروم ، مونتاژ ، سختکاری | J5: 0.75 | K5: فرز
A6: 3 | B6: شمش عقب پژو پایه بلند | C6: 9278/د/04 | D6: 9278/د/04
A7: 4 | B7: قالب توری پگاسوز | C7: 12371/د/04 | E7: 1404/10/23 | F7: 1405/02/10 | H7: CNC، وایر ، تراش ، کروم ، مونتاژ ، سختکاری | I7: CNC، وایر ، تراش ، کروم ، مونتاژ ، سختکاری | J7: 1 | K7: تحویل
A8: 5 | B8: شمشی عقب پیکان | C8: 9278/د/04 | D8: 9278/د/04
A9: 6 | B9: دیسکی ریو | D9: برون سپاری (اصفهان) امینی
A10: 7 | B10: دیسکی پژو 405 | D10: برون سپاری (اصفهان) امینی
A11: 8 | B11: قالب اصلاح دسته کفشک مترو K | D11: قالب سازی | E11: 1405/01/29 | F11: 1405/02/05 | H11: فرز ، سنگ ، وایر ، CNC، مونتاز | I11: مونتاژ | J11: 1 | K11: مونتاژ

Sheet 6
A1: New Project | I1: Date | J1: =#REF! -> #REF!
I2: Weeks | J2: 6
B3: Name | C3: شماره فنی | D3: تاریخ شروع | E3: پیش بینی تاریخ تحویل1 | F3: تاریخ تحویل 2 | G3: علت تاخیر در تحویل بموقع | H3: فرایند OK | I3: فرایند NOT OK | J3: Baseline | K3: آخرین وظعیت
A4: 1 | B4: شمش ریو | C4: 9278/د/04 | D4: برون سپاری (اصفهان) امینی
A5: 2 | B5: شمش عقب پژو پایه کوتاه | C5: 9278/د/04 | D5: تامین متریال | E5: 1404/09/10 | F5: 1404/11/10 1405/02/10 | G5: خرابی سنگ | H5: CNC، وایر ، تراش ، کروم ، مونتاژ ، سختکاری | I5: CNC، وایر ، تراش ، کروم ، مونتاژ ، سختکاری | J5: 0.8 | K5: فرز
A6: 3 | B6: شمش عقب پژو پایه بلند | C6: 9278/د/04 | D6: 9278/د/04
A7: 4 | B7: قالب توری پگاسوز | C7: 12371/د/04 | E7: 1404/10/23 | F7: 1405/02/10 | H7: CNC، وایر ، تراش ، کروم ، مونتاژ ، سختکاری | I7: CNC، وایر ، تراش ، کروم ، مونتاژ ، سختکاری | J7: 1 | K7: تحویل
A8: 5 | B8: شمشی عقب پیکان | C8: 9278/د/04 | D8: 9278/د/04
A9: 6 | B9: دیسکی ریو | D9: برون سپاری (اصفهان) امینی
A10: 7 | B10: دیسکی پژو 405 | D10: برون سپاری (اصفهان) امینی

Sheet 7
A1: New Project | I1: Date | J1: =#REF! -> #REF!
I2: Weeks | J2: 7
B3: Name | C3: شماره فنی | D3: تاریخ شروع | E3: پیش بینی تاریخ تحویل1 | F3: تاریخ تحویل 2 | G3: علت تاخیر در تحویل بموقع | H3: فرایند OK | I3: فرایند NOT OK | J3: Baseline | K3: آخرین وظعیت
A4: 1 | B4: شمش ریو | C4: 9278/د/04 | D4: برون سپاری (اصفهان) امینی
A5: 2 | B5: شمش عقب پژو پایه کوتاه | C5: 9278/د/04 | D5: تامین متریال | E5: 1404/09/10 | F5: 1404/11/10 1405/02/10 | G5: خرابی سنگ | H5: CNC، وایر ، تراش ، کروم ، مونتاژ ، سختکاری | I5: CNC، وایر ، تراش ، کروم ، مونتاژ ، سختکاری | J5: 0.85 | K5: فرز
A6: 3 | B6: شمش عقب پژو پایه بلند | C6: 9278/د/04 | D6: 9278/د/04
A7: 4 | B7: شمشی عقب پیکان | C7: 9278/د/04 | D7: 9278/د/04
A8: 5 | B8: دیسکی ریو | D8: برون سپاری (اصفهان) امینی
A9: 6 | B9: دیسکی پژو 405 | D9: برون سپاری (اصفهان) امینی

Sheet 8
A1: New Project | I1: Date | J1: 1405
I2: Weeks | J2: 8
B3: Name | C3: شماره فنی | D3: تاریخ شروع | E3: پیش بینی تاریخ تحویل1 | F3: تاریخ تحویل 2 | G3: علت تاخیر در تحویل بموقع | H3: فرایند OK | I3: فرایند NOT OK | J3: Baseline | K3: آخرین وظعیت
A4: 1 | B4: شمش ریو | C4: 9278/د/04 | D4: برون سپاری (اصفهان) امینی
A5: 2 | B5: شمش عقب پژو پایه کوتاه | C5: 9278/د/04 | D5: تامین متریال | E5: 1404/09/10 | F5: 1404/11/10 1405/02/10 | G5: خرابی سنگ | H5: CNC، وایر ، تراش ، کروم ، مونتاژ ، سختکاری | I5: CNC، وایر ، تراش ، کروم ، مونتاژ ، سختکاری | J5: 0.87 | K5: فرز
A6: 3 | B6: شمش عقب پژو پایه بلند | C6: 9278/د/04 | D6: 9278/د/04
A7: 4 | B7: شمشی عقب پیکان | C7: 9278/د/04 | D7: 9278/د/04
A8: 5 | B8: دیسکی ریو | D8: برون سپاری (اصفهان) امینی
A9: 6 | B9: دیسکی پژو 405 | D9: برون سپاری (اصفهان) امینی

Sheet 9
A1: New Project | I1: Date | J1: 1405
I2: Weeks | J2: 9
B3: Name | C3: شماره فنی | D3: تاریخ شروع | E3: پیش بینی تاریخ تحویل1 | F3: تاریخ تحویل 2 | G3: علت تاخیر در تحویل بموقع | H3: BPMN (OK) | I3: BPMN (NC) | J3: Baseline | K3: آخرین وظعیت
A4: 1 | B4: شمش ریو | C4: 9278/د/04 | D4: برون سپاری (اصفهان) امینی | K4: Stop
A5: 2 | B5: شمش عقب پژو پایه کوتاه | C5: 9278/د/04 | D5: تامین متریال | E5: 1404/09/10 | F5: 1404/11/10 1405/02/10 | G5: خرابی سنگ تغییر در فرایند (خرابی قالب کلاچ) | H5: CNC، وایر ، تراش ، کروم ، مونتاژ ، سختکاری | I5: CNC، وایر ، تراش ، کروم ، مونتاژ ، سختکاری | J5: 0.87 | K5: Stop
A6: 3 | B6: شمش عقب پژو پایه بلند | C6: 9278/د/04 | D6: 9278/د/04 | K6: Stop
A7: 4 | B7: شمشی عقب پیکان | C7: 9278/د/04 | D7: 9278/د/04 | K7: Stop
A8: 5 | B8: عقب F12 | D8: 1405/02/08 | E8: 1405/04/20 | G8: در خواست متریال | H8: فرز | I8: فرز ، سنگ ، CNC ، سوراخکاری ، سختکاری(برون سپاری) ، وایر ، کروم(برون سپاری)، مونتاژ | J8: 0.05 | K8: Stop

Sheet 10
A1: New Project | I1: Date | J1: 1405
I2: Weeks | J2: 10
B3: Name | C3: شماره فنی | D3: تاریخ شروع | E3: پیش بینی تاریخ تحویل1 | F3: تاریخ تحویل 2 | G3: علت تاخیر در تحویل بموقع | H3: BPMN (OK) | I3: BPMN (NC) | J3: Baseline | K3: آخرین وظعیت
A4: 1 | B4: شمش ریو | C4: 9278/د/04 | D4: برون سپاری (اصفهان) امینی | K4: Stop
A5: 2 | B5: شمش عقب پژو پایه کوتاه | C5: 9278/د/04 | D5: تامین متریال | E5: 1404/09/10 | F5: 1404/11/10 1405/02/10 | G5: خرابی سنگ | H5: CNC، وایر ، تراش ، کروم ، مونتاژ ، سختکاری | I5: CNC، وایر ، تراش ، کروم ، مونتاژ ، سختکاری | J5: 0.87 | K5: Stop
A6: 3 | B6: شمش عقب پژو پایه بلند | C6: 9278/د/04 | D6: 9278/د/04 | K6: Stop
A7: 4 | B7: شمشی عقب پیکان | C7: 9278/د/04 | D7: 9278/د/04 | K7: Stop
A8: 5 | B8: عقب F12 | D8: 1405/02/08 | E8: 1405/04/20 | G8: در خواست متریال | H8: فرز | I8: فرز ، سنگ ، CNC ، سوراخکاری ، سختکاری(برون سپاری) ، وایر ، کروم(برون سپاری)، مونتاژ | J8: 0.05 | K8: Stop
A9: 6 | B9: قالب پخت دیسکی نیسان اریا | C9: 30303 | D9: 1403/03/05 | J9: تامین متریال | K9: Stop

Sheet 11
A1: New Project | I1: Date | J1: 1405
I2: Weeks | J2: 11
B3: Name | C3: شماره فنی | D3: تاریخ شروع | E3: پیش بینی تاریخ تحویل1 | F3: تاریخ تحویل 2 | G3: علت تاخیر در تحویل بموقع | H3: BPMN (OK) | I3: BPMN (NC) | J3: Baseline | K3: آخرین وظعیت
A4: 1 | B4: شمش ریو | C4: 9278/د/04 | D4: برون سپاری (اصفهان) امینی | K4: Stop
A5: 2 | B5: شمش عقب پژو پایه کوتاه | C5: 9278/د/04 | D5: تامین متریال | E5: 1404/09/10 | F5: 1404/11/10 1405/02/10 | G5: خرابی سنگ | H5: CNC، وایر ، تراش ، کروم ، مونتاژ ، سختکاری | I5: CNC، وایر ، تراش ، کروم ، مونتاژ ، سختکاری | J5: 0.87 | K5: Stop
A6: 3 | B6: شمش عقب پژو پایه بلند | C6: 9278/د/04 | D6: 9278/د/04 | K6: Stop
A7: 4 | B7: شمشی عقب پیکان | C7: 9278/د/04 | D7: 9278/د/04 | K7: Stop
A8: 5 | B8: عقب F12 | D8: 1405/02/08 | E8: 1405/04/20 | G8: در خواست متریال | H8: فرز | I8: فرز ، سنگ ، CNC ، سوراخکاری ، سختکاری(برون سپاری) ، وایر ، کروم(برون سپاری)، مونتاژ | J8: 0.05 | K8: Stop
A9: 6 | B9: قالب پخت دیسکی نیسان اریا | C9: 30303 | D9: 1403/03/05 | J9: تامین متریال | K9: Stop

Sheet 12
A1: New Project | I1: Date | J1: 1405
I2: Weeks | J2: 12
B3: Name | C3: شماره فنی | D3: تاریخ شروع | E3: پیش بینی تاریخ تحویل1 | F3: تاریخ تحویل 2 | G3: علت تاخیر در تحویل بموقع | H3: BPMN (OK) | I3: BPMN (NC) | J3: Baseline | K3: آخرین وظعیت
A4: 1 | B4: شمش ریو | C4: 9278/د/04 | D4: برون سپاری (اصفهان) امینی | K4: Stop
A5: 2 | B5: شمش عقب پژو پایه کوتاه | C5: 9278/د/04 | D5: تامین متریال | E5: 1404/09/10 | F5: 1404/11/10 1405/02/10 | G5: خرابی سنگ | H5: CNC، وایر ، تراش ، کروم ، مونتاژ ، سختکاری | I5: شیرازی(پیمانکاری) | J5: 0.87 | K5: CNC
A6: 3 | B6: شمش عقب پژو پایه بلند | C6: 9278/د/04 | D6: 9278/د/04 | K6: Stop
A7: 4 | B7: شمشی عقب پیکان | C7: 9278/د/04 | D7: 9278/د/04 | K7: Stop
A8: 5 | B8: عقب F12 | D8: 1405/02/08 | E8: 1405/04/20 | G8: در خواست متریال | H8: فرز | I8: فرز ، سنگ ، CNC ، سوراخکاری ، سختکاری(برون سپاری) ، وایر ، کروم(برون سپاری)، مونتاژ | J8: 0.15 | K8: سختکاری
A9: 6 | B9: قالب پخت دیسکی نیسان اریا | C9: 30303 | D9: 1403/03/05 | J9: تامین متریال | K9: Stop
A10: 7 | B10: شمش عقب پراید | C10: 9278/د/04 | D10: 1404/09/07 1405/03/18 | I10: شیرازی(پیمانکاری) | K10: CNC

Sheet 13
A1: New Project | I1: Date | J1: 1405
I2: Weeks | J2: 13
B3: Name | C3: شماره فنی | D3: تاریخ شروع | E3: پیش بینی تاریخ تحویل1 | F3: تاریخ تحویل 2 | G3: علت تاخیر در تحویل بموقع | H3: BPMN (OK) | I3: BPMN (NC) | J3: Baseline | K3: آخرین وظعیت
A4: 1 | B4: شمش ریو | C4: 9278/د/04 | D4: برون سپاری (اصفهان) امینی | K4: Stop
A5: 2 | B5: شمش عقب پژو پایه کوتاه | C5: 9278/د/04 | D5: تامین متریال | E5: 1404/09/10 | F5: 1404/11/10 1405/02/10 | G5: خرابی سنگ | H5: CNC، وایر ، تراش ، کروم ، مونتاژ ، سختکاری | I5: شیرازی(پیمانکاری) | J5: 0.87 | K5: CNC
A6: 3 | B6: شمش عقب پژو پایه بلند | C6: 9278/د/04 | D6: 9278/د/04 | K6: Stop
A7: 4 | B7: شمشی عقب پیکان | C7: 9278/د/04 | D7: 9278/د/04 | K7: Stop
A8: 5 | B8: عقب F12 | D8: 1405/02/08 | E8: 1405/04/20 | G8: در خواست متریال | H8: فرز | I8: فرز ، سنگ ، CNC ، سوراخکاری ، سختکاری(برون سپاری) ، وایر ، کروم(برون سپاری)، مونتاژ | J8: 0.15 | K8: سختکاری
A9: 6 | B9: قالب پخت دیسکی نیسان اریا | C9: 30303 | D9: 1403/03/05 | J9: تامین متریال | K9: Stop
A10: 7 | B10: شمش عقب پراید | C10: 9278/د/04 | D10: 1404/09/07 1405/03/18 | I10: تست | J10: 1 | K10: مونتاژ

Sheet 14
A1: New Project | I1: Date | J1: 1405
I2: Weeks | J2: 14
B3: Name | C3: شماره فنی | D3: تاریخ شروع | E3: پیش بینی تاریخ تحویل1 | F3: تاریخ تحویل 2 | G3: علت تاخیر در تحویل بموقع | H3: BPMN (OK) | I3: BPMN (NC) | J3: Baseline | K3: آخرین وظعیت
A4: 1 | B4: شمش ریو | C4: 9278/د/04 | D4: برون سپاری (اصفهان) امینی | K4: Stop
A5: 2 | B5: شمش عقب پژو پایه کوتاه | C5: 9278/د/04 | D5: تامین متریال | E5: 1404/09/10 | F5: 1404/11/10 1405/02/10 | G5: خرابی سنگ | H5: CNC، وایر ، تراش ، کروم ، مونتاژ ، سختکاری | I5: شیرازی(پیمانکاری) | J5: 0.87 | K5: CNC
A6: 3 | B6: شمش عقب پژو پایه بلند | C6: 9278/د/04 | D6: 9278/د/04 | K6: Stop
A7: 4 | B7: شمشی عقب پیکان | C7: 9278/د/04 | D7: 9278/د/04 | K7: Stop
A8: 5 | B8: عقب F12 | D8: 1405/02/08 | E8: 1405/04/20 | G8: در خواست متریال | H8: فرز | I8: فرز ، سنگ ، CNC ، سوراخکاری ، سختکاری(برون سپاری) ، وایر ، کروم(برون سپاری)، مونتاژ | J8: 0.15 | K8: سختکاری
A9: 6 | B9: قالب پخت دیسکی نیسان اریا | C9: 30303 | D9: 1403/03/05 | J9: تامین متریال | K9: Stop
A10: 7 | B10: شمش عقب پراید | C10: 9278/د/04 | D10: 1404/09/07 1405/03/18 | I10: تست | J10: 1 | K10: مونتاژ

Sheet 15
A1: New Project | J1: Date | K1: 1405
J2: Weeks | K2: 15
B3: Name | C3: واحد مصرف | D3: شماره فنی | E3: تاریخ شروع | F3: پیش بینی تاریخ تحویل1 | G3: تاریخ تحویل 2 | H3: علت تاخیر در تحویل بموقع | I3: BPMN (OK) | J3: BPMN (NC) | K3: Baseline | L3: آخرین وظعیت
A4: 1 | B4: شمش ریو | C4: جهان لنت | D4: 9278/د/04 | E4: برون سپاری (اصفهان) امینی | L4: Stop
A5: 2 | B5: شمش عقب پژو پایه کوتاه | C5: جهان لنت | D5: 9278/د/04 | E5: تامین متریال | F5: 1404/09/10 | G5: 1404/11/10 1405/02/10 | H5: خرابی سنگ | I5: CNC، وایر ، تراش ، کروم ، مونتاژ ، سختکاری | J5: شیرازی(پیمانکاری) | K5: 0.87 | L5: CNC
A6: 3 | B6: شمش عقب پژو پایه بلند | C6: جهان لنت | D6: 9278/د/04 | E6: 9278/د/04 | L6: Stop
A7: 4 | B7: شمشی عقب پیکان | C7: جهان لنت | D7: 9278/د/04 | E7: 9278/د/04 | L7: Stop
A8: 5 | B8: عقب F12 | C8: جهان لنت | E8: 1405/02/08 | F8: 1405/04/20 | I8: فرز | J8: فرز ، سنگ ، CNC ، سوراخکاری ، سختکاری(برون سپاری) ، وایر ، کروم(برون سپاری)، مونتاژ | K8: 0.15 | L8: سختکاری
A9: 6 | B9: قالب پخت دیسکی نیسان اریا | C9: جهان لنت | D9: 30303 | E9: 1403/03/05 | K9: تامین متریال | L9: Stop
A10: 7 | B10: شمش عقب پراید | C10: جهان لنت | D10: 9278/د/04 | E10: 1404/09/07 1405/03/18 | J10: تست | K10: 1 | L10: مونتاژ
A11: 8 | B11: لودر دیسکی XGL 50 | C11: پرس | D11: 29935 | E11: 1405/04/08 | I11: تامین متریال | J11: فرز ، سنگ ، CNC ، سوراخکاری ، سختکاری(برون سپاری) ، وایر ، کروم(برون سپاری)، مونتاژ | K11: 0 | L11: فرز
A12: 9 | B12: کامیونت هیوندای | C12: تولید جهان لنت | D12: 29889 | E12: 1405/04/10 | I12: تامین متریال | J12: فرز ، سنگ ، CNC ، سوراخکاری ، سختکاری(برون سپاری) ، وایر ، کروم(برون سپاری)، مونتاژ | K12: 0
A13: 10 | B13: کشنده ماموت -محور SAF | C13: تولید جهان لنت | D13: 29087 | E13: 1405/04/10 | F13: 1405/05/25 | I13: فرز | J13: فرز ، سنگ ، CNC ، سوراخکاری ، سختکاری(برون سپاری) ، وایر ، کروم(برون سپاری)، مونتاژ | K13: 0.03 | L13: فرز
A14: 11 | B14: لنت ترمز دیسكی جلو دیما(خم) | C14: پرس | D14: 30416 | E14: 1405/04/10 | I14: تامین متریال | J14: فرز ، سنگ ، CNC ، سوراخکاری ، سختکاری(برون سپاری) ، وایر ، کروم(برون سپاری)، مونتاژ | K14: 0
A15: 12 | B15: (جدید)C&C نیوفیس(جدید) | C15: پرس | D15: 29162 30487 | E15: 1405/04/10 | I15: تامین متریال | J15: فرز ، سنگ ، CNC ، سوراخکاری ، سختکاری(برون سپاری) ، وایر ، کروم(برون سپاری)، مونتاژ | K15: 0

Sheet 16
A1: New Project | J1: Date | K1: 1405
J2: Weeks | K2: 16
B3: Name | C3: واحد مصرف | D3: شماره فنی | E3: تاریخ شروع | F3: پیش بینی تاریخ تحویل1 | G3: تاریخ تحویل 2 | H3: علت تاخیر در تحویل بموقع | I3: BPMN (OK) | J3: BPMN (NC) | K3: Baseline | L3: آخرین وظعیت
A4: 1 | B4: شمش ریو | C4: جهان لنت | D4: 9278/د/04 | E4: برون سپاری (اصفهان) امینی | L4: Stop
A5: 2 | B5: شمش عقب پژو پایه کوتاه | C5: جهان لنت | D5: 9278/د/04 | E5: 1404/09/10 | F5: 1404/11/10 1405/02/10 | I5: CNC، وایر ، تراش ، کروم ، مونتاژ ، سختکاری | J5: شیرازی(پیمانکاری) | K5: 0.87 | L5: CNC
A6: 3 | B6: شمش عقب پژو پایه بلند | C6: جهان لنت | D6: 9278/د/04 | E6: 9278/د/04 | F6: 1405/04/18 | L6: Stop
A7: 4 | B7: شمشی عقب پیکان | C7: جهان لنت | D7: 9278/د/04 | E7: 9278/د/04 | L7: Stop
A8: 5 | B8: عقب F12 | C8: جهان لنت | E8: 1405/02/08 | F8: 1405/04/20 | I8: فرز | J8: فرز ، سنگ ، CNC ، سوراخکاری ، سختکاری(برون سپاری) ، وایر ، کروم(برون سپاری)، مونتاژ | K8: 0.15 | L8: سختکاری
A9: 6 | B9: قالب پخت دیسکی نیسان اریا | C9: جهان لنت | D9: 30303 | E9: 1405/04/17 | F9: 1405/06/01 | I9: فرز | J9: فرز ، سنگ ، CNC ، سوراخکاری ، سختکاری(برون سپاری) ، وایر ، کروم(برون سپاری)، مونتاژ | K9: 0.07 | L9: CNC
A10: 7 | B10: شمش عقب پراید | C10: جهان لنت | D10: 9278/د/04 | E10: 1404/09/07 1405/03/18 | J10: تست | K10: 1 | L10: مونتاژ
A11: 8 | B11: لودر دیسکی XGL 50 | C11: پرس | D11: 29935 | E11: 1405/04/17 | I11: تامین متریال | J11: فرز ، سنگ ، CNC ، سوراخکاری ، سختکاری(برون سپاری) ، وایر ، کروم(برون سپاری)، مونتاژ | K11: 0.05 | L11: فرز
A12: 9 | B12: کامیونت هیوندای | C12: تولید جهان لنت | D12: 29889 | J12: فرز ، سنگ ، CNC ، سوراخکاری ، سختکاری(برون سپاری) ، وایر ، کروم(برون سپاری)، مونتاژ | K12: 0 | L12: تامین متریال
A13: 10 | B13: کشنده ماموت -محور SAF | C13: تولید جهان لنت | D13: 29087 | E13: 1405/04/10 | F13: 1405/05/25 | I13: فرز | J13: فرز ، سنگ ، CNC ، سوراخکاری ، سختکاری(برون سپاری) ، وایر ، کروم(برون سپاری)، مونتاژ | K13: 0.07 | L13: فرز
A14: 11 | B14: لنت ترمز دیسكی جلو دیما(خم) | C14: پرس | D14: 30416 | E14: 1405/04/17 | F14: 1405/05/20 | I14: فرز | J14: فرز ، سنگ ، CNC ، سوراخکاری ، سختکاری(برون سپاری) ، وایر ، کروم(برون سپاری)، مونتاژ | K14: 0.1 | L14: CNC
A15: 12 | B15: (جدید)C&C نیوفیس(جدید) | C15: پرس | D15: 29162 30487 | E15: 1405/04/17 | F15: 1405/05/20 | J15: فرز ، سنگ ، CNC ، سوراخکاری ، سختکاری(برون سپاری) ، وایر ، کروم(برون سپاری)، مونتاژ | K15: 0.03 | L15: فرز
A16: 13 | B16: پخت کلاچ تیبا چپ(فلش) | C16: تولید جهان ترمز | D16: 30247 | E16: 1405/04/18 | J16: فرز ، سنگ ، CNC ، سوراخکاری ، سختکاری(برون سپاری) ، وایر ، کروم(برون سپاری)، مونتاژ | K16: 0 | L16: تامین متریال
A17: 14 | B17: پخت کلاچ تیبا راست(فلش) | C17: تولید جهان ترمز | D17: 30278 | E17: 1405/04/18 | J17: فرز ، سنگ ، CNC ، سوراخکاری ، سختکاری(برون سپاری) ، وایر ، کروم(برون سپاری)، مونتاژ | K17: 0 | L17: تامین متریال
A18: 15

Sheet 17
A1: New Project | J1: Date | K1: 1405
J2: Weeks | K2: 17
B3: Name | C3: واحد مصرف | D3: شماره فنی | E3: تاریخ شروع | F3: پیش بینی تاریخ تحویل1 | G3: تاریخ تحویل 2 | H3: علت تاخیر در تحویل بموقع | I3: BPMN (OK) | J3: BPMN (NC) | K3: Baseline | L3: آخرین وظعیت
A4: 1 | B4: شمش ریو | C4: جهان لنت | D4: 9278/د/04 | E4: برون سپاری (اصفهان) امینی | L4: Stop
A5: 2 | B5: شمش عقب پژو پایه کوتاه | C5: جهان لنت | D5: 9278/د/04 | E5: 1404/09/10 | F5: 1404/11/10 1405/02/10 | I5: CNC، وایر ، تراش ، کروم ، مونتاژ ، سختکاری | J5: شیرازی(پیمانکاری) | K5: 0.87 | L5: CNC
A6: 3 | B6: شمش عقب پژو پایه بلند | C6: جهان لنت | D6: 9278/د/04 | E6: 9278/د/04 | F6: 1405/04/18 | L6: Stop
A7: 4 | B7: شمشی عقب پیکان | C7: جهان لنت | D7: 9278/د/04 | E7: 9278/د/04 | L7: Stop
A8: 5 | B8: عقب F12 | C8: جهان لنت | E8: 1405/02/08 | F8: 1405/04/20 | I8: فرز، سختکاری ، CNC | J8: فرز ، سنگ ، CNC ، سوراخکاری ، سختکاری(برون سپاری) ، وایر ، کروم(برون سپاری)، مونتاژ | K8: 0.2 | L8: وایر
A9: 6 | B9: قالب پخت دیسکی نیسان اریا | C9: جهان لنت | D9: 30303 | E9: 1405/04/17 | F9: 1405/06/01 | I9: فرز، سختکاری ، CNC | J9: فرز ، سنگ ، CNC ، سوراخکاری ، سختکاری(برون سپاری) ، وایر ، کروم(برون سپاری)، مونتاژ | K9: 0.12 | L9: وایر
A10: 7 | B10: شمش عقب پراید | C10: جهان لنت | D10: 9278/د/04 | E10: 1404/09/07 1405/03/18 | J10: تست | K10: 1 | L10: مونتاژ
A11: 8 | B11: لودر دیسکی XGL 50 | C11: پرس | D11: 29935 | E11: 1405/04/17 | I11: فرز | J11: فرز ، سنگ ، CNC ، سوراخکاری ، سختکاری(برون سپاری) ، وایر ، کروم(برون سپاری)، مونتاژ | K11: 0.15 | L11: CNC
A12: 9 | B12: کامیونت هیوندای | C12: تولید جهان لنت | D12: 29889 | J12: فرز ، سنگ ، CNC ، سوراخکاری ، سختکاری(برون سپاری) ، وایر ، کروم(برون سپاری)، مونتاژ | K12: 0 | L12: تامین متریال
A13: 10 | B13: کشنده ماموت -محور SAF | C13: تولید جهان لنت | D13: 29087 | E13: 1405/04/10 | F13: 1405/05/25 | I13: فرز | J13: فرز ، سنگ ، CNC ، سوراخکاری ، سختکاری(برون سپاری) ، وایر ، کروم(برون سپاری)، مونتاژ | K13: 0.1 | L13: سختکاری
A14: 11 | B14: لنت ترمز دیسكی جلو دیما(خم) | C14: پرس | D14: 30416 | E14: 1405/04/17 | F14: 1405/05/20 | I14: فرز | J14: فرز ، سنگ ، CNC ، سوراخکاری ، سختکاری(برون سپاری) ، وایر ، کروم(برون سپاری)، مونتاژ | K14: 0.1 | L14: CNC
A15: 12 | B15: (جدید)C&C نیوفیس(جدید) | C15: پرس | D15: 29162 30487 | E15: 1405/04/17 | F15: 1405/05/20 | J15: فرز ، سنگ ، CNC ، سوراخکاری ، سختکاری(برون سپاری) ، وایر ، کروم(برون سپاری)، مونتاژ | K15: 0.05 | L15: فرز
A16: 13 | B16: پخت کلاچ تیبا چپ(فلش) | C16: تولید جهان ترمز | D16: 30247 | E16: 1405/04/18 | J16: فرز ، سنگ ، CNC ، سوراخکاری ، سختکاری(برون سپاری) ، وایر ، کروم(برون سپاری)، مونتاژ | K16: 0 | L16: تامین متریال
A17: 14 | B17: پخت کلاچ تیبا راست(فلش) | C17: تولید جهان ترمز | D17: 30278 | E17: 1405/04/18 | J17: فرز ، سنگ ، CNC ، سوراخکاری ، سختکاری(برون سپاری) ، وایر ، کروم(برون سپاری)، مونتاژ | K17: 0 | L17: تامین متریال
A18: 15

Sheet 18
A1: New Project | J1: Date | K1: 1405
J2: Weeks | K2: 18
B3: Name | C3: واحد مصرف | D3: شماره فنی | E3: تاریخ شروع | F3: پیش بینی تاریخ تحویل1 | G3: تاریخ تحویل 2 | H3: علت تاخیر در تحویل بموقع | I3: BPMN (OK) | J3: BPMN (NC) | K3: Baseline | L3: آخرین وظعیت
A4: 1 | B4: شمش ریو | C4: جهان لنت | D4: 9278/د/04 | E4: برون سپاری (اصفهان) امینی | L4: Stop
A5: 2 | B5: شمش عقب پژو پایه کوتاه | C5: جهان لنت | D5: 9278/د/04 | E5: 1404/09/10 | F5: 1404/11/10 1405/02/10 1405/05/31 | I5: CNC، وایر ، تراش ، کروم ، مونتاژ ، سختکاری | J5: CNC ، Wier ، Assemble ، Test | K5: 0.87 | L5: CNC
A6: 3 | B6: شمشی عقب پیکان | C6: جهان لنت | D6: 9278/د/04 | E6: 9278/د/04 | I6: CNC، وایر ، تراش ، کروم ، مونتاژ ، سختکاری | J6: CNC ، Wier ، Assemble ، Test | K6: 0.15 | L6: فرز
A7: 4 | B7: عقب F12 | C7: جهان لنت | E7: 1405/02/08 | F7: 1405/04/20 | I7: فرز، سختکاری ، CNC | J7: فرز ، سنگ ، CNC ، سوراخکاری ، سختکاری(برون سپاری) ، وایر ، کروم(برون سپاری)، مونتاژ | K7: 0.3 | L7: CNC
A8: 5 | B8: قالب پخت دیسکی نیسان اریا | C8: جهان لنت | D8: 30303 | E8: 1405/04/17 | F8: 1405/06/01 | I8: فرز، سختکاری ، CNC | J8: سوراخکاری ، وایر ، کروم(برون سپاری)، مونتاژ | K8: 0.63 | L8: Wier EMD
A9: 6 | B9: لودر دیسکی XGL 50 | C9: پرس | D9: 29935 | E9: 1405/04/17 | I9: فرز، سختکاری ، CNC | J9: ، وایر ، کروم(برون سپاری)، مونتاژ | K9: 0.45 | L9: CNC
A10: 7 | B10: کامیونت هیوندای | C10: تولید جهان لنت | D10: 29889 | J10: فرز ، سنگ ، CNC ، سوراخکاری ، سختکاری(برون سپاری) ، وایر ، کروم(برون سپاری)، مونتاژ | K10: 0 | L10: تامین متریال
A11: 8 | B11: کشنده ماموت -محور SAF | C11: تولید جهان لنت | D11: 29087 | E11: 1405/04/10 | F11: 1405/05/25 | I11: فرز ، سختکاری | J11: فرز ، سنگ ، CNC ، سوراخکاری ، سختکاری(برون سپاری) ، وایر ، کروم(برون سپاری)، مونتاژ | K11: 0.25 | L11: وایر
A12: 9 | B12: لنت ترمز دیسكی جلو دیما(خم) | C12: پرس | D12: 30416 | E12: 1405/04/17 | F12: 1405/05/20 | I12: فرز،CNC، سوراخکاری ، Wier سختکاری, | J12: Assamble ، CNC ، | K12: 0.89 | L12: CNC
A13: 10 | B13: (جدید)C&C نیوفیس(جدید) | C13: پرس | D13: 29162 30487 | E13: 1405/04/17 | F13: 1405/05/20 | I13: فرز،CNC، سوراخکاری ، Wier | J13: Assamble ، سختکاری | K13: 0.45 | L13: سختکاری
A14: 11 | B14: پخت کلاچ تیبا چپ(فلش) | C14: تولید جهان ترمز | D14: 30247 | J14: فرز ، سنگ ، CNC ، سوراخکاری ، سختکاری(برون سپاری) ، وایر ، کروم(برون سپاری)، مونتاژ | K14: 0 | L14: تامین متریال
A15: 12 | B15: پخت کلاچ تیبا راست(فلش) | C15: تولید جهان ترمز | D15: 30278 | J15: فرز ، سنگ ، CNC ، سوراخکاری ، سختکاری(برون سپاری) ، وایر ، کروم(برون سپاری)، مونتاژ | K15: 0 | L15: تامین متریال
A16: 13 | B16: شمش عقب پژو 405 پایه بلند | C16: جهان لنت | D16: 9278/د/04 | J16: فرز ، سنگ ، CNC ، سوراخکاری ، سختکاری(برون سپاری) ، وایر ، کروم(برون سپاری)، مونتاژ | K16: 0 | L16: تامین متریال
A17: 14 | B17: شمش جلو نیسان | C17: جهان لنت | D17: 9278/د/04 | J17: فرز ، سنگ ، CNC ، سوراخکاری ، سختکاری(برون سپاری) ، وایر ، کروم(برون سپاری)، مونتاژ | K17: 0 | L17: تامین متریال

Sheet 19
A1: New Project | J1: Date | K1: 1405
J2: Weeks | K2: 19
B3: Name | C3: واحد مصرف | D3: شماره فنی | E3: تاریخ شروع | F3: پیش بینی تاریخ تحویل1 | G3: تاریخ تحویل 2 | H3: علت تاخیر در تحویل بموقع | I3: BPMN (OK) | J3: BPMN (NC) | K3: Baseline | L3: آخرین وظعیت
A4: 1 | B4: شمش ریو | C4: جهان لنت | D4: 9278/د/04 | E4: برون سپاری (اصفهان) امینی | L4: Stop
A5: 2 | B5: شمش عقب پژو پایه کوتاه | C5: جهان لنت | D5: 9278/د/04 | E5: 1404/09/10 | F5: 1404/11/10 1405/02/10 1405/05/31 | I5: CNC، وایر ، تراش ، کروم ، مونتاژ ، سختکاری | J5: CNC ، Wier ، Assemble ، Test | K5: 0.87 | L5: CNC
A6: 3 | B6: شمشی عقب پیکان | C6: جهان لنت | D6: 9278/د/04 | E6: 9278/د/04 | I6: CNC، وایر ، تراش ، کروم ، مونتاژ ، سختکاری | J6: CNC ، Wier ، Assemble ، Test | K6: 0.15 | L6: فرز
A7: 4 | B7: عقب F12 | C7: جهان لنت | E7: 1405/02/08 | F7: 1405/04/20 | I7: فرز، سختکاری ، CNC | J7: فرز ، سنگ ، CNC ، سوراخکاری ، سختکاری(برون سپاری) ، وایر ، کروم(برون سپاری)، مونتاژ | K7: 0.3 | L7: CNC
A8: 5 | B8: قالب پخت دیسکی نیسان اریا | C8: جهان لنت | D8: 30303 | E8: 1405/04/17 | F8: 1405/06/01 | I8: فرز، سختکاری ، CNC | J8: سوراخکاری ، وایر ، کروم(برون سپاری)، مونتاژ | K8: 0.63 | L8: Wier EMD
A9: 6 | B9: لودر دیسکی XGL 50 | C9: پرس | D9: 29935 | E9: 1405/04/17 | I9: فرز، سختکاری ، CNC | J9: ، وایر ، کروم(برون سپاری)، مونتاژ | K9: 0.45 | L9: CNC
A10: 7 | B10: کامیونت هیوندای | C10: تولید جهان لنت | D10: 29889 | J10: فرز ، سنگ ، CNC ، سوراخکاری ، سختکاری(برون سپاری) ، وایر ، کروم(برون سپاری)، مونتاژ | K10: 0 | L10: تامین متریال
A11: 8 | B11: کشنده ماموت -محور SAF | C11: تولید جهان لنت | D11: 29087 | E11: 1405/04/10 | F11: 1405/05/25 | I11: فرز ، سختکاری | J11: فرز ، سنگ ، CNC ، سوراخکاری ، سختکاری(برون سپاری) ، وایر ، کروم(برون سپاری)، مونتاژ | K11: 0.25 | L11: وایر
A12: 9 | B12: لنت ترمز دیسكی جلو دیما(خم) | C12: پرس | D12: 30416 | E12: 1405/04/17 | F12: 1405/05/20 | I12: فرز،CNC، سوراخکاری ، Wier سختکاری, | J12: Assamble ، CNC ، | K12: 0.89 | L12: CNC
A13: 10 | B13: (جدید)C&C نیوفیس(جدید) | C13: پرس | D13: 29162 30487 | E13: 1405/04/17 | F13: 1405/05/20 | I13: فرز،CNC، سوراخکاری ، Wier | J13: Assamble ، سختکاری | K13: 0.45 | L13: سختکاری
A14: 11 | B14: پخت کلاچ تیبا چپ(فلش) | C14: تولید جهان ترمز | D14: 30247 | J14: فرز ، سنگ ، CNC ، سوراخکاری ، سختکاری(برون سپاری) ، وایر ، کروم(برون سپاری)، مونتاژ | K14: 0 | L14: تامین متریال
A15: 12 | B15: پخت کلاچ تیبا راست(فلش) | C15: تولید جهان ترمز | D15: 30278 | J15: فرز ، سنگ ، CNC ، سوراخکاری ، سختکاری(برون سپاری) ، وایر ، کروم(برون سپاری)، مونتاژ | K15: 0 | L15: تامین متریال
A16: 13 | B16: شمش عقب پژو 405 پایه بلند | C16: جهان لنت | D16: 9278/د/04 | J16: فرز ، سنگ ، CNC ، سوراخکاری ، سختکاری(برون سپاری) ، وایر ، کروم(برون سپاری)، مونتاژ | K16: 0 | L16: تامین متریال
A17: 14 | B17: شمش جلو نیسان | C17: جهان لنت | D17: 9278/د/04 | J17: فرز ، سنگ ، CNC ، سوراخکاری ، سختکاری(برون سپاری) ، وایر ، کروم(برون سپاری)، مونتاژ | K17: 0 | L17: تامین متریال

Sheet 20
A1: New Project | J1: Date | K1: 1405
J2: Weeks | K2: 20
B3: Name | C3: واحد مصرف | D3: شماره فنی | E3: تاریخ شروع | F3: پیش بینی تاریخ تحویل1 | G3: تاریخ تحویل 2 | H3: علت تاخیر در تحویل بموقع | I3: BPMN (OK) | J3: BPMN (NC) | K3: Baseline | L3: آخرین وظعیت
A4: 1 | B4: شمش ریو | C4: جهان لنت | D4: 9278/د/04 | E4: برون سپاری (اصفهان) امینی | L4: Stop
A5: 2 | B5: شمش عقب پژو پایه کوتاه | C5: جهان لنت | D5: 9278/د/04 | E5: 1404/09/10 | F5: 1404/11/10 1405/02/10 1405/05/31 | I5: CNC، وایر ، تراش ، کروم ، مونتاژ ، سختکاری | J5: CNC ، Wier ، Assemble ، Test | K5: 0.87 | L5: CNC
A6: 3 | B6: شمشی عقب پیکان | C6: جهان لنت | D6: 9278/د/04 | E6: 9278/د/04 | I6: CNC، وایر ، تراش ، کروم ، مونتاژ ، سختکاری | J6: CNC ، Wier ، Assemble ، Test | K6: 0.15 | L6: فرز
A7: 4 | B7: عقب F12 | C7: جهان لنت | E7: 1405/02/08 | F7: 1405/04/20 | I7: فرز، سختکاری ، CNC | J7: فرز ، سنگ ، CNC ، سوراخکاری ، سختکاری(برون سپاری) ، وایر ، کروم(برون سپاری)، مونتاژ | K7: 0.3 | L7: CNC
A8: 5 | B8: قالب پخت دیسکی نیسان اریا | C8: جهان لنت | D8: 30303 | E8: 1405/04/17 | F8: 1405/06/01 | I8: فرز، سختکاری ، CNC، سوراخکاری ، وایر | J8: ، کروم(برون سپاری)، مونتاژ | K8: 0.74 | L8: Chrome
A9: 6 | B9: لودر دیسکی XGL 50 | C9: پرس | D9: 29935 | E9: 1405/04/17 | H9: CNC | I9: فرز، سختکاری ، CNC | J9: ، وایر ، کروم(برون سپاری)، مونتاژ | K9: 0.45 | L9: Wier EMD
A10: 7 | B10: کامیونت هیوندای | C10: تولید جهان لنت | D10: 29889 | J10: فرز ، سنگ ، CNC ، سوراخکاری ، سختکاری(برون سپاری) ، وایر ، کروم(برون سپاری)، مونتاژ | K10: 0 | L10: تامین متریال
A11: 8 | B11: کشنده ماموت -محور SAF | C11: تولید جهان لنت | D11: 29087 | E11: 1405/04/10 | F11: 1405/05/25 | I11: فرز ، سختکاری | J11: فرز ، سنگ ، CNC ، سوراخکاری ، سختکاری(برون سپاری) ، وایر ، کروم(برون سپاری)، مونتاژ | K11: 0.25 | L11: وایر
A12: 9 | B12: لنت ترمز دیسكی جلو دیما(خم) | C12: پرس | D12: 30416 | E12: 1405/04/17 | F12: 1405/05/20 | I12: فرز،CNC، سوراخکاری ، Wier سختکاری,Assamble ، CNC ، | K12: 1 | L12: Test
A13: 10 | B13: (جدید)C&C نیوفیس(جدید) | C13: پرس | D13: 29162 30487 | E13: 1405/04/17 | F13: 1405/05/20 | I13: فرز،CNC، سوراخکاری ، Wier | J13: Assamble ، سختکاری | K13: 0.45 | L13: سختکاری
A14: 11 | B14: پخت کلاچ تیبا چپ(فلش) | C14: تولید جهان ترمز | D14: 30247 | E14: 1405/05/11 | F14: 1405/06/27 | J14: فرز ، سنگ ، CNC ، سوراخکاری ، سختکاری(برون سپاری) ، وایر ، کروم(برون سپاری)، مونتاژ | K14: 0.05 | L14: فرز
A15: 12 | B15: پخت کلاچ تیبا راست(فلش) | C15: تولید جهان ترمز | D15: 30278 | E15: 1405/05/11 | F15: 1405/06/27 | J15: فرز ، سنگ ، CNC ، سوراخکاری ، سختکاری(برون سپاری) ، وایر ، کروم(برون سپاری)، مونتاژ | K15: 0.05 | L15: فرز
A16: 13 | B16: شمش عقب پژو 405 پایه بلند | C16: جهان لنت | D16: 9278/د/04 | J16: فرز ، سنگ ، CNC ، سوراخکاری ، سختکاری(برون سپاری) ، وایر ، کروم(برون سپاری)، مونتاژ | K16: 0 | L16: تامین متریال
A17: 14 | B17: شمش جلو نیسان | C17: جهان لنت | D17: 9278/د/04 | J17: فرز ، سنگ ، CNC ، سوراخکاری ، سختکاری(برون سپاری) ، وایر ، کروم(برون سپاری)، مونتاژ | K17: 0 | L17: تامین متریال

Sheet 21
A1: New Project | J1: Date | K1: 1405
J2: Weeks | K2: 21
B3: Name | C3: واحد مصرف | D3: شماره فنی | E3: تاریخ شروع | F3: پیش بینی تاریخ تحویل1 | G3: تاریخ تحویل 2 | H3: علت تاخیر در تحویل بموقع | I3: فرایند (OK) | J3: فرایند (NC) | K3: درصد پیشرفت | L3: آخرین وظعیت
A4: 1 | B4: شمش ریو | C4: جهان لنت | D4: 9278/د/04 | E4: برون سپاری (اصفهان) امینی | I4: CNC، وایر ، تراش ، کروم ، مونتاژ ، سختکاری | J4: CNC ، Wier ، Assemble ، Test | K4: 0.25 | L4: CNC
A5: 2 | B5: شمش عقب پژو پایه کوتاه | C5: جهان لنت | D5: 9278/د/04 | E5: 1404/09/10 | F5: 1404/11/10 1405/02/10 1405/05/31 | I5: CNC، وایر ، تراش ، کروم ، مونتاژ ، سختکاری | J5: CNC ، Wier ، Assemble ، Test | K5: 0.9 | L5: CNC
A6: 3 | B6: شمشی عقب پیکان | C6: جهان لنت | D6: 9278/د/04 | E6: 9278/د/04 | I6: CNC، وایر ، تراش ، کروم ، مونتاژ ، سختکاری | J6: CNC ، Wier ، Assemble ، Test | K6: 0.2 | L6: فرز
A7: 4 | B7: عقب F12 | C7: جهان لنت | E7: 1405/02/08 | F7: 1405/04/20 | I7: فرز ، سنگ ، CNC ، سوراخکاری ، سختکاری(برون سپاری) ، | J7: ، کروم(برون سپاری)، مونتاژ | K7: 0.8 | L7: Chrome
A8: 5 | B8: قالب پخت دیسکی نیسان اریا | C8: جهان لنت | D8: 30303 | E8: 1405/04/17 | F8: 1405/06/01 | I8: فرز، سختکاری ، CNC، سوراخکاری ، وایر | J8: ، کروم(برون سپاری)، مونتاژ | K8: 0.8 | L8: Chrome
A9: 6 | B9: لودر دیسکی XGL 50 | C9: پرس | D9: 29935 | E9: 1405/04/17 | H9: CNC | I9: فرز، سختکاری ، CNC | J9: ، وایر ، کروم(برون سپاری)، مونتاژ | K9: 0.45 | L9: Wier EMD
A10: 7 | B10: کامیونت هیوندای | C10: تولید جهان لنت | D10: 29889 | J10: فرز ، سنگ ، CNC ، سوراخکاری ، سختکاری(برون سپاری) ، وایر ، کروم(برون سپاری)، مونتاژ | K10: 0 | L10: تامین متریال
A11: 8 | B11: کشنده ماموت -محور SAF | C11: تولید جهان لنت | D11: 29087 | E11: 1405/04/10 | F11: 1405/05/25 | I11: فرز ، سنگ ، CNC ، سوراخکاری ، سختکاری(برون سپاری) ، | J11: ، کروم(برون سپاری)، مونتاژ | K11: 0.8 | L11: Chrome
A12: 9 | B12: (جدید)C&C نیوفیس(جدید) | C12: پرس | D12: 29162 30487 | E12: 1405/04/17 | F12: 1405/05/20 1405/06/13 | I12: فرز،CNC، سوراخکاری ، Wier | J12: Assamble ،,wier | K12: 0.65 | L12: Wier EMD
A13: 10 | B13: پخت کلاچ تیبا چپ(فلش) | C13: تولید جهان ترمز | D13: 30247 | E13: 1405/05/11 | F13: 1405/06/27 | J13: فرز ، سنگ ، CNC ، سوراخکاری ، سختکاری(برون سپاری) ، وایر ، کروم(برون سپاری)، مونتاژ | K13: 0.05 | L13: فرز
A14: 11 | B14: پخت کلاچ تیبا راست(فلش) | C14: تولید جهان ترمز | D14: 30278 | E14: 1405/05/11 | F14: 1405/06/27 | J14: فرز ، سنگ ، CNC ، سوراخکاری ، سختکاری(برون سپاری) ، وایر ، کروم(برون سپاری)، مونتاژ | K14: 0.05 | L14: فرز
A15: 12 | B15: شمش عقب پژو 405 پایه بلند | C15: جهان لنت | D15: 9278/د/04 | J15: فرز ، سنگ ، CNC ، سوراخکاری ، سختکاری(برون سپاری) ، وایر ، کروم(برون سپاری)، مونتاژ | K15: 0 | L15: تامین متریال
A16: 13 | B16: شمش جلو نیسان | C16: جهان لنت | D16: 9278/د/04 | J16: فرز ، سنگ ، CNC ، سوراخکاری ، سختکاری(برون سپاری) ، وایر ، کروم(برون سپاری)، مونتاژ | K16: 0 | L16: تامین متریال

Sheet 22
A1: New Project | J1: Date | K1: 1405
J2: Weeks | K2: 22
B3: Name | C3: واحد مصرف | D3: شماره فنی | E3: تاریخ شروع | F3: پیش بینی تاریخ تحویل1 | G3: تاریخ تحویل 2 | H3: علت تاخیر در تحویل بموقع | I3: فرایند (OK) | J3: فرایند (NC) | K3: درصد پیشرفت | L3: آخرین وظعیت
A4: 1 | B4: شمش ریو | C4: جهان لنت | D4: 9278/د/04 | E4: برون سپاری (اصفهان) امینی | I4: CNC، وایر ، تراش ، کروم ، مونتاژ ، سختکاری | J4: CNC ، Wier ، Assemble ، Test | K4: 0.42 | L4: CNC
A5: 2 | B5: شمش عقب پژو پایه کوتاه | C5: جهان لنت | D5: 9278/د/04 | E5: 1404/09/10 | F5: 1404/11/10 1405/02/10 1405/05/31 | I5: CNC، وایر ، تراش ، مونتاژ ، سختکاری | J5: CNC ، Wier ، Assemble ، Test ، کروم | K5: 0.9 | L5: CNC
A6: 3 | B6: شمشی عقب پیکان | C6: جهان لنت | D6: 9278/د/04 | E6: 9278/د/04 | I6: CNC، وایر ، تراش ، ، Wier ،، مونتاژ ، سختکاری | J6: CNC ، Wier ، Assemble ، Test ، کروم | K6: 0.75 | L6: CNC
A7: 4 | B7: عقب F12 | C7: جهان لنت | E7: 1405/02/08 | F7: 1405/04/20 | G7: 1405/06/20 | H7: سنگ زنی | I7: فرز ، سنگ ، CNC ، سوراخکاری ، سختکاری(برون سپاری) ، | J7: کروم (برون سپاری) سنگ،مونتاژ | K7: 0.8 | L7: Chrome
A8: 5 | B8: قالب پخت دیسکی نیسان اریا | C8: جهان لنت | D8: 30303 | E8: 1405/04/17 | F8: 1405/06/01 | I8: فرز، سختکاری ، CNC، سوراخکاری ، وایر | J8: ، کروم(برون سپاری)، مونتاژ | K8: 1 | L8: Assamble
A9: 6 | B9: لودر دیسکی XGL 50 | C9: پرس | D9: 29935 | E9: 1405/04/17 | H9: CNC | I9: فرز، سختکاری ، CNC، وایر ، کروم(برون سپاری) | J9: ، مونتاژ | K9: 0.9 | L9: مونتاژ
A10: 7 | B10: کامیونت هیوندای | C10: تولید جهان لنت | D10: 29889 | J10: فرز ، سنگ ، CNC ، سوراخکاری ، سختکاری(برون سپاری) ، وایر ، کروم(برون سپاری)، مونتاژ | K10: 0 | L10: تامین متریال
A11: 8 | B11: کشنده ماموت -محور SAF | C11: تولید جهان لنت | D11: 29087 | E11: 1405/04/10 | F11: 1405/05/25 | I11: فرز ، سختکاری | J11: فرز ، سنگ ، CNC ، سوراخکاری ، سختکاری(برون سپاری) ، وایر ، کروم(برون سپاری)، مونتاژ | K11: 0.55 | L11: سختکاری
A12: 9 | B12: (جدید)C&C نیوفیس(جدید) | C12: پرس | D12: 29162 30487 | E12: 1405/04/17 | F12: 1405/05/20 | I12: فرز،CNC، سوراخکاری ، Wier | J12: Assamble ، سختکاری | K12: 0.65 | L12: سختکاری
A13: 10 | B13: پخت کلاچ تیبا چپ(فلش) | C13: تولید جهان ترمز | D13: 30247 | E13: 1405/05/11 | F13: 1405/06/27 | H13: عدم ارسال به کروم (بموقع) ، تاریخ درخواست 1405/06/01 | I13: فرز ، سنگ ، CNC ، سوراخکاری ، سختکاری(برون سپاری) ، | J13: فرز ، سنگ ، CNC ، سوراخکاری ، سختکاری(برون سپاری) ، وایر ، کروم(برون سپاری)، مونتاژ | K13: 0.25 | L13: سختکاری
A14: 11 | B14: پخت کلاچ تیبا راست(فلش) | C14: تولید جهان ترمز | D14: 30278 | E14: 1405/05/11 | F14: 1405/06/27 | H14: عدم ارسال به کروم (بموقع) ، تاریخ درخواست 1405/06/01 | I14: فرز ، سنگ ، CNC ، سوراخکاری ، سختکاری(برون سپاری) ، | J14: فرز ، سنگ ، CNC ، سوراخکاری ، سختکاری(برون سپاری) ، وایر ، کروم(برون سپاری)، مونتاژ | K14: 0.25 | L14: سختکاری
A15: 12 | B15: شمش عقب پژو 405 پایه بلند | C15: جهان لنت | D15: 9278/د/04 | J15: فرز ، سنگ ، CNC ، سوراخکاری ، سختکاری(برون سپاری) ، وایر ، کروم(برون سپاری)، مونتاژ | K15: 0 | L15: تامین متریال
A16: 13 | B16: شمش جلو نیسان | C16: جهان لنت | D16: 9278/د/04 | J16: فرز ، سنگ ، CNC ، سوراخکاری ، سختکاری(برون سپاری) ، وایر ، کروم(برون سپاری)، مونتاژ | K16: 0 | L16: تامین متریال

Sheet 23
A1: New Project | J1: Date | K1: 1405
J2: Weeks | K2: 23
B3: Name | C3: واحد مصرف | D3: شماره فنی | E3: تاریخ شروع | F3: پیش بینی تاریخ تحویل1 | G3: تاریخ تحویل 2 | H3: علت تاخیر در تحویل بموقع | I3: فرایند (OK) | J3: فرایند (NC) | K3: درصد پیشرفت | L3: آخرین وظعیت
A4: 1 | B4: شمش ریو | C4: جهان لنت | D4: 9278/د/04 | E4: برون سپاری (اصفهان) امینی | I4: CNC، وایر ، تراش ، کروم ، مونتاژ ، سختکاری | J4: CNC ، Wier ، Assemble ، Test | K4: 0.42 | L4: CNC
A5: 2 | B5: شمش عقب پژو پایه کوتاه | C5: جهان لنت | D5: 9278/د/04 | E5: 1404/09/10 | F5: 1405/07/10 | I5: CNC، وایر ، تراش ، مونتاژ ، سختکاری | J5: CNC ، Wier ، Assemble ، Test ، کروم | K5: 0.9 | L5: CNC
A6: 3 | B6: شمشی عقب پیکان | C6: جهان لنت | D6: 9278/د/04 | E6: 9278/د/04 | F6: 1405/06/30 | I6: CNC، وایر ، تراش ، ، Wier ،، مونتاژ ، سختکاری | J6: CNC ، Wier ، Assemble ، Test ، کروم | K6: 0.75 | L6: CNC
A7: 4 | B7: عقب F12 | C7: جهان لنت | E7: 1405/02/08 | F7: 1405/06/31 | I7: فرز ، سنگ ، CNC ، سوراخکاری ، سختکاری(برون سپاری) ، | J7: کروم (برون سپاری) سنگ،مونتاژ | K7: 0.8 | L7: Chrome
A8: 5 | B8: قالب پخت دیسکی نیسان اریا | C8: جهان لنت | D8: 30303 | E8: 1405/04/17 | F8: 1405/07/01 | I8: فرز، سختکاری ، CNC، سوراخکاری ، وایر | J8: ، کروم(برون سپاری)، مونتاژ | K8: 1 | L8: Assamble
A9: 6 | B9: لودر دیسکی XGL 50 | C9: پرس | D9: 29935 | E9: 1405/04/17 | F9: 1405/07/15 | H9: CNC | I9: فرز، سختکاری ، CNC، وایر ، کروم(برون سپاری) | J9: ، مونتاژ | K9: 0.9 | L9: مونتاژ
A10: 7 | B10: کامیونت هیوندای | C10: تولید جهان لنت | D10: 29889 | J10: فرز ، سنگ ، CNC ، سوراخکاری ، سختکاری(برون سپاری) ، وایر ، کروم(برون سپاری)، مونتاژ | K10: 0 | L10: تامین متریال
A11: 8 | B11: کشنده ماموت -محور SAF | C11: تولید جهان لنت | D11: 29087 | E11: 1405/04/10 | F11: 1405/06/30 | I11: فرز ، سختکاری | J11: فرز ، سنگ ، CNC ، سوراخکاری ، سختکاری(برون سپاری) ، وایر ، کروم(برون سپاری)، مونتاژ | K11: 0.55 | L11: سختکاری
A12: 9 | B12: (جدید)C&C نیوفیس(جدید) | C12: پرس | D12: 29162 30487 | E12: 1405/04/17 | F12: 1405/06/14 | I12: فرز،CNC، سوراخکاری ، Wier | J12: Assamble ، سختکاری | K12: 0.65 | L12: سختکاری
A13: 10 | B13: پخت کلاچ تیبا چپ(فلش) | C13: تولید جهان ترمز | D13: 30247 | E13: 1405/05/11 | F13: 1405/07/10 | H13: عدم ارسال به کروم (بموقع) ، تاریخ درخواست 1405/06/01 | I13: فرز ، سنگ ، CNC ، سوراخکاری ، سختکاری(برون سپاری) ، | J13: فرز ، سنگ ، CNC ، سوراخکاری ، سختکاری(برون سپاری) ، وایر ، کروم(برون سپاری)، مونتاژ | K13: 0.25 | L13: سختکاری
A14: 11 | B14: پخت کلاچ تیبا راست(فلش) | C14: تولید جهان ترمز | D14: 30278 | E14: 1405/05/11 | F14: 1405/07/10 | H14: عدم ارسال به کروم (بموقع) ، تاریخ درخواست 1405/06/01 | I14: فرز ، سنگ ، CNC ، سوراخکاری ، سختکاری(برون سپاری) ، | J14: فرز ، سنگ ، CNC ، سوراخکاری ، سختکاری(برون سپاری) ، وایر ، کروم(برون سپاری)، مونتاژ | K14: 0.25 | L14: سختکاری
A15: 12 | B15: شمش عقب پژو 405 پایه بلند | C15: جهان لنت | D15: 9278/د/04 | J15: فرز ، سنگ ، CNC ، سوراخکاری ، سختکاری(برون سپاری) ، وایر ، کروم(برون سپاری)، مونتاژ | K15: 0 | L15: تامین متریال
A16: 13 | B16: شمش جلو نیسان | C16: جهان لنت | D16: 9278/د/04 | J16: فرز ، سنگ ، CNC ، سوراخکاری ، سختکاری(برون سپاری) ، وایر ، کروم(برون سپاری)، مونتاژ | K16: 0 | L16: تامین متریال

Sheet 24
A1: New Project | J1: Date | K1: 1405
J2: Weeks | K2: 24
B3: Name | C3: واحد مصرف | D3: شماره فنی | E3: تاریخ شروع | F3: پیش بینی تاریخ تحویل1 | G3: تاریخ تحویل 2 | H3: علت تاخیر در تحویل بموقع | I3: فرایند (OK) | J3: فرایند (NC) | K3: درصد پیشرفت | L3: آخرین وظعیت | M3: س . کار شده | N3: مقدار ساعات کلی
A4: 1 | B4: قالب شمشی عقب ریو | C4: جهان لنت | D4: 9278/د/04 | E4: برون سپاری (اصفهان) امینی | I4: CNC، وایر ، تراش ، کروم ، مونتاژ ، سختکاری | J4: CNC ، Wier ، Assemble ، Test | K4: =IFERROR(M4/N4,0) -> 0.56833333 | L4: {=_xlfn.LET( _xlpm.n,TRIM(B4), _xlpm.D,_xlfn._xlws.FILTER(CHOOSE({1,2},[1]فروردین!$N$4:$N$800,[1]فروردین!$AC$4:$AC$800),(TRIM([1]فروردین!$B$4:$B$800)=_xlpm.n)*(TRIM([1]فروردین!$C$4:$C$800)="قالب نو")*([1]فروردین!$AC$4:$AC$800<>"")), _xlpm.O,_xlfn._xlws.FILTER(CHOOSE({1,2},[2]اردیبهشت!$N$4:$N$800,[2]اردیبهشت!$AC$4:$AC$800),(TRIM([2]اردیبهشت!$B$4:$B$800)=_xlpm.n)*(TRIM([2]اردیبهشت!$C$4:$C$800)="قالب نو")*([2]اردیبهشت!$AC$4:$AC$800<>"")), _xlpm.K,_xlfn._xlws.FILTER(CHOOSE({1,2},[3]خرداد!$N$4:$N$800,[3]خرداد!$AC$4:$AC$800),(TRIM([3]خرداد!$B$4:$B$800)=_xlpm.n)*(TRIM([3]خرداد!$C$4:$C$800)="قالب نو")*([3]خرداد!$AC$4:$AC$800<>"")), _xlpm.T,_xlfn._xlws.FILTER(CHOOSE({1,2},[4]تیر!$N$4:$N$800,[4]تیر!$AC$4:$AC$800),(TRIM([4]تیر!$B$4:$B$800)=_xlpm.n)*(TRIM([4]تیر!$C$4:$C$800)="قالب نو")*([4]تیر!$AC$4:$AC$800<>"")), _xlpm.M,_xlfn._xlws.FILTER(CHOOSE({1,2},[5]مرداد!$N$4:$N$800,[5]مرداد!$AC$4:$AC$800),(TRIM([5]مرداد!$B$4:$B$800)=_xlpm.n)*(TRIM([5]مرداد!$C$4:$C$800)="قالب نو")*([5]مرداد!$AC$4:$AC$800<>"")), _xlpm.S,_xlfn._xlws.FILTER(CHOOSE({1,2},[6]شهریور!$N$4:$N$800,[6]شهریور!$AC$4:$AC$800),(TRIM([6]شهریور!$B$4:$B$800)=_xlpm.n)*(TRIM([6]شهریور!$C$4:$C$800)="قالب نو")*([6]شهریور!$AC$4:$AC$800<>"")), IFERROR(INDEX(_xlfn.SORTBY(VSTACK(_xlpm.D,_xlpm.O,_xlpm.K,_xlpm.T,_xlpm.M,_xlpm.S),--SUBSTITUTE(INDEX(VSTACK(_xlpm.D,_xlpm.O,_xlpm.K,_xlpm.T,_xlpm.M,_xlpm.S),,2),"/",""),-1),1,1),""))} | M4: =SUM( SUMIFS([7]فروردین!$AF4:$AF800,[7]فروردین!$B4:$B800,B4,[7]فروردین!$C4:$C800,"قالب نو"), SUMIFS([7]اردیبهشت!$AF4:$AF800,[7]اردیبهشت!$B4:$B800,B4,[7]اردیبهشت!$C4:$C800,"قالب نو"), SUMIFS([7]خرداد!$AF4:$AF800,[7]خرداد!$B4:$B800,B4,[7]خرداد!$C4:$C800,"قالب نو"), SUMIFS([7]تیر!$AF4:$AF800,[7]تیر!$B4:$B800,B4,[7]تیر!$C4:$C800,"قالب نو"), SUMIFS([7]مرداد!$AF4:$AF800,[7]مرداد!$B4:$B800,B4,[7]مرداد!$C4:$C800,"قالب نو"), SUMIFS([7]شهریور!$AF4:$AF800,[7]شهریور!$B4:$B800,B4,[7]شهریور!$C4:$C800,"قالب نو"), SUMIFS([7]مهر!$AF4:$AF800,[7]مهر!$B4:$B800,B4,[7]مهر!$C4:$C800,"قالب نو"), SUMIFS([7]آبان!$AF4:$AF800,[7]آبان!$B4:$B800,B4,[7]آبان!$C4:$C800,"قالب نو"), SUMIFS([7]آذر!$AF4:$AF800,[7]آذر!$B4:$B800,B4,[7]آذر!$C4:$C800,"قالب نو"), SUMIFS([7]دی!$AF4:$AF800,[7]دی!$B4:$B800,B4,[7]دی!$C4:$C800,"قالب نو"), SUMIFS([7]بهمن!$AF4:$AF800,[7]بهمن!$B4:$B800,B4,[7]بهمن!$C4:$C800,"قالب نو"), SUMIFS([7]اسفند!$AF4:$AF800,[7]اسفند!$B4:$B800,B4,[7]اسفند!$C4:$C800,"قالب نو") ) -> 56.833333 | N4: 100
A5: 2 | B5: پخت عقب پژو 405 شمشی پایه کوتاه | C5: جهان لنت | D5: 9278/د/04 | E5: 1404/09/10 | F5: 1405/07/10 | I5: CNC، وایر ، تراش ، مونتاژ ، سختکاری | J5: CNC ، Wier ، Assemble ، Test ، کروم | K5: =IFERROR(M5/N5,0) -> 0.87462963 | L5: CNC | M5: =SUM( SUMIFS([7]فروردین!$AF5:$AF801,[7]فروردین!$B5:$B801,B5,[7]فروردین!$C5:$C801,"قالب نو"), SUMIFS([7]اردیبهشت!$AF5:$AF801,[7]اردیبهشت!$B5:$B801,B5,[7]اردیبهشت!$C5:$C801,"قالب نو"), SUMIFS([7]خرداد!$AF5:$AF801,[7]خرداد!$B5:$B801,B5,[7]خرداد!$C5:$C801,"قالب نو"), SUMIFS([7]تیر!$AF5:$AF801,[7]تیر!$B5:$B801,B5,[7]تیر!$C5:$C801,"قالب نو"), SUMIFS([7]مرداد!$AF5:$AF801,[7]مرداد!$B5:$B801,B5,[7]مرداد!$C5:$C801,"قالب نو"), SUMIFS([7]شهریور!$AF5:$AF801,[7]شهریور!$B5:$B801,B5,[7]شهریور!$C5:$C801,"قالب نو"), SUMIFS([7]مهر!$AF5:$AF801,[7]مهر!$B5:$B801,B5,[7]مهر!$C5:$C801,"قالب نو"), SUMIFS([7]آبان!$AF5:$AF801,[7]آبان!$B5:$B801,B5,[7]آبان!$C5:$C801,"قالب نو"), SUMIFS([7]آذر!$AF5:$AF801,[7]آذر!$B5:$B801,B5,[7]آذر!$C5:$C801,"قالب نو"), SUMIFS([7]دی!$AF5:$AF801,[7]دی!$B5:$B801,B5,[7]دی!$C5:$C801,"قالب نو"), SUMIFS([7]بهمن!$AF5:$AF801,[7]بهمن!$B5:$B801,B5,[7]بهمن!$C5:$C801,"قالب نو"), SUMIFS([7]اسفند!$AF5:$AF801,[7]اسفند!$B5:$B801,B5,[7]اسفند!$C5:$C801,"قالب نو") ) -> 393.58333 | N5: 450
A6: 3 | B6: قالب شمشی عقب پیکان | C6: جهان لنت | D6: 9278/د/04 | E6: 9278/د/04 | F6: 1405/06/30 | I6: CNC، وایر ، تراش ، ، Wier ،، مونتاژ ، سختکاری | J6: CNC ، Wier ، Assemble ، Test ، کروم | K6: =IFERROR(M6/N6,0) -> 1.035 | L6: CNC | M6: =SUM( SUMIFS([7]فروردین!$AF6:$AF802,[7]فروردین!$B6:$B802,B6,[7]فروردین!$C6:$C802,"قالب نو"), SUMIFS([7]اردیبهشت!$AF6:$AF802,[7]اردیبهشت!$B6:$B802,B6,[7]اردیبهشت!$C6:$C802,"قالب نو"), SUMIFS([7]خرداد!$AF6:$AF802,[7]خرداد!$B6:$B802,B6,[7]خرداد!$C6:$C802,"قالب نو"), SUMIFS([7]تیر!$AF6:$AF802,[7]تیر!$B6:$B802,B6,[7]تیر!$C6:$C802,"قالب نو"), SUMIFS([7]مرداد!$AF6:$AF802,[7]مرداد!$B6:$B802,B6,[7]مرداد!$C6:$C802,"قالب نو"), SUMIFS([7]شهریور!$AF6:$AF802,[7]شهریور!$B6:$B802,B6,[7]شهریور!$C6:$C802,"قالب نو"), SUMIFS([7]مهر!$AF6:$AF802,[7]مهر!$B6:$B802,B6,[7]مهر!$C6:$C802,"قالب نو"), SUMIFS([7]آبان!$AF6:$AF802,[7]آبان!$B6:$B802,B6,[7]آبان!$C6:$C802,"قالب نو"), SUMIFS([7]آذر!$AF6:$AF802,[7]آذر!$B6:$B802,B6,[7]آذر!$C6:$C802,"قالب نو"), SUMIFS([7]دی!$AF6:$AF802,[7]دی!$B6:$B802,B6,[7]دی!$C6:$C802,"قالب نو"), SUMIFS([7]بهمن!$AF6:$AF802,[7]بهمن!$B6:$B802,B6,[7]بهمن!$C6:$C802,"قالب نو"), SUMIFS([7]اسفند!$AF6:$AF802,[7]اسفند!$B6:$B802,B6,[7]اسفند!$C6:$C802,"قالب نو") ) -> 207 | N6: 200
A7: 4 | B7: قالب عقب F12 | C7: جهان لنت | E7: 1405/02/08 | F7: 1405/06/31 | I7: فرز ، سنگ ، CNC ، سوراخکاری ، سختکاری(برون سپاری) ، | J7: کروم (برون سپاری) سنگ،مونتاژ | K7: =IFERROR(M7/N7,0) -> 2.1305556 | L7: Chrome | M7: =SUM( SUMIFS([7]فروردین!$AF4:$AF803,[7]فروردین!$B4:$B803,B7,[7]فروردین!$C4:$C803,"قالب نو"), SUMIFS([7]اردیبهشت!$AF4:$AF803,[7]اردیبهشت!$B4:$B803,B7,[7]اردیبهشت!$C4:$C803,"قالب نو"), SUMIFS([7]خرداد!$AF4:$AF803,[7]خرداد!$B4:$B803,B7,[7]خرداد!$C4:$C803,"قالب نو"), SUMIFS([7]تیر!$AF4:$AF803,[7]تیر!$B4:$B803,B7,[7]تیر!$C4:$C803,"قالب نو"), SUMIFS([7]مرداد!$AF4:$AF803,[7]مرداد!$B4:$B803,B7,[7]مرداد!$C4:$C803,"قالب نو"), SUMIFS([7]شهریور!$AF4:$AF803,[7]شهریور!$B4:$B803,B7,[7]شهریور!$C4:$C803,"قالب نو"), SUMIFS([7]مهر!$AF4:$AF803,[7]مهر!$B4:$B803,B7,[7]مهر!$C4:$C803,"قالب نو"), SUMIFS([7]آبان!$AF4:$AF803,[7]آبان!$B4:$B803,B7,[7]آبان!$C4:$C803,"قالب نو"), SUMIFS([7]آذر!$AF4:$AF803,[7]آذر!$B4:$B803,B7,[7]آذر!$C4:$C803,"قالب نو"), SUMIFS([7]دی!$AF4:$AF803,[7]دی!$B4:$B803,B7,[7]دی!$C4:$C803,"قالب نو"), SUMIFS([7]بهمن!$AF4:$AF803,[7]بهمن!$B4:$B803,B7,[7]بهمن!$C4:$C803,"قالب نو"), SUMIFS([7]اسفند!$AF4:$AF803,[7]اسفند!$B4:$B803,B7,[7]اسفند!$C4:$C803,"قالب نو") ) -> 255.66667 | N7: 120
A8: 5 | B8: قالب مینی بوس آریا | C8: جهان لنت | D8: 30303 | E8: 1405/04/17 | F8: 1405/07/01 | I8: فرز، سختکاری ، CNC، سوراخکاری ، وایر | J8: ، کروم(برون سپاری)، مونتاژ | K8: =IFERROR(M8/N8,0) -> 1.2323529 | L8: Assamble | M8: =SUM( SUMIFS([7]فروردین!$AF8:$AF804,[7]فروردین!$B8:$B804,B8,[7]فروردین!$C8:$C804,"قالب نو"), SUMIFS([7]اردیبهشت!$AF8:$AF804,[7]اردیبهشت!$B8:$B804,B8,[7]اردیبهشت!$C8:$C804,"قالب نو"), SUMIFS([7]خرداد!$AF8:$AF804,[7]خرداد!$B8:$B804,B8,[7]خرداد!$C8:$C804,"قالب نو"), SUMIFS([7]تیر!$AF8:$AF804,[7]تیر!$B8:$B804,B8,[7]تیر!$C8:$C804,"قالب نو"), SUMIFS([7]مرداد!$AF8:$AF804,[7]مرداد!$B8:$B804,B8,[7]مرداد!$C8:$C804,"قالب نو"), SUMIFS([7]شهریور!$AF8:$AF804,[7]شهریور!$B8:$B804,B8,[7]شهریور!$C8:$C804,"قالب نو"), SUMIFS([7]مهر!$AF8:$AF804,[7]مهر!$B8:$B804,B8,[7]مهر!$C8:$C804,"قالب نو"), SUMIFS([7]آبان!$AF8:$AF804,[7]آبان!$B8:$B804,B8,[7]آبان!$C8:$C804,"قالب نو"), SUMIFS([7]آذر!$AF8:$AF804,[7]آذر!$B8:$B804,B8,[7]آذر!$C8:$C804,"قالب نو"), SUMIFS([7]دی!$AF8:$AF804,[7]دی!$B8:$B804,B8,[7]دی!$C8:$C804,"قالب نو"), SUMIFS([7]بهمن!$AF8:$AF804,[7]بهمن!$B8:$B804,B8,[7]بهمن!$C8:$C804,"قالب نو"), SUMIFS([7]اسفند!$AF8:$AF804,[7]اسفند!$B8:$B804,B8,[7]اسفند!$C8:$C804,"قالب نو") ) -> 209.5 | N8: 170
A9: 6 | B9: لودر دیسکی XGL 50 | C9: پرس | D9: 29935 | E9: 1405/04/17 | F9: 1405/07/15 | H9: CNC | I9: فرز، سختکاری ، CNC، وایر ، کروم(برون سپاری) | J9: ، مونتاژ | K9: =IFERROR(M9/N9,0) -> 0.9047619 | L9: مونتاژ | M9: =SUM( SUMIFS([7]فروردین!$AF9:$AF805,[7]فروردین!$B9:$B805,B9,[7]فروردین!$C9:$C805,"قالب نو"), SUMIFS([7]اردیبهشت!$AF9:$AF805,[7]اردیبهشت!$B9:$B805,B9,[7]اردیبهشت!$C9:$C805,"قالب نو"), SUMIFS([7]خرداد!$AF9:$AF805,[7]خرداد!$B9:$B805,B9,[7]خرداد!$C9:$C805,"قالب نو"), SUMIFS([7]تیر!$AF9:$AF805,[7]تیر!$B9:$B805,B9,[7]تیر!$C9:$C805,"قالب نو"), SUMIFS([7]مرداد!$AF9:$AF805,[7]مرداد!$B9:$B805,B9,[7]مرداد!$C9:$C805,"قالب نو"), SUMIFS([7]شهریور!$AF9:$AF805,[7]شهریور!$B9:$B805,B9,[7]شهریور!$C9:$C805,"قالب نو"), SUMIFS([7]مهر!$AF9:$AF805,[7]مهر!$B9:$B805,B9,[7]مهر!$C9:$C805,"قالب نو"), SUMIFS([7]آبان!$AF9:$AF805,[7]آبان!$B9:$B805,B9,[7]آبان!$C9:$C805,"قالب نو"), SUMIFS([7]آذر!$AF9:$AF805,[7]آذر!$B9:$B805,B9,[7]آذر!$C9:$C805,"قالب نو"), SUMIFS([7]دی!$AF9:$AF805,[7]دی!$B9:$B805,B9,[7]دی!$C9:$C805,"قالب نو"), SUMIFS([7]بهمن!$AF9:$AF805,[7]بهمن!$B9:$B805,B9,[7]بهمن!$C9:$C805,"قالب نو"), SUMIFS([7]اسفند!$AF9:$AF805,[7]اسفند!$B9:$B805,B9,[7]اسفند!$C9:$C805,"قالب نو") ) -> 38 | N9: 42
A10: 7 | B10: کامیونت هیوندای | C10: تولید جهان لنت | D10: 29889 | J10: فرز ، سنگ ، CNC ، سوراخکاری ، سختکاری(برون سپاری) ، وایر ، کروم(برون سپاری)، مونتاژ | K10: =IFERROR(M10/N10,0) -> 0.30138889 | L10: تامین متریال | M10: =SUM( SUMIFS([7]فروردین!$AF10:$AF806,[7]فروردین!$B10:$B806,B10,[7]فروردین!$C10:$C806,"قالب نو"), SUMIFS([7]اردیبهشت!$AF10:$AF806,[7]اردیبهشت!$B10:$B806,B10,[7]اردیبهشت!$C10:$C806,"قالب نو"), SUMIFS([7]خرداد!$AF10:$AF806,[7]خرداد!$B10:$B806,B10,[7]خرداد!$C10:$C806,"قالب نو"), SUMIFS([7]تیر!$AF10:$AF806,[7]تیر!$B10:$B806,B10,[7]تیر!$C10:$C806,"قالب نو"), SUMIFS([7]مرداد!$AF10:$AF806,[7]مرداد!$B10:$B806,B10,[7]مرداد!$C10:$C806,"قالب نو"), SUMIFS([7]شهریور!$AF10:$AF806,[7]شهریور!$B10:$B806,B10,[7]شهریور!$C10:$C806,"قالب نو"), SUMIFS([7]مهر!$AF10:$AF806,[7]مهر!$B10:$B806,B10,[7]مهر!$C10:$C806,"قالب نو"), SUMIFS([7]آبان!$AF10:$AF806,[7]آبان!$B10:$B806,B10,[7]آبان!$C10:$C806,"قالب نو"), SUMIFS([7]آذر!$AF10:$AF806,[7]آذر!$B10:$B806,B10,[7]آذر!$C10:$C806,"قالب نو"), SUMIFS([7]دی!$AF10:$AF806,[7]دی!$B10:$B806,B10,[7]دی!$C10:$C806,"قالب نو"), SUMIFS([7]بهمن!$AF10:$AF806,[7]بهمن!$B10:$B806,B10,[7]بهمن!$C10:$C806,"قالب نو"), SUMIFS([7]اسفند!$AF10:$AF806,[7]اسفند!$B10:$B806,B10,[7]اسفند!$C10:$C806,"قالب نو") ) -> 108.5 | N10: 360
A11: 8 | B11: قالب پخت SAF | C11: تولید جهان لنت | D11: 29087 | E11: 1405/04/10 | F11: 1405/06/30 | I11: فرز ، سختکاری | J11: فرز ، سنگ ، CNC ، سوراخکاری ، سختکاری(برون سپاری) ، وایر ، کروم(برون سپاری)، مونتاژ | K11: =IFERROR(M11/N11,0) -> 0.93958333 | L11: سختکاری | M11: =SUM( SUMIFS([7]فروردین!$AF11:$AF807,[7]فروردین!$B11:$B807,B11,[7]فروردین!$C11:$C807,"قالب نو"), SUMIFS([7]اردیبهشت!$AF11:$AF807,[7]اردیبهشت!$B11:$B807,B11,[7]اردیبهشت!$C11:$C807,"قالب نو"), SUMIFS([7]خرداد!$AF11:$AF807,[7]خرداد!$B11:$B807,B11,[7]خرداد!$C11:$C807,"قالب نو"), SUMIFS([7]تیر!$AF11:$AF807,[7]تیر!$B11:$B807,B11,[7]تیر!$C11:$C807,"قالب نو"), SUMIFS([7]مرداد!$AF11:$AF807,[7]مرداد!$B11:$B807,B11,[7]مرداد!$C11:$C807,"قالب نو"), SUMIFS([7]شهریور!$AF11:$AF807,[7]شهریور!$B11:$B807,B11,[7]شهریور!$C11:$C807,"قالب نو"), SUMIFS([7]مهر!$AF11:$AF807,[7]مهر!$B11:$B807,B11,[7]مهر!$C11:$C807,"قالب نو"), SUMIFS([7]آبان!$AF11:$AF807,[7]آبان!$B11:$B807,B11,[7]آبان!$C11:$C807,"قالب نو"), SUMIFS([7]آذر!$AF11:$AF807,[7]آذر!$B11:$B807,B11,[7]آذر!$C11:$C807,"قالب نو"), SUMIFS([7]دی!$AF11:$AF807,[7]دی!$B11:$B807,B11,[7]دی!$C11:$C807,"قالب نو"), SUMIFS([7]بهمن!$AF11:$AF807,[7]بهمن!$B11:$B807,B11,[7]بهمن!$C11:$C807,"قالب نو"), SUMIFS([7]اسفند!$AF11:$AF807,[7]اسفند!$B11:$B807,B11,[7]اسفند!$C11:$C807,"قالب نو") ) -> 150.33333 | N11: 160
A12: 9 | B12: برشی نیوفیس C&C | C12: پرس | D12: 29162 30487 | E12: 1405/04/17 | F12: 1405/06/14 | I12: فرز،CNC، سوراخکاری ، Wier | J12: Assamble ، سختکاری | K12: =IFERROR(M12/N12,0) -> 1.0108333 | L12: Wier | M12: =SUM( SUMIFS([7]فروردین!$AF12:$AF808,[7]فروردین!$B12:$B808,B12,[7]فروردین!$C12:$C808,"قالب نو"), SUMIFS([7]اردیبهشت!$AF12:$AF808,[7]اردیبهشت!$B12:$B808,B12,[7]اردیبهشت!$C12:$C808,"قالب نو"), SUMIFS([7]خرداد!$AF12:$AF808,[7]خرداد!$B12:$B808,B12,[7]خرداد!$C12:$C808,"قالب نو"), SUMIFS([7]تیر!$AF12:$AF808,[7]تیر!$B12:$B808,B12,[7]تیر!$C12:$C808,"قالب نو"), SUMIFS([7]مرداد!$AF12:$AF808,[7]مرداد!$B12:$B808,B12,[7]مرداد!$C12:$C808,"قالب نو"), SUMIFS([7]شهریور!$AF12:$AF808,[7]شهریور!$B12:$B808,B12,[7]شهریور!$C12:$C808,"قالب نو"), SUMIFS([7]مهر!$AF12:$AF808,[7]مهر!$B12:$B808,B12,[7]مهر!$C12:$C808,"قالب نو"), SUMIFS([7]آبان!$AF12:$AF808,[7]آبان!$B12:$B808,B12,[7]آبان!$C12:$C808,"قالب نو"), SUMIFS([7]آذر!$AF12:$AF808,[7]آذر!$B12:$B808,B12,[7]آذر!$C12:$C808,"قالب نو"), SUMIFS([7]دی!$AF12:$AF808,[7]دی!$B12:$B808,B12,[7]دی!$C12:$C808,"قالب نو"), SUMIFS([7]بهمن!$AF12:$AF808,[7]بهمن!$B12:$B808,B12,[7]بهمن!$C12:$C808,"قالب نو"), SUMIFS([7]اسفند!$AF12:$AF808,[7]اسفند!$B12:$B808,B12,[7]اسفند!$C12:$C808,"قالب نو") ) -> 404.33333 | N12: 400
A13: 10 | B13: پخت کلاچ تیبا چپ | C13: تولید جهان ترمز | D13: 30247 | E13: 1405/05/11 | F13: 1405/07/10 | H13: عدم ارسال به کروم (بموقع) ، تاریخ درخواست 1405/06/01 | I13: فرز ، سنگ ، CNC ، سوراخکاری ، سختکاری(برون سپاری) ، | J13: فرز ، سنگ ، CNC ، سوراخکاری ، سختکاری(برون سپاری) ، وایر ، کروم(برون سپاری)، مونتاژ | K13: =IFERROR(M13/N13,0) -> 0.571875 | L13: سختکاری | M13: =SUM( SUMIFS([7]فروردین!$AF13:$AF809,[7]فروردین!$B13:$B809,B13,[7]فروردین!$C13:$C809,"قالب نو"), SUMIFS([7]اردیبهشت!$AF13:$AF809,[7]اردیبهشت!$B13:$B809,B13,[7]اردیبهشت!$C13:$C809,"قالب نو"), SUMIFS([7]خرداد!$AF13:$AF809,[7]خرداد!$B13:$B809,B13,[7]خرداد!$C13:$C809,"قالب نو"), SUMIFS([7]تیر!$AF13:$AF809,[7]تیر!$B13:$B809,B13,[7]تیر!$C13:$C809,"قالب نو"), SUMIFS([7]مرداد!$AF13:$AF809,[7]مرداد!$B13:$B809,B13,[7]مرداد!$C13:$C809,"قالب نو"), SUMIFS([7]شهریور!$AF13:$AF809,[7]شهریور!$B13:$B809,B13,[7]شهریور!$C13:$C809,"قالب نو"), SUMIFS([7]مهر!$AF13:$AF809,[7]مهر!$B13:$B809,B13,[7]مهر!$C13:$C809,"قالب نو"), SUMIFS([7]آبان!$AF13:$AF809,[7]آبان!$B13:$B809,B13,[7]آبان!$C13:$C809,"قالب نو"), SUMIFS([7]آذر!$AF13:$AF809,[7]آذر!$B13:$B809,B13,[7]آذر!$C13:$C809,"قالب نو"), SUMIFS([7]دی!$AF13:$AF809,[7]دی!$B13:$B809,B13,[7]دی!$C13:$C809,"قالب نو"), SUMIFS([7]بهمن!$AF13:$AF809,[7]بهمن!$B13:$B809,B13,[7]بهمن!$C13:$C809,"قالب نو"), SUMIFS([7]اسفند!$AF13:$AF809,[7]اسفند!$B13:$B809,B13,[7]اسفند!$C13:$C809,"قالب نو") ) -> 91.5 | N13: 160
A14: 11 | B14: پخت کلاچ تیبا راست | C14: تولید جهان ترمز | D14: 30278 | E14: 1405/05/11 | F14: 1405/07/10 | H14: عدم ارسال به کروم (بموقع) ، تاریخ درخواست 1405/06/01 | I14: فرز ، سنگ ، CNC ، سوراخکاری ، سختکاری(برون سپاری) ، | J14: فرز ، سنگ ، CNC ، سوراخکاری ، سختکاری(برون سپاری) ، وایر ، کروم(برون سپاری)، مونتاژ | K14: =IFERROR(M14/N14,0) -> 0.4875 | L14: سختکاری | M14: =SUM( SUMIFS([7]فروردین!$AF14:$AF810,[7]فروردین!$B14:$B810,B14,[7]فروردین!$C14:$C810,"قالب نو"), SUMIFS([7]اردیبهشت!$AF14:$AF810,[7]اردیبهشت!$B14:$B810,B14,[7]اردیبهشت!$C14:$C810,"قالب نو"), SUMIFS([7]خرداد!$AF14:$AF810,[7]خرداد!$B14:$B810,B14,[7]خرداد!$C14:$C810,"قالب نو"), SUMIFS([7]تیر!$AF14:$AF810,[7]تیر!$B14:$B810,B14,[7]تیر!$C14:$C810,"قالب نو"), SUMIFS([7]مرداد!$AF14:$AF810,[7]مرداد!$B14:$B810,B14,[7]مرداد!$C14:$C810,"قالب نو"), SUMIFS([7]شهریور!$AF14:$AF810,[7]شهریور!$B14:$B810,B14,[7]شهریور!$C14:$C810,"قالب نو"), SUMIFS([7]مهر!$AF14:$AF810,[7]مهر!$B14:$B810,B14,[7]مهر!$C14:$C810,"قالب نو"), SUMIFS([7]آبان!$AF14:$AF810,[7]آبان!$B14:$B810,B14,[7]آبان!$C14:$C810,"قالب نو"), SUMIFS([7]آذر!$AF14:$AF810,[7]آذر!$B14:$B810,B14,[7]آذر!$C14:$C810,"قالب نو"), SUMIFS([7]دی!$AF14:$AF810,[7]دی!$B14:$B810,B14,[7]دی!$C14:$C810,"قالب نو"), SUMIFS([7]بهمن!$AF14:$AF810,[7]بهمن!$B14:$B810,B14,[7]بهمن!$C14:$C810,"قالب نو"), SUMIFS([7]اسفند!$AF14:$AF810,[7]اسفند!$B14:$B810,B14,[7]اسفند!$C14:$C810,"قالب نو") ) -> 78 | N14: 160
A15: 12 | B15: شمش عقب پژو 405 پایه بلند | C15: جهان لنت | D15: 9278/د/04 | J15: فرز ، سنگ ، CNC ، سوراخکاری ، سختکاری(برون سپاری) ، وایر ، کروم(برون سپاری)، مونتاژ | K15: =IFERROR(M15/N15,0) -> 0 | L15: تامین متریال | M15: =SUM( SUMIFS([7]فروردین!$AF15:$AF811,[7]فروردین!$B15:$B811,B15,[7]فروردین!$C15:$C811,"قالب نو"), SUMIFS([7]اردیبهشت!$AF15:$AF811,[7]اردیبهشت!$B15:$B811,B15,[7]اردیبهشت!$C15:$C811,"قالب نو"), SUMIFS([7]خرداد!$AF15:$AF811,[7]خرداد!$B15:$B811,B15,[7]خرداد!$C15:$C811,"قالب نو"), SUMIFS([7]تیر!$AF15:$AF811,[7]تیر!$B15:$B811,B15,[7]تیر!$C15:$C811,"قالب نو"), SUMIFS([7]مرداد!$AF15:$AF811,[7]مرداد!$B15:$B811,B15,[7]مرداد!$C15:$C811,"قالب نو"), SUMIFS([7]شهریور!$AF15:$AF811,[7]شهریور!$B15:$B811,B15,[7]شهریور!$C15:$C811,"قالب نو"), SUMIFS([7]مهر!$AF15:$AF811,[7]مهر!$B15:$B811,B15,[7]مهر!$C15:$C811,"قالب نو"), SUMIFS([7]آبان!$AF15:$AF811,[7]آبان!$B15:$B811,B15,[7]آبان!$C15:$C811,"قالب نو"), SUMIFS([7]آذر!$AF15:$AF811,[7]آذر!$B15:$B811,B15,[7]آذر!$C15:$C811,"قالب نو"), SUMIFS([7]دی!$AF15:$AF811,[7]دی!$B15:$B811,B15,[7]دی!$C15:$C811,"قالب نو"), SUMIFS([7]بهمن!$AF15:$AF811,[7]بهمن!$B15:$B811,B15,[7]بهمن!$C15:$C811,"قالب نو"), SUMIFS([7]اسفند!$AF15:$AF811,[7]اسفند!$B15:$B811,B15,[7]اسفند!$C15:$C811,"قالب نو") ) -> 0 | N15: 420
A16: 13 | B16: شمش جلو نیسان | C16: جهان لنت | D16: 9278/د/04 | J16: فرز ، سنگ ، CNC ، سوراخکاری ، سختکاری(برون سپاری) ، وایر ، کروم(برون سپاری)، مونتاژ | K16: =IFERROR(M16/N16,0) -> 0 | L16: تامین متریال | M16: =SUM( SUMIFS([7]فروردین!$AF16:$AF812,[7]فروردین!$B16:$B812,B16,[7]فروردین!$C16:$C812,"قالب نو"), SUMIFS([7]اردیبهشت!$AF16:$AF812,[7]اردیبهشت!$B16:$B812,B16,[7]اردیبهشت!$C16:$C812,"قالب نو"), SUMIFS([7]خرداد!$AF16:$AF812,[7]خرداد!$B16:$B812,B16,[7]خرداد!$C16:$C812,"قالب نو"), SUMIFS([7]تیر!$AF16:$AF812,[7]تیر!$B16:$B812,B16,[7]تیر!$C16:$C812,"قالب نو"), SUMIFS([7]مرداد!$AF16:$AF812,[7]مرداد!$B16:$B812,B16,[7]مرداد!$C16:$C812,"قالب نو"), SUMIFS([7]شهریور!$AF16:$AF812,[7]شهریور!$B16:$B812,B16,[7]شهریور!$C16:$C812,"قالب نو"), SUMIFS([7]مهر!$AF16:$AF812,[7]مهر!$B16:$B812,B16,[7]مهر!$C16:$C812,"قالب نو"), SUMIFS([7]آبان!$AF16:$AF812,[7]آبان!$B16:$B812,B16,[7]آبان!$C16:$C812,"قالب نو"), SUMIFS([7]آذر!$AF16:$AF812,[7]آذر!$B16:$B812,B16,[7]آذر!$C16:$C812,"قالب نو"), SUMIFS([7]دی!$AF16:$AF812,[7]دی!$B16:$B812,B16,[7]دی!$C16:$C812,"قالب نو"), SUMIFS([7]بهمن!$AF16:$AF812,[7]بهمن!$B16:$B812,B16,[7]بهمن!$C16:$C812,"قالب نو"), SUMIFS([7]اسفند!$AF16:$AF812,[7]اسفند!$B16:$B812,B16,[7]اسفند!$C16:$C812,"قالب نو") ) -> 0 | N16: 560
A17: 14 | B17: خودرو دیزل آذربایجان | C17: جهان لنت | D17: 9278/د/05 | J17: فرز ، سنگ ، CNC ، سوراخکاری ، سختکاری(برون سپاری) ، وایر ، کروم(برون سپاری)، مونتاژ | K17: =IFERROR(M17/N17,0) -> 0.17111111 | L17: تامین متریال | M17: =SUM( SUMIFS([7]فروردین!$AF17:$AF813,[7]فروردین!$B17:$B813,B17,[7]فروردین!$C17:$C813,"قالب نو"), SUMIFS([7]اردیبهشت!$AF17:$AF813,[7]اردیبهشت!$B17:$B813,B17,[7]اردیبهشت!$C17:$C813,"قالب نو"), SUMIFS([7]خرداد!$AF17:$AF813,[7]خرداد!$B17:$B813,B17,[7]خرداد!$C17:$C813,"قالب نو"), SUMIFS([7]تیر!$AF17:$AF813,[7]تیر!$B17:$B813,B17,[7]تیر!$C17:$C813,"قالب نو"), SUMIFS([7]مرداد!$AF17:$AF813,[7]مرداد!$B17:$B813,B17,[7]مرداد!$C17:$C813,"قالب نو"), SUMIFS([7]شهریور!$AF17:$AF813,[7]شهریور!$B17:$B813,B17,[7]شهریور!$C17:$C813,"قالب نو"), SUMIFS([7]مهر!$AF17:$AF813,[7]مهر!$B17:$B813,B17,[7]مهر!$C17:$C813,"قالب نو"), SUMIFS([7]آبان!$AF17:$AF813,[7]آبان!$B17:$B813,B17,[7]آبان!$C17:$C813,"قالب نو"), SUMIFS([7]آذر!$AF17:$AF813,[7]آذر!$B17:$B813,B17,[7]آذر!$C17:$C813,"قالب نو"), SUMIFS([7]دی!$AF17:$AF813,[7]دی!$B17:$B813,B17,[7]دی!$C17:$C813,"قالب نو"), SUMIFS([7]بهمن!$AF17:$AF813,[7]بهمن!$B17:$B813,B17,[7]بهمن!$C17:$C813,"قالب نو"), SUMIFS([7]اسفند!$AF17:$AF813,[7]اسفند!$B17:$B813,B17,[7]اسفند!$C17:$C813,"قالب نو") ) -> 77 | N17: 450

Sheet 25
A1: New Project | J1: Date | K1: 1405
J2: Weeks | K2: 25
B3: Name | C3: واحد مصرف | D3: شماره فنی | E3: تاریخ شروع | F3: پیش بینی تاریخ تحویل1 | G3: تاریخ تحویل 2 | H3: علت تاخیر در تحویل بموقع | I3: فرایند (OK) | J3: فرایند (NC) | K3: درصد پیشرفت | L3: آخرین وظعیت | M3: س . کار شده | N3: مقدار ساعات کلی
