Workbook

Sheet 2
A1: Performance of molding machines | M1: Date | N1: 1405 | O1: Time of Weeks
M2: weeks | N2: 2
A3: ردیف | B3: ایستگاه | C3: کد دستگاه | D3: ظرفیت نسبی (نفر ساعت) | E3: شاخص سلامت | F3: نام اپراتور | G3: تحقق (کارکرد عادی) | H3: تحقق (جمعه کاری) | I3: مرخصی | J3: خرابی دستگاه | K3: ساعات تعطیل | L3: نبود برق | M3: عدم تحقق | N3: علت عدم تحقق (کد) | O3: 1405/01/08 | P3: 1405/01/09 | Q3: 1405/01/10 | R3: 1405/01/11 | S3: 1405/01/12 | T3: 1405/01/13 | U3: 1405/01/14
F4: حیدری | G4: =SUM(O4:T4) -> 0 | H4: =U4 -> 0 | I4: 0 | J4: 0 | K4: 29.2 | L4: 0 | N4: ⑥ ② | O4: =SUMIFS([1]فروردین!$AD$2:$AD$57,[1]فروردین!$N$2:$N$57,7101,[1]فروردین!$D$2:$D$57,$F$4,[1]فروردین!$AA$2:$AA$57,O3) -> 0 | P4: =SUMIFS([1]فروردین!$AD$2:$AD$57,[1]فروردین!$N$2:$N$57,7101,[1]فروردین!$D$2:$D$57,$F$4,[1]فروردین!$AA$2:$AA$57,P3) -> 0 | Q4: =SUMIFS([1]فروردین!$AD$2:$AD$57,[1]فروردین!$N$2:$N$57,7101,[1]فروردین!$D$2:$D$57,$F$4,[1]فروردین!$AA$2:$AA$57,Q3) -> 0 | R4: =SUMIFS([1]فروردین!$AD$2:$AD$57,[1]فروردین!$N$2:$N$57,7101,[1]فروردین!$D$2:$D$57,$F$4,[1]فروردین!$AA$2:$AA$57,R3) -> 0 | S4: =SUMIFS([1]فروردین!$AD$2:$AD$57,[1]فروردین!$N$2:$N$57,7101,[1]فروردین!$D$2:$D$57,$F$4,[1]فروردین!$AA$2:$AA$57,S3) -> 0 | T4: =SUMIFS([1]فروردین!$AD$2:$AD$57,[1]فروردین!$N$2:$N$57,7101,[1]فروردین!$D$2:$D$57,$F$4,[1]فروردین!$AA$2:$AA$57,T3) -> 0 | U4: =SUMIFS([1]فروردین!$AD$2:$AD$57,[1]فروردین!$N$2:$N$57,7101,[1]فروردین!$D$2:$D$57,$F$4,[1]فروردین!$AA$2:$AA$57,U3) -> 0
A5: 1 | B5: فرز | C5: 7101 | D5: 62.5 | E5: سالم | G5: =SUM(O5:T5) -> 0 | H5: =U5 -> 0 | I5: 0 | J5: 0 | K5: 0 | L5: 0 | M5: =SUM(G4:G6)+SUM(H4:H6)+SUM(I4:I6)+SUM(L4:L6)+SUM(K4:K6)-D5 -> -33.3 | O5: =SUMIFS([1]فروردین!$AD$2:$AD$57,[1]فروردین!$N$2:$N$57,7101,[1]فروردین!$D$2:$D$57,$F$5,[1]فروردین!$AA$2:$AA$57,O3) -> 0 | P5: =SUMIFS([1]فروردین!$AD$2:$AD$57,[1]فروردین!$N$2:$N$57,7101,[1]فروردین!$D$2:$D$57,$F$5,[1]فروردین!$AA$2:$AA$57,P3) -> 0 | Q5: =SUMIFS([1]فروردین!$AD$2:$AD$57,[1]فروردین!$N$2:$N$57,7101,[1]فروردین!$D$2:$D$57,$F$5,[1]فروردین!$AA$2:$AA$57,Q3) -> 0 | R5: =SUMIFS([1]فروردین!$AD$2:$AD$57,[1]فروردین!$N$2:$N$57,7101,[1]فروردین!$D$2:$D$57,$F$5,[1]فروردین!$AA$2:$AA$57,R3) -> 0 | S5: =SUMIFS([1]فروردین!$AD$2:$AD$57,[1]فروردین!$N$2:$N$57,7101,[1]فروردین!$D$2:$D$57,$F$5,[1]فروردین!$AA$2:$AA$57,S3) -> 0 | T5: =SUMIFS([1]فروردین!$AD$2:$AD$57,[1]فروردین!$N$2:$N$57,7101,[1]فروردین!$D$2:$D$57,$F$5,[1]فروردین!$AA$2:$AA$57,T3) -> 0 | U5: =SUMIFS([1]فروردین!$AD$2:$AD$57,[1]فروردین!$N$2:$N$57,7101,[1]فروردین!$D$2:$D$57,$F$5,[1]فروردین!$AA$2:$AA$57,U3) -> 0
G6: =SUM(O6:T6) -> 0 | H6: =U6 -> 0 | I6: 0 | J6: 0 | K6: 0 | L6: 0 | O6: =SUMIFS([1]فروردین!$AD$2:$AD$57,[1]فروردین!$N$2:$N$57,7101,[1]فروردین!$D$2:$D$57,$F$6,[1]فروردین!$AA$2:$AA$57,O3) -> 0 | P6: =SUMIFS([1]فروردین!$AD$2:$AD$57,[1]فروردین!$N$2:$N$57,7101,[1]فروردین!$D$2:$D$57,$F$6,[1]فروردین!$AA$2:$AA$57,P3) -> 0 | Q6: =SUMIFS([1]فروردین!$AD$2:$AD$57,[1]فروردین!$N$2:$N$57,7101,[1]فروردین!$D$2:$D$57,$F$6,[1]فروردین!$AA$2:$AA$57,Q3) -> 0 | R6: =SUMIFS([1]فروردین!$AD$2:$AD$57,[1]فروردین!$N$2:$N$57,7101,[1]فروردین!$D$2:$D$57,$F$6,[1]فروردین!$AA$2:$AA$57,R3) -> 0 | S6: =SUMIFS([1]فروردین!$AD$2:$AD$57,[1]فروردین!$N$2:$N$57,7101,[1]فروردین!$D$2:$D$57,$F$6,[1]فروردین!$AA$2:$AA$57,S3) -> 0 | T6: =SUMIFS([1]فروردین!$AD$2:$AD$57,[1]فروردین!$N$2:$N$57,7101,[1]فروردین!$D$2:$D$57,$F$6,[1]فروردین!$AA$2:$AA$57,T3) -> 0 | U6: =SUMIFS([1]فروردین!$AD$2:$AD$57,[1]فروردین!$N$2:$N$57,7101,[1]فروردین!$D$2:$D$57,$F$6,[1]فروردین!$AA$2:$AA$57,U3) -> 0
G7: =SUM(O7:T7) -> 0 | H7: =U7 -> 0 | I7: 0 | J7: 0 | K7: 0 | L7: 0 | O7: =SUMIFS([1]فروردین!$AD$2:$AD$57,[1]فروردین!$N$2:$N$57,7102,[1]فروردین!$D$2:$D$57,$F$7,[1]فروردین!$AA$2:$AA$57,O3) -> 0 | P7: =SUMIFS([1]فروردین!$AD$2:$AD$57,[1]فروردین!$N$2:$N$57,7102,[1]فروردین!$D$2:$D$57,$F$7,[1]فروردین!$AA$2:$AA$57,P3) -> 0 | Q7: =SUMIFS([1]فروردین!$AD$2:$AD$57,[1]فروردین!$N$2:$N$57,7102,[1]فروردین!$D$2:$D$57,$F$7,[1]فروردین!$AA$2:$AA$57,Q3) -> 0 | R7: =SUMIFS([1]فروردین!$AD$2:$AD$57,[1]فروردین!$N$2:$N$57,7102,[1]فروردین!$D$2:$D$57,$F$7,[1]فروردین!$AA$2:$AA$57,R3) -> 0 | S7: =SUMIFS([1]فروردین!$AD$2:$AD$57,[1]فروردین!$N$2:$N$57,7102,[1]فروردین!$D$2:$D$57,$F$7,[1]فروردین!$AA$2:$AA$57,S3) -> 0 | T7: =SUMIFS([1]فروردین!$AD$2:$AD$57,[1]فروردین!$N$2:$N$57,7102,[1]فروردین!$D$2:$D$57,$F$7,[1]فروردین!$AA$2:$AA$57,T3) -> 0 | U7: =SUMIFS([1]فروردین!$AD$2:$AD$57,[1]فروردین!$N$2:$N$57,7102,[1]فروردین!$D$2:$D$57,$F$7,[1]فروردین!$AA$2:$AA$57,U3) -> 0
A8: 2 | B8: فرز | C8: 7102 | D8: 62.5 | E8: سالم | G8: =SUM(O8:T8) -> 0 | H8: =U8 -> 0 | I8: 0 | J8: 0 | K8: 0 | L8: 0 | M8: =SUM(G7:G9)+SUM(H7:H9)+SUM(I7:I9)+SUM(J7:J9)+SUM(K7:K9)+SUM(L7:L9)-D8 -> -62.5 | N8: ⑥ | O8: =SUMIFS([1]فروردین!$AD$2:$AD$57,[1]فروردین!$N$2:$N$57,7102,[1]فروردین!$D$2:$D$57,$F$8,[1]فروردین!$AA$2:$AA$57,O3) -> 0 | P8: =SUMIFS([1]فروردین!$AD$2:$AD$57,[1]فروردین!$N$2:$N$57,7102,[1]فروردین!$D$2:$D$57,$F$8,[1]فروردین!$AA$2:$AA$57,P3) -> 0 | Q8: =SUMIFS([1]فروردین!$AD$2:$AD$57,[1]فروردین!$N$2:$N$57,7102,[1]فروردین!$D$2:$D$57,$F$8,[1]فروردین!$AA$2:$AA$57,Q3) -> 0 | R8: =SUMIFS([1]فروردین!$AD$2:$AD$57,[1]فروردین!$N$2:$N$57,7102,[1]فروردین!$D$2:$D$57,$F$8,[1]فروردین!$AA$2:$AA$57,R3) -> 0 | S8: =SUMIFS([1]فروردین!$AD$2:$AD$57,[1]فروردین!$N$2:$N$57,7102,[1]فروردین!$D$2:$D$57,$F$8,[1]فروردین!$AA$2:$AA$57,S3) -> 0 | T8: =SUMIFS([1]فروردین!$AD$2:$AD$57,[1]فروردین!$N$2:$N$57,7102,[1]فروردین!$D$2:$D$57,$F$8,[1]فروردین!$AA$2:$AA$57,T3) -> 0 | U8: =SUMIFS([1]فروردین!$AD$2:$AD$57,[1]فروردین!$N$2:$N$57,7102,[1]فروردین!$D$2:$D$57,$F$8,[1]فروردین!$AA$2:$AA$57,U3) -> 0
G9: =SUM(O9:T9) -> 0 | H9: =U9 -> 0 | I9: 0 | J9: 0 | K9: 0 | L9: 0 | O9: =SUMIFS([1]فروردین!$AD$2:$AD$57,[1]فروردین!$N$2:$N$57,7102,[1]فروردین!$D$2:$D$57,$F$9,[1]فروردین!$AA$2:$AA$57,O3) -> 0 | P9: =SUMIFS([1]فروردین!$AD$2:$AD$57,[1]فروردین!$N$2:$N$57,7102,[1]فروردین!$D$2:$D$57,$F$9,[1]فروردین!$AA$2:$AA$57,P3) -> 0 | Q9: =SUMIFS([1]فروردین!$AD$2:$AD$57,[1]فروردین!$N$2:$N$57,7102,[1]فروردین!$D$2:$D$57,$F$9,[1]فروردین!$AA$2:$AA$57,Q3) -> 0 | R9: =SUMIFS([1]فروردین!$AD$2:$AD$57,[1]فروردین!$N$2:$N$57,7102,[1]فروردین!$D$2:$D$57,$F$9,[1]فروردین!$AA$2:$AA$57,R3) -> 0 | S9: =SUMIFS([1]فروردین!$AD$2:$AD$57,[1]فروردین!$N$2:$N$57,7102,[1]فروردین!$D$2:$D$57,$F$9,[1]فروردین!$AA$2:$AA$57,S3) -> 0 | T9: =SUMIFS([1]فروردین!$AD$2:$AD$57,[1]فروردین!$N$2:$N$57,7102,[1]فروردین!$D$2:$D$57,$F$9,[1]فروردین!$AA$2:$AA$57,T3) -> 0 | U9: =SUMIFS([1]فروردین!$AD$2:$AD$57,[1]فروردین!$N$2:$N$57,7102,[1]فروردین!$D$2:$D$57,$F$9,[1]فروردین!$AA$2:$AA$57,U3) -> 0
A10: 3 | B10: فرز | C10: 7103 | D10: 62.5 | E10: سالم | G10: =SUM(O10:T10) -> 0 | H10: =U10 -> 0 | I10: 0 | J10: 0 | K10: 0 | L10: 0 | M10: =SUM(G10:L10)-64 -> -64 | N10: ① | O10: =SUMIFS([1]فروردین!$AD$2:$AD$57,[1]فروردین!$N$2:$N$57,7103,[1]فروردین!$D$2:$D$57,$F$10,[1]فروردین!$AA$2:$AA$57,O3) -> 0 | P10: =SUMIFS([1]فروردین!$AD$2:$AD$57,[1]فروردین!$N$2:$N$57,7103,[1]فروردین!$D$2:$D$57,$F$10,[1]فروردین!$AA$2:$AA$57,P3) -> 0 | Q10: =SUMIFS([1]فروردین!$AD$2:$AD$57,[1]فروردین!$N$2:$N$57,7103,[1]فروردین!$D$2:$D$57,$F$10,[1]فروردین!$AA$2:$AA$57,Q3) -> 0 | R10: =SUMIFS([1]فروردین!$AD$2:$AD$57,[1]فروردین!$N$2:$N$57,7103,[1]فروردین!$D$2:$D$57,$F$10,[1]فروردین!$AA$2:$AA$57,R3) -> 0 | S10: =SUMIFS([1]فروردین!$AD$2:$AD$57,[1]فروردین!$N$2:$N$57,7103,[1]فروردین!$D$2:$D$57,$F$10,[1]فروردین!$AA$2:$AA$57,S3) -> 0 | T10: =SUMIFS([1]فروردین!$AD$2:$AD$57,[1]فروردین!$N$2:$N$57,7103,[1]فروردین!$D$2:$D$57,$F$10,[1]فروردین!$AA$2:$AA$57,T3) -> 0 | U10: =SUMIFS([1]فروردین!$AD$2:$AD$57,[1]فروردین!$N$2:$N$57,7103,[1]فروردین!$D$2:$D$57,$F$10,[1]فروردین!$AA$2:$AA$57,U3) -> 0
A11: 4 | B11: CNC | C11: 7201 | D11: 62.5 | E11: خراب | G11: =SUM(O11:T11) -> 0 | H11: =U11 -> 0 | I11: 0 | J11: 62 | K11: 0 | L11: 0 | M11: =SUM(G11:J11)-62 -> 0 | N11: ⑤ ③
A12: 5 | B12: CNC | C12: 7202 | D12: 62.5 | E12: سالم | G12: =SUM(O12:T12) -> 0 | H12: =U12 -> 0 | I12: 0 | J12: 0 | K12: 0 | L12: 0 | M12: =SUM(G12:L12)-62 -> -62 | N12: ② ① | O12: =SUMIFS([1]فروردین!$AD$2:$AD$57,[1]فروردین!$N$2:$N$57,7202,[1]فروردین!$D$2:$D$57,$F$12,[1]فروردین!$AA$2:$AA$57,O3) -> 0 | P12: =SUMIFS([1]فروردین!$AD$2:$AD$57,[1]فروردین!$N$2:$N$57,7202,[1]فروردین!$D$2:$D$57,$F$12,[1]فروردین!$AA$2:$AA$57,P3) -> 0 | Q12: =SUMIFS([1]فروردین!$AD$2:$AD$57,[1]فروردین!$N$2:$N$57,7202,[1]فروردین!$D$2:$D$57,$F$12,[1]فروردین!$AA$2:$AA$57,Q3) -> 0 | R12: =SUMIFS([1]فروردین!$AD$2:$AD$57,[1]فروردین!$N$2:$N$57,7202,[1]فروردین!$D$2:$D$57,$F$12,[1]فروردین!$AA$2:$AA$57,R3) -> 0 | S12: =SUMIFS([1]فروردین!$AD$2:$AD$57,[1]فروردین!$N$2:$N$57,7202,[1]فروردین!$D$2:$D$57,$F$12,[1]فروردین!$AA$2:$AA$57,S3) -> 0 | T12: =SUMIFS([1]فروردین!$AD$2:$AD$57,[1]فروردین!$N$2:$N$57,7202,[1]فروردین!$D$2:$D$57,$F$12,[1]فروردین!$AA$2:$AA$57,T3) -> 0 | U12: =SUMIFS([1]فروردین!$AD$2:$AD$57,[1]فروردین!$N$2:$N$57,7202,[1]فروردین!$D$2:$D$57,$F$12,[1]فروردین!$AA$2:$AA$57,U3) -> 0
A13: 6 | B13: CNC | C13: 7203 | D13: 62.5 | E13: سالم | G13: =SUM(O13:T13) -> 0 | H13: =U13 -> 0 | I13: 0 | J13: 0 | K13: 0 | L13: 0 | M13: =(G13+H13+I13+J13+K13)-D13 -> -62.5 | O13: =SUMIFS([1]فروردین!$AD$2:$AD$57,[1]فروردین!$N$2:$N$57,7203,[1]فروردین!$D$2:$D$57,$F$13,[1]فروردین!$AA$2:$AA$57,O3) -> 0 | P13: =SUMIFS([1]فروردین!$AD$2:$AD$57,[1]فروردین!$N$2:$N$57,7203,[1]فروردین!$D$2:$D$57,$F$13,[1]فروردین!$AA$2:$AA$57,P3) -> 0 | Q13: =SUMIFS([1]فروردین!$AD$2:$AD$57,[1]فروردین!$N$2:$N$57,7203,[1]فروردین!$D$2:$D$57,$F$13,[1]فروردین!$AA$2:$AA$57,Q3) -> 0 | R13: =SUMIFS([1]فروردین!$AD$2:$AD$57,[1]فروردین!$N$2:$N$57,7203,[1]فروردین!$D$2:$D$57,$F$13,[1]فروردین!$AA$2:$AA$57,R3) -> 0 | S13: =SUMIFS([1]فروردین!$AD$2:$AD$57,[1]فروردین!$N$2:$N$57,7203,[1]فروردین!$D$2:$D$57,$F$13,[1]فروردین!$AA$2:$AA$57,S3) -> 0 | T13: =SUMIFS([1]فروردین!$AD$2:$AD$57,[1]فروردین!$N$2:$N$57,7203,[1]فروردین!$D$2:$D$57,$F$13,[1]فروردین!$AA$2:$AA$57,T3) -> 0 | U13: =SUMIFS([1]فروردین!$AD$2:$AD$57,[1]فروردین!$N$2:$N$57,7203,[1]فروردین!$D$2:$D$57,$F$13,[1]فروردین!$AA$2:$AA$57,U3) -> 0
A14: 7 | B14: CNC | C14: 7204 | D14: 62.5 | E14: سالم | G14: =SUM(O14:T14) -> 0 | H14: =U14 -> 0 | I14: 0 | J14: 0 | K14: 0 | L14: 0 | M14: =SUM(G14:J14)-62 -> -62 | O14: =SUMIFS([1]فروردین!$AD$2:$AD$57,[1]فروردین!$N$2:$N$57,7204,[1]فروردین!$D$2:$D$57,$F$14,[1]فروردین!$AA$2:$AA$57,O3) -> 0 | P14: =SUMIFS([1]فروردین!$AD$2:$AD$57,[1]فروردین!$N$2:$N$57,7204,[1]فروردین!$D$2:$D$57,$F$14,[1]فروردین!$AA$2:$AA$57,P3) -> 0 | Q14: =SUMIFS([1]فروردین!$AD$2:$AD$57,[1]فروردین!$N$2:$N$57,7204,[1]فروردین!$D$2:$D$57,$F$14,[1]فروردین!$AA$2:$AA$57,Q3) -> 0 | R14: =SUMIFS([1]فروردین!$AD$2:$AD$57,[1]فروردین!$N$2:$N$57,7204,[1]فروردین!$D$2:$D$57,$F$14,[1]فروردین!$AA$2:$AA$57,R3) -> 0 | S14: =SUMIFS([1]فروردین!$AD$2:$AD$57,[1]فروردین!$N$2:$N$57,7204,[1]فروردین!$D$2:$D$57,$F$14,[1]فروردین!$AA$2:$AA$57,S3) -> 0 | T14: =SUMIFS([1]فروردین!$AD$2:$AD$57,[1]فروردین!$N$2:$N$57,7204,[1]فروردین!$D$2:$D$57,$F$14,[1]فروردین!$AA$2:$AA$57,T3) -> 0 | U14: =SUMIFS([1]فروردین!$AD$2:$AD$57,[1]فروردین!$N$2:$N$57,7204,[1]فروردین!$D$2:$D$57,$F$14,[1]فروردین!$AA$2:$AA$57,U3) -> 0
A15: 8 | B15: تراش | C15: 7301 | D15: 62.5 | E15: سالم | G15: =SUM(O15:T15) -> 0 | H15: =U15 -> 0 | I15: 0 | J15: 0 | K15: 0 | L15: 0 | M15: =SUM(G15:L15)-D15 -> -62.5 | N15: ② | O15: =SUMIFS([1]فروردین!$AD$2:$AD$57,[1]فروردین!$N$2:$N$57,7301,[1]فروردین!$D$2:$D$57,$F$15,[1]فروردین!$AA$2:$AA$57,O3) -> 0 | P15: =SUMIFS([1]فروردین!$AD$2:$AD$57,[1]فروردین!$N$2:$N$57,7301,[1]فروردین!$D$2:$D$57,$F$15,[1]فروردین!$AA$2:$AA$57,P3) -> 0 | Q15: =SUMIFS([1]فروردین!$AD$2:$AD$57,[1]فروردین!$N$2:$N$57,7301,[1]فروردین!$D$2:$D$57,$F$15,[1]فروردین!$AA$2:$AA$57,Q3) -> 0 | R15: =SUMIFS([1]فروردین!$AD$2:$AD$57,[1]فروردین!$N$2:$N$57,7301,[1]فروردین!$D$2:$D$57,$F$15,[1]فروردین!$AA$2:$AA$57,R3) -> 0 | S15: =SUMIFS([1]فروردین!$AD$2:$AD$57,[1]فروردین!$N$2:$N$57,7301,[1]فروردین!$D$2:$D$57,$F$15,[1]فروردین!$AA$2:$AA$57,S3) -> 0 | T15: =SUMIFS([1]فروردین!$AD$2:$AD$57,[1]فروردین!$N$2:$N$57,7301,[1]فروردین!$D$2:$D$57,$F$15,[1]فروردین!$AA$2:$AA$57,T3) -> 0 | U15: =SUMIFS([1]فروردین!$AD$2:$AD$57,[1]فروردین!$N$2:$N$57,7301,[1]فروردین!$D$2:$D$57,$F$15,[1]فروردین!$AA$2:$AA$57,U3) -> 0
G16: =SUM(O16:T16) -> 0 | H16: =U16 -> 0 | I16: 0 | J16: 0 | K16: 0 | L16: 0 | N16: ② ⑥ | O16: =SUMIFS([1]فروردین!$AD$2:$AD$57,[1]فروردین!$N$2:$N$57,7302,[1]فروردین!$D$2:$D$57,$F$16,[1]فروردین!$AA$2:$AA$57,O3) -> 0 | P16: =SUMIFS([1]فروردین!$AD$2:$AD$57,[1]فروردین!$N$2:$N$57,7302,[1]فروردین!$D$2:$D$57,$F$16,[1]فروردین!$AA$2:$AA$57,P3) -> 0 | Q16: =SUMIFS([1]فروردین!$AD$2:$AD$57,[1]فروردین!$N$2:$N$57,7302,[1]فروردین!$D$2:$D$57,$F$16,[1]فروردین!$AA$2:$AA$57,Q3) -> 0 | R16: =SUMIFS([1]فروردین!$AD$2:$AD$57,[1]فروردین!$N$2:$N$57,7302,[1]فروردین!$D$2:$D$57,$F$16,[1]فروردین!$AA$2:$AA$57,R3) -> 0 | S16: =SUMIFS([1]فروردین!$AD$2:$AD$57,[1]فروردین!$N$2:$N$57,7302,[1]فروردین!$D$2:$D$57,$F$16,[1]فروردین!$AA$2:$AA$57,S3) -> 0 | T16: =SUMIFS([1]فروردین!$AD$2:$AD$57,[1]فروردین!$N$2:$N$57,7302,[1]فروردین!$D$2:$D$57,$F$16,[1]فروردین!$AA$2:$AA$57,T3) -> 0 | U16: =SUMIFS([1]فروردین!$AD$2:$AD$57,[1]فروردین!$N$2:$N$57,7302,[1]فروردین!$D$2:$D$57,$F$16,[1]فروردین!$AA$2:$AA$57,U3) -> 0
A17: 9 | B17: تراش | C17: 7302 | D17: 62.5 | E17: سالم | G17: =SUM(O17:T17) -> 0 | H17: =U17 -> 0 | I17: 6 | J17: 0 | K17: 0 | L17: 0 | M17: =SUM(G16:L18)-D17 -> -56.5 | O17: =SUMIFS([1]فروردین!$AD$2:$AD$57,[1]فروردین!$N$2:$N$57,7302,[1]فروردین!$D$2:$D$57,$F$17,[1]فروردین!$AA$2:$AA$57,O3) -> 0 | P17: =SUMIFS([1]فروردین!$AD$2:$AD$57,[1]فروردین!$N$2:$N$57,7302,[1]فروردین!$D$2:$D$57,$F$17,[1]فروردین!$AA$2:$AA$57,P3) -> 0 | Q17: =SUMIFS([1]فروردین!$AD$2:$AD$57,[1]فروردین!$N$2:$N$57,7302,[1]فروردین!$D$2:$D$57,$F$17,[1]فروردین!$AA$2:$AA$57,Q3) -> 0 | R17: =SUMIFS([1]فروردین!$AD$2:$AD$57,[1]فروردین!$N$2:$N$57,7302,[1]فروردین!$D$2:$D$57,$F$17,[1]فروردین!$AA$2:$AA$57,R3) -> 0 | S17: =SUMIFS([1]فروردین!$AD$2:$AD$57,[1]فروردین!$N$2:$N$57,7302,[1]فروردین!$D$2:$D$57,$F$17,[1]فروردین!$AA$2:$AA$57,S3) -> 0 | T17: =SUMIFS([1]فروردین!$AD$2:$AD$57,[1]فروردین!$N$2:$N$57,7302,[1]فروردین!$D$2:$D$57,$F$17,[1]فروردین!$AA$2:$AA$57,T3) -> 0 | U17: =SUMIFS([1]فروردین!$AD$2:$AD$57,[1]فروردین!$N$2:$N$57,7302,[1]فروردین!$D$2:$D$57,$F$17,[1]فروردین!$AA$2:$AA$57,U3) -> 0
G18: =SUM(O18:T18) -> 0 | H18: =U18 -> 0 | I18: 0 | J18: 0 | K18: 0 | L18: 0 | O18: =SUMIFS([1]فروردین!$AD$2:$AD$57,[1]فروردین!$N$2:$N$57,7302,[1]فروردین!$D$2:$D$57,$F$18,[1]فروردین!$AA$2:$AA$57,O3) -> 0 | P18: =SUMIFS([1]فروردین!$AD$2:$AD$57,[1]فروردین!$N$2:$N$57,7302,[1]فروردین!$D$2:$D$57,$F$18,[1]فروردین!$AA$2:$AA$57,P3) -> 0 | Q18: =SUMIFS([1]فروردین!$AD$2:$AD$57,[1]فروردین!$N$2:$N$57,7302,[1]فروردین!$D$2:$D$57,$F$18,[1]فروردین!$AA$2:$AA$57,Q3) -> 0 | R18: =SUMIFS([1]فروردین!$AD$2:$AD$57,[1]فروردین!$N$2:$N$57,7302,[1]فروردین!$D$2:$D$57,$F$18,[1]فروردین!$AA$2:$AA$57,R3) -> 0 | S18: =SUMIFS([1]فروردین!$AD$2:$AD$57,[1]فروردین!$N$2:$N$57,7302,[1]فروردین!$D$2:$D$57,$F$18,[1]فروردین!$AA$2:$AA$57,S3) -> 0 | T18: =SUMIFS([1]فروردین!$AD$2:$AD$57,[1]فروردین!$N$2:$N$57,7302,[1]فروردین!$D$2:$D$57,$F$18,[1]فروردین!$AA$2:$AA$57,T3) -> 0 | U18: =SUMIFS([1]فروردین!$AD$2:$AD$57,[1]فروردین!$N$2:$N$57,7302,[1]فروردین!$D$2:$D$57,$F$18,[1]فروردین!$AA$2:$AA$57,U3) -> 0
A19: 10 | B19: تراش | C19: 7303 | D19: 44 | E19: خراب | G19: =SUM(O19:T19) -> 0 | H19: =U19 -> 0 | I19: 0 | J19: 0 | K19: 0 | L19: 0 | M19: =SUM(G19:L19)-44 -> -44 | O19: =SUMIFS([1]فروردین!$AD$2:$AD$57,[1]فروردین!$N$2:$N$57,7303,[1]فروردین!$D$2:$D$57,$F$19,[1]فروردین!$AA$2:$AA$57,O3) -> 0 | P19: =SUMIFS([1]فروردین!$AD$2:$AD$57,[1]فروردین!$N$2:$N$57,7303,[1]فروردین!$D$2:$D$57,$F$19,[1]فروردین!$AA$2:$AA$57,P3) -> 0 | Q19: =SUMIFS([1]فروردین!$AD$2:$AD$57,[1]فروردین!$N$2:$N$57,7303,[1]فروردین!$D$2:$D$57,$F$19,[1]فروردین!$AA$2:$AA$57,Q3) -> 0 | R19: =SUMIFS([1]فروردین!$AD$2:$AD$57,[1]فروردین!$N$2:$N$57,7303,[1]فروردین!$D$2:$D$57,$F$19,[1]فروردین!$AA$2:$AA$57,R3) -> 0 | S19: =SUMIFS([1]فروردین!$AD$2:$AD$57,[1]فروردین!$N$2:$N$57,7303,[1]فروردین!$D$2:$D$57,$F$19,[1]فروردین!$AA$2:$AA$57,S3) -> 0 | T19: =SUMIFS([1]فروردین!$AD$2:$AD$57,[1]فروردین!$N$2:$N$57,7303,[1]فروردین!$D$2:$D$57,$F$19,[1]فروردین!$AA$2:$AA$57,T3) -> 0 | U19: =SUMIFS([1]فروردین!$AD$2:$AD$57,[1]فروردین!$N$2:$N$57,7303,[1]فروردین!$D$2:$D$57,$F$19,[1]فروردین!$AA$2:$AA$57,U3) -> 0
G20: =SUM(O20:T20) -> 0 | H20: =U20 -> 0 | I20: 0 | J20: 0 | K20: 0 | L20: 0 | N20: ⑥ | O20: =SUMIFS([1]فروردین!$AD$2:$AD$57,[1]فروردین!$N$2:$N$57,7401,[1]فروردین!$D$2:$D$57,$F$20,[1]فروردین!$AA$2:$AA$57,O3) -> 0 | P20: =SUMIFS([1]فروردین!$AD$2:$AD$57,[1]فروردین!$N$2:$N$57,7401,[1]فروردین!$D$2:$D$57,$F$20,[1]فروردین!$AA$2:$AA$57,P3) -> 0 | Q20: =SUMIFS([1]فروردین!$AD$2:$AD$57,[1]فروردین!$N$2:$N$57,7401,[1]فروردین!$D$2:$D$57,$F$20,[1]فروردین!$AA$2:$AA$57,Q3) -> 0 | R20: =SUMIFS([1]فروردین!$AD$2:$AD$57,[1]فروردین!$N$2:$N$57,7401,[1]فروردین!$D$2:$D$57,$F$20,[1]فروردین!$AA$2:$AA$57,R3) -> 0 | S20: =SUMIFS([1]فروردین!$AD$2:$AD$57,[1]فروردین!$N$2:$N$57,7401,[1]فروردین!$D$2:$D$57,$F$20,[1]فروردین!$AA$2:$AA$57,S3) -> 0 | T20: =SUMIFS([1]فروردین!$AD$2:$AD$57,[1]فروردین!$N$2:$N$57,7401,[1]فروردین!$D$2:$D$57,$F$20,[1]فروردین!$AA$2:$AA$57,T3) -> 0 | U20: =SUMIFS([1]فروردین!$AD$2:$AD$57,[1]فروردین!$N$2:$N$57,7401,[1]فروردین!$D$2:$D$57,$F$20,[1]فروردین!$AA$2:$AA$57,U3) -> 0
A21: 11 | B21: دریل رادیال | C21: 7401 | D21: 62.5 | E21: سالم | G21: =SUM(O21:T21) -> 0 | H21: =U21 -> 0 | I21: 0 | J21: 0 | K21: 0 | L21: 0 | M21: =SUM(G20:L22)-D21 -> -62.5 | O21: =SUMIFS([1]فروردین!$AD$2:$AD$57,[1]فروردین!$N$2:$N$57,7401,[1]فروردین!$D$2:$D$57,$F$21,[1]فروردین!$AA$2:$AA$57,O3) -> 0 | P21: =SUMIFS([1]فروردین!$AD$2:$AD$57,[1]فروردین!$N$2:$N$57,7401,[1]فروردین!$D$2:$D$57,$F$21,[1]فروردین!$AA$2:$AA$57,P3) -> 0 | Q21: =SUMIFS([1]فروردین!$AD$2:$AD$57,[1]فروردین!$N$2:$N$57,7401,[1]فروردین!$D$2:$D$57,$F$21,[1]فروردین!$AA$2:$AA$57,Q3) -> 0 | R21: =SUMIFS([1]فروردین!$AD$2:$AD$57,[1]فروردین!$N$2:$N$57,7401,[1]فروردین!$D$2:$D$57,$F$21,[1]فروردین!$AA$2:$AA$57,R3) -> 0 | S21: =SUMIFS([1]فروردین!$AD$2:$AD$57,[1]فروردین!$N$2:$N$57,7401,[1]فروردین!$D$2:$D$57,$F$21,[1]فروردین!$AA$2:$AA$57,S3) -> 0 | T21: =SUMIFS([1]فروردین!$AD$2:$AD$57,[1]فروردین!$N$2:$N$57,7401,[1]فروردین!$D$2:$D$57,$F$21,[1]فروردین!$AA$2:$AA$57,T3) -> 0 | U21: =SUMIFS([1]فروردین!$AD$2:$AD$57,[1]فروردین!$N$2:$N$57,7401,[1]فروردین!$D$2:$D$57,$F$21,[1]فروردین!$AA$2:$AA$57,U3) -> 0
B22: دریل رادیال | C22: 7401 | E22: سام | G22: =SUM(O22:T22) -> 0 | H22: =U22 -> 0 | I22: 0 | J22: 0 | K22: 0 | L22: 0 | O22: =SUMIFS([1]فروردین!$AD$2:$AD$57,[1]فروردین!$N$2:$N$57,7401,[1]فروردین!$D$2:$D$57,$F$22,[1]فروردین!$AA$2:$AA$57,O3) -> 0 | P22: =SUMIFS([1]فروردین!$AD$2:$AD$57,[1]فروردین!$N$2:$N$57,7401,[1]فروردین!$D$2:$D$57,$F$22,[1]فروردین!$AA$2:$AA$57,P3) -> 0 | Q22: =SUMIFS([1]فروردین!$AD$2:$AD$57,[1]فروردین!$N$2:$N$57,7401,[1]فروردین!$D$2:$D$57,$F$22,[1]فروردین!$AA$2:$AA$57,Q3) -> 0 | R22: =SUMIFS([1]فروردین!$AD$2:$AD$57,[1]فروردین!$N$2:$N$57,7401,[1]فروردین!$D$2:$D$57,$F$22,[1]فروردین!$AA$2:$AA$57,R3) -> 0 | S22: =SUMIFS([1]فروردین!$AD$2:$AD$57,[1]فروردین!$N$2:$N$57,7401,[1]فروردین!$D$2:$D$57,$F$22,[1]فروردین!$AA$2:$AA$57,S3) -> 0 | T22: =SUMIFS([1]فروردین!$AD$2:$AD$57,[1]فروردین!$N$2:$N$57,7401,[1]فروردین!$D$2:$D$57,$F$22,[1]فروردین!$AA$2:$AA$57,T3) -> 0 | U22: =SUMIFS([1]فروردین!$AD$2:$AD$57,[1]فروردین!$N$2:$N$57,7401,[1]فروردین!$D$2:$D$57,$F$22,[1]فروردین!$AA$2:$AA$57,U3) -> 0
E23: خراب | G23: =SUM(O23:T23) -> 0 | H23: =U23 -> 0 | I23: 0 | J23: 0 | K23: 0 | L23: 0 | N23: ③ | O23: =SUMIFS([1]فروردین!$AD$2:$AD$57,[1]فروردین!$N$2:$N$57,7501,[1]فروردین!$D$2:$D$57,$F$23,[1]فروردین!$AA$2:$AA$57,O3) -> 0 | P23: =SUMIFS([1]فروردین!$AD$2:$AD$57,[1]فروردین!$N$2:$N$57,7501,[1]فروردین!$D$2:$D$57,$F$23,[1]فروردین!$AA$2:$AA$57,P3) -> 0 | Q23: =SUMIFS([1]فروردین!$AD$2:$AD$57,[1]فروردین!$N$2:$N$57,7501,[1]فروردین!$D$2:$D$57,$F$23,[1]فروردین!$AA$2:$AA$57,Q3) -> 0 | R23: =SUMIFS([1]فروردین!$AD$2:$AD$57,[1]فروردین!$N$2:$N$57,7501,[1]فروردین!$D$2:$D$57,$F$23,[1]فروردین!$AA$2:$AA$57,R3) -> 0 | S23: =SUMIFS([1]فروردین!$AD$2:$AD$57,[1]فروردین!$N$2:$N$57,7501,[1]فروردین!$D$2:$D$57,$F$23,[1]فروردین!$AA$2:$AA$57,S3) -> 0 | T23: =SUMIFS([1]فروردین!$AD$2:$AD$57,[1]فروردین!$N$2:$N$57,7501,[1]فروردین!$D$2:$D$57,$F$23,[1]فروردین!$AA$2:$AA$57,T3) -> 0 | U23: =SUMIFS([1]فروردین!$AD$2:$AD$57,[1]فروردین!$N$2:$N$57,7501,[1]فروردین!$D$2:$D$57,$F$23,[1]فروردین!$AA$2:$AA$57,U3) -> 0
A24: 12 | B24: سنگ تخت | C24: 7501 | D24: 62.5 | G24: =SUM(O24:T24) -> 0 | H24: =U24 -> 0 | I24: 0 | J24: 0 | K24: 0 | L24: 0 | M24: =SUM(G23:L25)-D24 -> -62.5 | O24: =SUMIFS([1]فروردین!$AD$2:$AD$57,[1]فروردین!$N$2:$N$57,7501,[1]فروردین!$D$2:$D$57,$F$24,[1]فروردین!$AA$2:$AA$57,O3) -> 0 | P24: =SUMIFS([1]فروردین!$AD$2:$AD$57,[1]فروردین!$N$2:$N$57,7501,[1]فروردین!$D$2:$D$57,$F$24,[1]فروردین!$AA$2:$AA$57,P3) -> 0 | Q24: =SUMIFS([1]فروردین!$AD$2:$AD$57,[1]فروردین!$N$2:$N$57,7501,[1]فروردین!$D$2:$D$57,$F$24,[1]فروردین!$AA$2:$AA$57,Q3) -> 0 | R24: =SUMIFS([1]فروردین!$AD$2:$AD$57,[1]فروردین!$N$2:$N$57,7501,[1]فروردین!$D$2:$D$57,$F$24,[1]فروردین!$AA$2:$AA$57,R3) -> 0 | S24: =SUMIFS([1]فروردین!$AD$2:$AD$57,[1]فروردین!$N$2:$N$57,7501,[1]فروردین!$D$2:$D$57,$F$24,[1]فروردین!$AA$2:$AA$57,S3) -> 0 | T24: =SUMIFS([1]فروردین!$AD$2:$AD$57,[1]فروردین!$N$2:$N$57,7501,[1]فروردین!$D$2:$D$57,$F$24,[1]فروردین!$AA$2:$AA$57,T3) -> 0 | U24: =SUMIFS([1]فروردین!$AD$2:$AD$57,[1]فروردین!$N$2:$N$57,7501,[1]فروردین!$D$2:$D$57,$F$24,[1]فروردین!$AA$2:$AA$57,U3) -> 0
G25: =SUM(O25:T25) -> 0 | H25: =U25 -> 0 | I25: 0 | J25: 0 | K25: 0 | L25: 0 | O25: =SUMIFS([1]فروردین!$AD$2:$AD$57,[1]فروردین!$N$2:$N$57,7501,[1]فروردین!$D$2:$D$57,$F$25,[1]فروردین!$AA$2:$AA$57,O3) -> 0 | P25: =SUMIFS([1]فروردین!$AD$2:$AD$57,[1]فروردین!$N$2:$N$57,7501,[1]فروردین!$D$2:$D$57,$F$25,[1]فروردین!$AA$2:$AA$57,P3) -> 0 | Q25: =SUMIFS([1]فروردین!$AD$2:$AD$57,[1]فروردین!$N$2:$N$57,7501,[1]فروردین!$D$2:$D$57,$F$25,[1]فروردین!$AA$2:$AA$57,Q3) -> 0 | R25: =SUMIFS([1]فروردین!$AD$2:$AD$57,[1]فروردین!$N$2:$N$57,7501,[1]فروردین!$D$2:$D$57,$F$25,[1]فروردین!$AA$2:$AA$57,R3) -> 0 | S25: =SUMIFS([1]فروردین!$AD$2:$AD$57,[1]فروردین!$N$2:$N$57,7501,[1]فروردین!$D$2:$D$57,$F$25,[1]فروردین!$AA$2:$AA$57,S3) -> 0 | T25: =SUMIFS([1]فروردین!$AD$2:$AD$57,[1]فروردین!$N$2:$N$57,7501,[1]فروردین!$D$2:$D$57,$F$25,[1]فروردین!$AA$2:$AA$57,T3) -> 0 | U25: =SUMIFS([1]فروردین!$AD$2:$AD$57,[1]فروردین!$N$2:$N$57,7501,[1]فروردین!$D$2:$D$57,$F$25,[1]فروردین!$AA$2:$AA$57,U3) -> 0
E26: تست | G26: =SUM(O26:T26) -> 0 | H26: =U26 -> 0 | I26: 0 | J26: 0 | K26: 0 | L26: 0 | N26: ⑥ ③ | O26: =SUMIFS([1]فروردین!$AD$2:$AD$57,[1]فروردین!$N$2:$N$57,7502,[1]فروردین!$D$2:$D$57,$F$26,[1]فروردین!$AA$2:$AA$57,O3) -> 0 | P26: =SUMIFS([1]فروردین!$AD$2:$AD$57,[1]فروردین!$N$2:$N$57,7502,[1]فروردین!$D$2:$D$57,$F$26,[1]فروردین!$AA$2:$AA$57,P3) -> 0 | Q26: =SUMIFS([1]فروردین!$AD$2:$AD$57,[1]فروردین!$N$2:$N$57,7502,[1]فروردین!$D$2:$D$57,$F$26,[1]فروردین!$AA$2:$AA$57,Q3) -> 0 | R26: =SUMIFS([1]فروردین!$AD$2:$AD$57,[1]فروردین!$N$2:$N$57,7502,[1]فروردین!$D$2:$D$57,$F$26,[1]فروردین!$AA$2:$AA$57,R3) -> 0 | S26: =SUMIFS([1]فروردین!$AD$2:$AD$57,[1]فروردین!$N$2:$N$57,7502,[1]فروردین!$D$2:$D$57,$F$26,[1]فروردین!$AA$2:$AA$57,S3) -> 0 | T26: =SUMIFS([1]فروردین!$AD$2:$AD$57,[1]فروردین!$N$2:$N$57,7502,[1]فروردین!$D$2:$D$57,$F$26,[1]فروردین!$AA$2:$AA$57,T3) -> 0 | U26: =SUMIFS([1]فروردین!$AD$2:$AD$57,[1]فروردین!$N$2:$N$57,7502,[1]فروردین!$D$2:$D$57,$F$26,[1]فروردین!$AA$2:$AA$57,U3) -> 0
A27: 13 | B27: سنگ تخت | C27: 7502 | D27: 62.5 | F27: یاراحمدی | G27: =SUM(O27:T27) -> 0 | H27: =U27 -> 0 | I27: 0 | J27: 29.5 | K27: 0 | L27: 0 | M27: =SUM(G26:L28)-D27 -> -33 | O27: =SUMIFS([1]فروردین!$AD$2:$AD$57,[1]فروردین!$N$2:$N$57,7502,[1]فروردین!$D$2:$D$57,$F$27,[1]فروردین!$AA$2:$AA$57,O3) -> 0 | P27: =SUMIFS([1]فروردین!$AD$2:$AD$57,[1]فروردین!$N$2:$N$57,7502,[1]فروردین!$D$2:$D$57,$F$27,[1]فروردین!$AA$2:$AA$57,P3) -> 0 | Q27: =SUMIFS([1]فروردین!$AD$2:$AD$57,[1]فروردین!$N$2:$N$57,7502,[1]فروردین!$D$2:$D$57,$F$27,[1]فروردین!$AA$2:$AA$57,Q3) -> 0 | R27: =SUMIFS([1]فروردین!$AD$2:$AD$57,[1]فروردین!$N$2:$N$57,7502,[1]فروردین!$D$2:$D$57,$F$27,[1]فروردین!$AA$2:$AA$57,R3) -> 0 | S27: =SUMIFS([1]فروردین!$AD$2:$AD$57,[1]فروردین!$N$2:$N$57,7502,[1]فروردین!$D$2:$D$57,$F$27,[1]فروردین!$AA$2:$AA$57,S3) -> 0 | T27: =SUMIFS([1]فروردین!$AD$2:$AD$57,[1]فروردین!$N$2:$N$57,7502,[1]فروردین!$D$2:$D$57,$F$27,[1]فروردین!$AA$2:$AA$57,T3) -> 0 | U27: =SUMIFS([1]فروردین!$AD$2:$AD$57,[1]فروردین!$N$2:$N$57,7502,[1]فروردین!$D$2:$D$57,$F$27,[1]فروردین!$AA$2:$AA$57,U3) -> 0
G28: =SUM(O28:T28) -> 0 | H28: =U28 -> 0 | I28: 0 | J28: 0 | K28: 0 | L28: 0 | O28: =SUMIFS([1]فروردین!$AD$2:$AD$57,[1]فروردین!$N$2:$N$57,7502,[1]فروردین!$D$2:$D$57,$F$28,[1]فروردین!$AA$2:$AA$57,O3) -> 0 | P28: =SUMIFS([1]فروردین!$AD$2:$AD$57,[1]فروردین!$N$2:$N$57,7502,[1]فروردین!$D$2:$D$57,$F$28,[1]فروردین!$AA$2:$AA$57,P3) -> 0 | Q28: =SUMIFS([1]فروردین!$AD$2:$AD$57,[1]فروردین!$N$2:$N$57,7502,[1]فروردین!$D$2:$D$57,$F$28,[1]فروردین!$AA$2:$AA$57,Q3) -> 0 | R28: =SUMIFS([1]فروردین!$AD$2:$AD$57,[1]فروردین!$N$2:$N$57,7502,[1]فروردین!$D$2:$D$57,$F$28,[1]فروردین!$AA$2:$AA$57,R3) -> 0 | S28: =SUMIFS([1]فروردین!$AD$2:$AD$57,[1]فروردین!$N$2:$N$57,7502,[1]فروردین!$D$2:$D$57,$F$28,[1]فروردین!$AA$2:$AA$57,S3) -> 0 | T28: =SUMIFS([1]فروردین!$AD$2:$AD$57,[1]فروردین!$N$2:$N$57,7502,[1]فروردین!$D$2:$D$57,$F$28,[1]فروردین!$AA$2:$AA$57,T3) -> 0 | U28: =SUMIFS([1]فروردین!$AD$2:$AD$57,[1]فروردین!$N$2:$N$57,7502,[1]فروردین!$D$2:$D$57,$F$28,[1]فروردین!$AA$2:$AA$57,U3) -> 0
A29: 14 | B29: وایر | C29: 7601 | D29: 68 | E29: سالم | F29: صلواتی | G29: =SUM(O29:T29) -> 0 | H29: =U29 -> 0 | I29: 16 | J29: 0 | K29: 29.5 | L29: 0 | M29: =(J29+J30+I30+I29+H29+H30+G30+G29+L29+K29)-D29 -> -22.5 | N29: ② | O29: =SUMIFS([1]فروردین!$AD$2:$AD$57,[1]فروردین!$N$2:$N$57,7601,[1]فروردین!$D$2:$D$57,$F$29,[1]فروردین!$AA$2:$AA$57,O3) -> 0 | P29: =SUMIFS([1]فروردین!$AD$2:$AD$57,[1]فروردین!$N$2:$N$57,7601,[1]فروردین!$D$2:$D$57,$F$29,[1]فروردین!$AA$2:$AA$57,P3) -> 0 | Q29: =SUMIFS([1]فروردین!$AD$2:$AD$57,[1]فروردین!$N$2:$N$57,7601,[1]فروردین!$D$2:$D$57,$F$29,[1]فروردین!$AA$2:$AA$57,Q3) -> 0 | R29: =SUMIFS([1]فروردین!$AD$2:$AD$57,[1]فروردین!$N$2:$N$57,7601,[1]فروردین!$D$2:$D$57,$F$29,[1]فروردین!$AA$2:$AA$57,R3) -> 0 | S29: =SUMIFS([1]فروردین!$AD$2:$AD$57,[1]فروردین!$N$2:$N$57,7601,[1]فروردین!$D$2:$D$57,$F$29,[1]فروردین!$AA$2:$AA$57,S3) -> 0 | T29: =SUMIFS([1]فروردین!$AD$2:$AD$57,[1]فروردین!$N$2:$N$57,7601,[1]فروردین!$D$2:$D$57,$F$29,[1]فروردین!$AA$2:$AA$57,T3) -> 0 | U29: =SUMIFS([1]فروردین!$AD$2:$AD$57,[1]فروردین!$N$2:$N$57,7601,[1]فروردین!$D$2:$D$57,$F$29,[1]فروردین!$AA$2:$AA$57,U3) -> 0
G30: =SUM(O30:T30) -> 0 | H30: =U30 -> 0 | I30: 0 | J30: 0 | K30: 0 | L30: 0 | O30: =SUMIFS([1]فروردین!$AD$2:$AD$57,[1]فروردین!$N$2:$N$57,7601,[1]فروردین!$D$2:$D$57,$F$30,[1]فروردین!$AA$2:$AA$57,O3) -> 0 | P30: =SUMIFS([1]فروردین!$AD$2:$AD$57,[1]فروردین!$N$2:$N$57,7601,[1]فروردین!$D$2:$D$57,$F$30,[1]فروردین!$AA$2:$AA$57,P3) -> 0 | Q30: =SUMIFS([1]فروردین!$AD$2:$AD$57,[1]فروردین!$N$2:$N$57,7601,[1]فروردین!$D$2:$D$57,$F$30,[1]فروردین!$AA$2:$AA$57,Q3) -> 0 | R30: =SUMIFS([1]فروردین!$AD$2:$AD$57,[1]فروردین!$N$2:$N$57,7601,[1]فروردین!$D$2:$D$57,$F$30,[1]فروردین!$AA$2:$AA$57,R3) -> 0 | S30: =SUMIFS([1]فروردین!$AD$2:$AD$57,[1]فروردین!$N$2:$N$57,7601,[1]فروردین!$D$2:$D$57,$F$30,[1]فروردین!$AA$2:$AA$57,S3) -> 0 | T30: =SUMIFS([1]فروردین!$AD$2:$AD$57,[1]فروردین!$N$2:$N$57,7601,[1]فروردین!$D$2:$D$57,$F$30,[1]فروردین!$AA$2:$AA$57,T3) -> 0 | U30: =SUMIFS([1]فروردین!$AD$2:$AD$57,[1]فروردین!$N$2:$N$57,7601,[1]فروردین!$D$2:$D$57,$F$30,[1]فروردین!$AA$2:$AA$57,U3) -> 0
A31: 15 | B31: وایر | C31: 7602 | D31: 68 | E31: سالم | F31: صلواتی | G31: =SUM(O31:T31) -> 0 | H31: =U31 -> 0 | I31: 16 | J31: 0 | K31: 29.5 | L31: 0 | M31: =(J31+J32+I32+I31+H31+H32+G32+G31)-D31 -> -52 | N31: ② | O31: =SUMIFS([1]فروردین!$AD$2:$AD$57,[1]فروردین!$N$2:$N$57,7602,[1]فروردین!$D$2:$D$57,$F$31,[1]فروردین!$AA$2:$AA$57,O3) -> 0 | P31: =SUMIFS([1]فروردین!$AD$2:$AD$57,[1]فروردین!$N$2:$N$57,7602,[1]فروردین!$D$2:$D$57,$F$31,[1]فروردین!$AA$2:$AA$57,P3) -> 0 | Q31: =SUMIFS([1]فروردین!$AD$2:$AD$57,[1]فروردین!$N$2:$N$57,7602,[1]فروردین!$D$2:$D$57,$F$31,[1]فروردین!$AA$2:$AA$57,Q3) -> 0 | R31: =SUMIFS([1]فروردین!$AD$2:$AD$57,[1]فروردین!$N$2:$N$57,7602,[1]فروردین!$D$2:$D$57,$F$31,[1]فروردین!$AA$2:$AA$57,R3) -> 0 | S31: =SUMIFS([1]فروردین!$AD$2:$AD$57,[1]فروردین!$N$2:$N$57,7602,[1]فروردین!$D$2:$D$57,$F$31,[1]فروردین!$AA$2:$AA$57,S3) -> 0 | T31: =SUMIFS([1]فروردین!$AD$2:$AD$57,[1]فروردین!$N$2:$N$57,7602,[1]فروردین!$D$2:$D$57,$F$31,[1]فروردین!$AA$2:$AA$57,T3) -> 0 | U31: =SUMIFS([1]فروردین!$AD$2:$AD$57,[1]فروردین!$N$2:$N$57,7602,[1]فروردین!$D$2:$D$57,$F$31,[1]فروردین!$AA$2:$AA$57,U3) -> 0
G32: =SUM(O32:T32) -> 0 | H32: =U32 -> 0 | I32: 0 | J32: 0 | K32: 0 | L32: 0 | O32: =SUMIFS([1]فروردین!$AD$2:$AD$57,[1]فروردین!$N$2:$N$57,7602,[1]فروردین!$D$2:$D$57,$F$32,[1]فروردین!$AA$2:$AA$57,O3) -> 0 | P32: =SUMIFS([1]فروردین!$AD$2:$AD$57,[1]فروردین!$N$2:$N$57,7602,[1]فروردین!$D$2:$D$57,$F$32,[1]فروردین!$AA$2:$AA$57,P3) -> 0 | Q32: =SUMIFS([1]فروردین!$AD$2:$AD$57,[1]فروردین!$N$2:$N$57,7602,[1]فروردین!$D$2:$D$57,$F$32,[1]فروردین!$AA$2:$AA$57,Q3) -> 0 | R32: =SUMIFS([1]فروردین!$AD$2:$AD$57,[1]فروردین!$N$2:$N$57,7602,[1]فروردین!$D$2:$D$57,$F$32,[1]فروردین!$AA$2:$AA$57,R3) -> 0 | S32: =SUMIFS([1]فروردین!$AD$2:$AD$57,[1]فروردین!$N$2:$N$57,7602,[1]فروردین!$D$2:$D$57,$F$32,[1]فروردین!$AA$2:$AA$57,S3) -> 0 | T32: =SUMIFS([1]فروردین!$AD$2:$AD$57,[1]فروردین!$N$2:$N$57,7602,[1]فروردین!$D$2:$D$57,$F$32,[1]فروردین!$AA$2:$AA$57,T3) -> 0 | U32: =SUMIFS([1]فروردین!$AD$2:$AD$57,[1]فروردین!$N$2:$N$57,7602,[1]فروردین!$D$2:$D$57,$F$32,[1]فروردین!$AA$2:$AA$57,U3) -> 0
A33: 16 | B33: وایر | C33: 7603 | D33: 68 | E33: سالم | F33: صلواتی | G33: =SUM(O33:T33) -> 0 | H33: =U33 -> 0 | I33: 0 | J33: 0 | K33: 29.5 | L33: 0 | M33: =(J33+J34+I34+I33+H33+H34+G34+G33+L33+L34)-D33 -> -68 | N33: ⑥ | O33: =SUMIFS([1]فروردین!$AD$2:$AD$57,[1]فروردین!$N$2:$N$57,7603,[1]فروردین!$D$2:$D$57,$F$33,[1]فروردین!$AA$2:$AA$57,O3) -> 0 | P33: =SUMIFS([1]فروردین!$AD$2:$AD$57,[1]فروردین!$N$2:$N$57,7603,[1]فروردین!$D$2:$D$57,$F$33,[1]فروردین!$AA$2:$AA$57,P3) -> 0 | Q33: =SUMIFS([1]فروردین!$AD$2:$AD$57,[1]فروردین!$N$2:$N$57,7603,[1]فروردین!$D$2:$D$57,$F$33,[1]فروردین!$AA$2:$AA$57,Q3) -> 0 | R33: =SUMIFS([1]فروردین!$AD$2:$AD$57,[1]فروردین!$N$2:$N$57,7603,[1]فروردین!$D$2:$D$57,$F$33,[1]فروردین!$AA$2:$AA$57,R3) -> 0 | S33: =SUMIFS([1]فروردین!$AD$2:$AD$57,[1]فروردین!$N$2:$N$57,7603,[1]فروردین!$D$2:$D$57,$F$33,[1]فروردین!$AA$2:$AA$57,S3) -> 0 | T33: =SUMIFS([1]فروردین!$AD$2:$AD$57,[1]فروردین!$N$2:$N$57,7603,[1]فروردین!$D$2:$D$57,$F$33,[1]فروردین!$AA$2:$AA$57,T3) -> 0 | U33: =SUMIFS([1]فروردین!$AD$2:$AD$57,[1]فروردین!$N$2:$N$57,7603,[1]فروردین!$D$2:$D$57,$F$33,[1]فروردین!$AA$2:$AA$57,U3) -> 0
G34: =SUM(O34:T34) -> 0 | H34: =U34 -> 0 | I34: 0 | J34: 0 | K34: 0 | L34: 0 | O34: =SUMIFS([1]فروردین!$AD$2:$AD$57,[1]فروردین!$N$2:$N$57,7603,[1]فروردین!$D$2:$D$57,$F$34,[1]فروردین!$AA$2:$AA$57,O3) -> 0 | P34: =SUMIFS([1]فروردین!$AD$2:$AD$57,[1]فروردین!$N$2:$N$57,7603,[1]فروردین!$D$2:$D$57,$F$34,[1]فروردین!$AA$2:$AA$57,P3) -> 0 | Q34: =SUMIFS([1]فروردین!$AD$2:$AD$57,[1]فروردین!$N$2:$N$57,7603,[1]فروردین!$D$2:$D$57,$F$34,[1]فروردین!$AA$2:$AA$57,Q3) -> 0 | R34: =SUMIFS([1]فروردین!$AD$2:$AD$57,[1]فروردین!$N$2:$N$57,7603,[1]فروردین!$D$2:$D$57,$F$34,[1]فروردین!$AA$2:$AA$57,R3) -> 0 | S34: =SUMIFS([1]فروردین!$AD$2:$AD$57,[1]فروردین!$N$2:$N$57,7603,[1]فروردین!$D$2:$D$57,$F$34,[1]فروردین!$AA$2:$AA$57,S3) -> 0 | T34: =SUMIFS([1]فروردین!$AD$2:$AD$57,[1]فروردین!$N$2:$N$57,7603,[1]فروردین!$D$2:$D$57,$F$34,[1]فروردین!$AA$2:$AA$57,T3) -> 0 | U34: =SUMIFS([1]فروردین!$AD$2:$AD$57,[1]فروردین!$N$2:$N$57,7603,[1]فروردین!$D$2:$D$57,$F$34,[1]فروردین!$AA$2:$AA$57,U3) -> 0
A35: 17 | B35: وایر | C35: 7604 | D35: 68 | E35: خراب | G35: =SUM(O35:T35) -> 0 | H35: =U35 -> 0 | I35: 0 | J35: 68 | K35: 0 | L35: 0 | M35: =(J35+J36+I35+I36+H36+H35+G35+G36)-D35 -> 0 | N35: ③
G36: =SUM(O36:T36) -> 0 | H36: =U36 -> 0 | I36: 0 | J36: 0 | K36: 0 | L36: 0
A37: 18 | B37: وایر | C37: 7605 | D37: 68 | E37: سالم | F37: صلواتی | G37: =SUM(O37:T37) -> 0 | H37: =U37 -> 0 | I37: 8 | J37: 0 | K37: 29.5 | L37: 0 | M37: =(G37+H37+I37+J37+K37+L37)-D37 -> -30.5 | O37: =SUMIFS([1]فروردین!$AD$2:$AD$57,[1]فروردین!$N$2:$N$57,7605,[1]فروردین!$D$2:$D$57,$F$37,[1]فروردین!$AA$2:$AA$57,O3) -> 0 | P37: =SUMIFS([1]فروردین!$AD$2:$AD$57,[1]فروردین!$N$2:$N$57,7605,[1]فروردین!$D$2:$D$57,$F$37,[1]فروردین!$AA$2:$AA$57,P3) -> 0 | Q37: =SUMIFS([1]فروردین!$AD$2:$AD$57,[1]فروردین!$N$2:$N$57,7605,[1]فروردین!$D$2:$D$57,$F$37,[1]فروردین!$AA$2:$AA$57,Q3) -> 0 | R37: =SUMIFS([1]فروردین!$AD$2:$AD$57,[1]فروردین!$N$2:$N$57,7605,[1]فروردین!$D$2:$D$57,$F$37,[1]فروردین!$AA$2:$AA$57,R3) -> 0 | S37: =SUMIFS([1]فروردین!$AD$2:$AD$57,[1]فروردین!$N$2:$N$57,7605,[1]فروردین!$D$2:$D$57,$F$37,[1]فروردین!$AA$2:$AA$57,S3) -> 0 | T37: =SUMIFS([1]فروردین!$AD$2:$AD$57,[1]فروردین!$N$2:$N$57,7605,[1]فروردین!$D$2:$D$57,$F$37,[1]فروردین!$AA$2:$AA$57,T3) -> 0 | U37: =SUMIFS([1]فروردین!$AD$2:$AD$57,[1]فروردین!$N$2:$N$57,7605,[1]فروردین!$D$2:$D$57,$F$37,[1]فروردین!$AA$2:$AA$57,U3) -> 0
G38: =SUM(O38:T38) -> 0 | H38: =U38 -> 0 | I38: 0 | J38: 0 | K38: 0 | L38: 0 | O38: =SUMIFS([1]فروردین!$AD$2:$AD$57,[1]فروردین!$N$2:$N$57,7605,[1]فروردین!$D$2:$D$57,$F$38,[1]فروردین!$AA$2:$AA$57,O3) -> 0 | P38: =SUMIFS([1]فروردین!$AD$2:$AD$57,[1]فروردین!$N$2:$N$57,7605,[1]فروردین!$D$2:$D$57,$F$38,[1]فروردین!$AA$2:$AA$57,P3) -> 0 | Q38: =SUMIFS([1]فروردین!$AD$2:$AD$57,[1]فروردین!$N$2:$N$57,7605,[1]فروردین!$D$2:$D$57,$F$38,[1]فروردین!$AA$2:$AA$57,Q3) -> 0 | R38: =SUMIFS([1]فروردین!$AD$2:$AD$57,[1]فروردین!$N$2:$N$57,7605,[1]فروردین!$D$2:$D$57,$F$38,[1]فروردین!$AA$2:$AA$57,R3) -> 0 | S38: =SUMIFS([1]فروردین!$AD$2:$AD$57,[1]فروردین!$N$2:$N$57,7605,[1]فروردین!$D$2:$D$57,$F$38,[1]فروردین!$AA$2:$AA$57,S3) -> 0 | T38: =SUMIFS([1]فروردین!$AD$2:$AD$57,[1]فروردین!$N$2:$N$57,7605,[1]فروردین!$D$2:$D$57,$F$38,[1]فروردین!$AA$2:$AA$57,T3) -> 0 | U38: =SUMIFS([1]فروردین!$AD$2:$AD$57,[1]فروردین!$N$2:$N$57,7605,[1]فروردین!$D$2:$D$57,$F$38,[1]فروردین!$AA$2:$AA$57,U3) -> 0
G39: =SUM(O39:T39) -> 0 | H39: =U39 -> 0 | I39: 0 | J39: 0 | K39: 0 | L39: 0 | N39: ⑥ | O39: =SUMIFS([1]فروردین!$AD$2:$AD$57,[1]فروردین!$N$2:$N$57,7701,[1]فروردین!$D$2:$D$57,$F$39,[1]فروردین!$AA$2:$AA$57,O3) -> 0 | P39: =SUMIFS([1]فروردین!$AD$2:$AD$57,[1]فروردین!$N$2:$N$57,7701,[1]فروردین!$D$2:$D$57,$F$39,[1]فروردین!$AA$2:$AA$57,P3) -> 0 | Q39: =SUMIFS([1]فروردین!$AD$2:$AD$57,[1]فروردین!$N$2:$N$57,7701,[1]فروردین!$D$2:$D$57,$F$39,[1]فروردین!$AA$2:$AA$57,Q3) -> 0 | R39: =SUMIFS([1]فروردین!$AD$2:$AD$57,[1]فروردین!$N$2:$N$57,7701,[1]فروردین!$D$2:$D$57,$F$39,[1]فروردین!$AA$2:$AA$57,R3) -> 0 | S39: =SUMIFS([1]فروردین!$AD$2:$AD$57,[1]فروردین!$N$2:$N$57,7701,[1]فروردین!$D$2:$D$57,$F$39,[1]فروردین!$AA$2:$AA$57,S3) -> 0 | T39: =SUMIFS([1]فروردین!$AD$2:$AD$57,[1]فروردین!$N$2:$N$57,7701,[1]فروردین!$D$2:$D$57,$F$39,[1]فروردین!$AA$2:$AA$57,T3) -> 0 | U39: =SUMIFS([1]فروردین!$AD$2:$AD$57,[1]فروردین!$N$2:$N$57,7701,[1]فروردین!$D$2:$D$57,$F$39,[1]فروردین!$AA$2:$AA$57,U3) -> 0
A40: 19 | B40: سوپر دریل | C40: 7701 | D40: 62.5 | E40: سالم | G40: =SUM(O40:T40) -> 0 | H40: =U40 -> 0 | I40: 0 | J40: 0 | K40: 0 | L40: 0 | M40: =(J39+J40+J41+I41+I40+I39+H39+H40+H41+G41+G40+G39)-D40 -> -62.5 | O40: =SUMIFS([1]فروردین!$AD$2:$AD$57,[1]فروردین!$N$2:$N$57,7701,[1]فروردین!$D$2:$D$57,$F$40,[1]فروردین!$AA$2:$AA$57,O3) -> 0 | P40: =SUMIFS([1]فروردین!$AD$2:$AD$57,[1]فروردین!$N$2:$N$57,7701,[1]فروردین!$D$2:$D$57,$F$40,[1]فروردین!$AA$2:$AA$57,P3) -> 0 | Q40: =SUMIFS([1]فروردین!$AD$2:$AD$57,[1]فروردین!$N$2:$N$57,7701,[1]فروردین!$D$2:$D$57,$F$40,[1]فروردین!$AA$2:$AA$57,Q3) -> 0 | R40: =SUMIFS([1]فروردین!$AD$2:$AD$57,[1]فروردین!$N$2:$N$57,7701,[1]فروردین!$D$2:$D$57,$F$40,[1]فروردین!$AA$2:$AA$57,R3) -> 0 | S40: =SUMIFS([1]فروردین!$AD$2:$AD$57,[1]فروردین!$N$2:$N$57,7701,[1]فروردین!$D$2:$D$57,$F$40,[1]فروردین!$AA$2:$AA$57,S3) -> 0 | T40: =SUMIFS([1]فروردین!$AD$2:$AD$57,[1]فروردین!$N$2:$N$57,7701,[1]فروردین!$D$2:$D$57,$F$40,[1]فروردین!$AA$2:$AA$57,T3) -> 0 | U40: =SUMIFS([1]فروردین!$AD$2:$AD$57,[1]فروردین!$N$2:$N$57,7701,[1]فروردین!$D$2:$D$57,$F$40,[1]فروردین!$AA$2:$AA$57,U3) -> 0
...

Sheet 3
A1: Performance of molding machines | M1: Date | N1: 1405 | O1: Time of Weeks
M2: weeks | N2: 3
A3: ردیف | B3: ایستگاه | C3: کد دستگاه | D3: ظرفیت نسبی (نفر ساعت) | E3: شاخص سلامت | F3: نام اپراتور | G3: تحقق (کارکرد عادی) | H3: تحقق (جمعه کاری) | I3: مرخصی | J3: خرابی دستگاه | K3: ساعات تعطیل | L3: نبود برق | M3: عدم تحقق | N3: علت عدم تحقق (کد) | O3: 1405/01/15 | P3: 1405/01/16 | Q3: 1405/01/17 | R3: 1405/01/18 | S3: 1405/01/19 | T3: 1405/01/20 | U3: 1405/01/21
B4: فرز | C4: 7101 | D4: 62.5 | E4: سالم | G4: =SUM(O4:T4) -> 0 | H4: =U4 -> 0 | I4: =SUMIFS([1]فروردین!$AF$27:$AF$157,[1]فروردین!$D$27:$D$157,F4) -> 0 | J4: 0 | K4: 0 | L4: 0 | N4: ⑥ ② | O4: =SUMIFS([1]فروردین!$AD$2:$AD$366,[1]فروردین!$N$2:$N$366,7101,[1]فروردین!$D$2:$D$366,$F$4,[1]فروردین!$AA$2:$AA$366,O3) -> 0 | P4: =SUMIFS([1]فروردین!$AD$2:$AD$366,[1]فروردین!$N$2:$N$366,7101,[1]فروردین!$D$2:$D$366,$F$4,[1]فروردین!$AA$2:$AA$366,P3) -> 0 | Q4: =SUMIFS([1]فروردین!$AD$2:$AD$366,[1]فروردین!$N$2:$N$366,7101,[1]فروردین!$D$2:$D$366,$F$4,[1]فروردین!$AA$2:$AA$366,Q3) -> 0 | R4: =SUMIFS([1]فروردین!$AD$2:$AD$366,[1]فروردین!$N$2:$N$366,7101,[1]فروردین!$D$2:$D$366,$F$4,[1]فروردین!$AA$2:$AA$366,R3) -> 0 | S4: =SUMIFS([1]فروردین!$AD$2:$AD$366,[1]فروردین!$N$2:$N$366,7101,[1]فروردین!$D$2:$D$366,$F$4,[1]فروردین!$AA$2:$AA$366,S3) -> 0 | T4: =SUMIFS([1]فروردین!$AD$2:$AD$366,[1]فروردین!$N$2:$N$366,7101,[1]فروردین!$D$2:$D$366,$F$4,[1]فروردین!$AA$2:$AA$366,T3) -> 0 | U4: =SUMIFS([1]فروردین!$AD$2:$AD$366,[1]فروردین!$N$2:$N$366,7101,[1]فروردین!$D$2:$D$366,$F$4,[1]فروردین!$AA$2:$AA$366,U3) -> 0
A5: 1 | F5: حیدری | G5: =SUM(O5:T5) -> 0 | H5: =U5 -> 0 | I5: =SUMIFS([1]فروردین!$AF$27:$AF$157,[1]فروردین!$D$27:$D$157,F5) -> 70 | J5: 0 | K5: 0 | L5: 0 | M5: =SUM(G4:G6)+SUM(H4:H6)+SUM(I4:I6)+SUM(L4:L6)+SUM(K4:K6)-D4 -> 7.5 | O5: =SUMIFS([1]فروردین!$AD$2:$AD$366,[1]فروردین!$N$2:$N$366,7101,[1]فروردین!$D$2:$D$366,$F$5,[1]فروردین!$AA$2:$AA$366,O3) -> 0 | P5: =SUMIFS([1]فروردین!$AD$2:$AD$366,[1]فروردین!$N$2:$N$366,7101,[1]فروردین!$D$2:$D$366,$F$5,[1]فروردین!$AA$2:$AA$366,P3) -> 0 | Q5: =SUMIFS([1]فروردین!$AD$2:$AD$366,[1]فروردین!$N$2:$N$366,7101,[1]فروردین!$D$2:$D$366,$F$5,[1]فروردین!$AA$2:$AA$366,Q3) -> 0 | R5: =SUMIFS([1]فروردین!$AD$2:$AD$366,[1]فروردین!$N$2:$N$366,7101,[1]فروردین!$D$2:$D$366,$F$5,[1]فروردین!$AA$2:$AA$366,R3) -> 0 | S5: =SUMIFS([1]فروردین!$AD$2:$AD$366,[1]فروردین!$N$2:$N$366,7101,[1]فروردین!$D$2:$D$366,$F$5,[1]فروردین!$AA$2:$AA$366,S3) -> 0 | T5: =SUMIFS([1]فروردین!$AD$2:$AD$366,[1]فروردین!$N$2:$N$366,7101,[1]فروردین!$D$2:$D$366,$F$5,[1]فروردین!$AA$2:$AA$366,T3) -> 0 | U5: =SUMIFS([1]فروردین!$AD$2:$AD$366,[1]فروردین!$N$2:$N$366,7101,[1]فروردین!$D$2:$D$366,$F$5,[1]فروردین!$AA$2:$AA$366,U3) -> 0
G6: =SUM(O6:T6) -> 0 | H6: =U6 -> 0 | I6: =SUMIFS([1]فروردین!$AF$27:$AF$157,[1]فروردین!$D$27:$D$157,F6) -> 0 | J6: 0 | K6: 0 | L6: 0 | O6: =SUMIFS([1]فروردین!$AD$2:$AD$366,[1]فروردین!$N$2:$N$366,7101,[1]فروردین!$D$2:$D$366,$F$6,[1]فروردین!$AA$2:$AA$366,O3) -> 0 | P6: =SUMIFS([1]فروردین!$AD$2:$AD$366,[1]فروردین!$N$2:$N$366,7101,[1]فروردین!$D$2:$D$366,$F$6,[1]فروردین!$AA$2:$AA$366,P3) -> 0 | Q6: =SUMIFS([1]فروردین!$AD$2:$AD$366,[1]فروردین!$N$2:$N$366,7101,[1]فروردین!$D$2:$D$366,$F$6,[1]فروردین!$AA$2:$AA$366,Q3) -> 0 | R6: =SUMIFS([1]فروردین!$AD$2:$AD$366,[1]فروردین!$N$2:$N$366,7101,[1]فروردین!$D$2:$D$366,$F$6,[1]فروردین!$AA$2:$AA$366,R3) -> 0 | S6: =SUMIFS([1]فروردین!$AD$2:$AD$366,[1]فروردین!$N$2:$N$366,7101,[1]فروردین!$D$2:$D$366,$F$6,[1]فروردین!$AA$2:$AA$366,S3) -> 0 | T6: =SUMIFS([1]فروردین!$AD$2:$AD$366,[1]فروردین!$N$2:$N$366,7101,[1]فروردین!$D$2:$D$366,$F$6,[1]فروردین!$AA$2:$AA$366,T3) -> 0 | U6: =SUMIFS([1]فروردین!$AD$2:$AD$366,[1]فروردین!$N$2:$N$366,7101,[1]فروردین!$D$2:$D$366,$F$6,[1]فروردین!$AA$2:$AA$366,U3) -> 0
B7: فرز | C7: 7102 | D7: 62.5 | E7: سالم | G7: =SUM(O7:T7) -> 0 | H7: =U7 -> 0 | I7: =SUMIFS([1]فروردین!$AF$27:$AF$157,[1]فروردین!$D$27:$D$157,F7) -> 0 | J7: 0 | K7: 0 | L7: 0 | O7: =SUMIFS([1]فروردین!$AD$2:$AD$366,[1]فروردین!$N$2:$N$366,7102,[1]فروردین!$D$2:$D$366,$F$7,[1]فروردین!$AA$2:$AA$366,O3) -> 0 | P7: =SUMIFS([1]فروردین!$AD$2:$AD$366,[1]فروردین!$N$2:$N$366,7102,[1]فروردین!$D$2:$D$366,$F$7,[1]فروردین!$AA$2:$AA$366,P3) -> 0 | Q7: =SUMIFS([1]فروردین!$AD$2:$AD$366,[1]فروردین!$N$2:$N$366,7102,[1]فروردین!$D$2:$D$366,$F$7,[1]فروردین!$AA$2:$AA$366,Q3) -> 0 | R7: =SUMIFS([1]فروردین!$AD$2:$AD$366,[1]فروردین!$N$2:$N$366,7102,[1]فروردین!$D$2:$D$366,$F$7,[1]فروردین!$AA$2:$AA$366,R3) -> 0 | S7: =SUMIFS([1]فروردین!$AD$2:$AD$366,[1]فروردین!$N$2:$N$366,7102,[1]فروردین!$D$2:$D$366,$F$7,[1]فروردین!$AA$2:$AA$366,S3) -> 0 | T7: =SUMIFS([1]فروردین!$AD$2:$AD$366,[1]فروردین!$N$2:$N$366,7102,[1]فروردین!$D$2:$D$366,$F$7,[1]فروردین!$AA$2:$AA$366,T3) -> 0 | U7: =SUMIFS([1]فروردین!$AD$2:$AD$366,[1]فروردین!$N$2:$N$366,7102,[1]فروردین!$D$2:$D$366,$F$7,[1]فروردین!$AA$2:$AA$366,U3) -> 0
A8: 2 | G8: =SUM(O8:T8) -> 0 | H8: =U8 -> 0 | I8: =SUMIFS([1]فروردین!$AF$27:$AF$157,[1]فروردین!$D$27:$D$157,F8) -> 0 | J8: 0 | K8: 0 | L8: 0 | M8: =SUM(G7:G9)+SUM(H7:H9)+SUM(I7:I9)+SUM(J7:J9)+SUM(K7:K9)+SUM(L7:L9)-D7 -> -62.5 | N8: ⑥ | O8: =SUMIFS([1]فروردین!$AD$2:$AD$366,[1]فروردین!$N$2:$N$366,7102,[1]فروردین!$D$2:$D$366,$F$8,[1]فروردین!$AA$2:$AA$366,O3) -> 0 | P8: =SUMIFS([1]فروردین!$AD$2:$AD$366,[1]فروردین!$N$2:$N$366,7102,[1]فروردین!$D$2:$D$366,$F$8,[1]فروردین!$AA$2:$AA$366,P3) -> 0 | Q8: =SUMIFS([1]فروردین!$AD$2:$AD$366,[1]فروردین!$N$2:$N$366,7102,[1]فروردین!$D$2:$D$366,$F$8,[1]فروردین!$AA$2:$AA$366,Q3) -> 0 | R8: =SUMIFS([1]فروردین!$AD$2:$AD$366,[1]فروردین!$N$2:$N$366,7102,[1]فروردین!$D$2:$D$366,$F$8,[1]فروردین!$AA$2:$AA$366,R3) -> 0 | S8: =SUMIFS([1]فروردین!$AD$2:$AD$366,[1]فروردین!$N$2:$N$366,7102,[1]فروردین!$D$2:$D$366,$F$8,[1]فروردین!$AA$2:$AA$366,S3) -> 0 | T8: =SUMIFS([1]فروردین!$AD$2:$AD$366,[1]فروردین!$N$2:$N$366,7102,[1]فروردین!$D$2:$D$366,$F$8,[1]فروردین!$AA$2:$AA$366,T3) -> 0 | U8: =SUMIFS([1]فروردین!$AD$2:$AD$366,[1]فروردین!$N$2:$N$366,7102,[1]فروردین!$D$2:$D$366,$F$8,[1]فروردین!$AA$2:$AA$366,U3) -> 0
G9: =SUM(O9:T9) -> 0 | H9: =U9 -> 0 | I9: =SUMIFS([1]فروردین!$AF$27:$AF$157,[1]فروردین!$D$27:$D$157,F9) -> 0 | J9: 0 | K9: 0 | L9: 0 | O9: =SUMIFS([1]فروردین!$AD$2:$AD$366,[1]فروردین!$N$2:$N$366,7102,[1]فروردین!$D$2:$D$366,$F$9,[1]فروردین!$AA$2:$AA$366,O3) -> 0 | P9: =SUMIFS([1]فروردین!$AD$2:$AD$366,[1]فروردین!$N$2:$N$366,7102,[1]فروردین!$D$2:$D$366,$F$9,[1]فروردین!$AA$2:$AA$366,P3) -> 0 | Q9: =SUMIFS([1]فروردین!$AD$2:$AD$366,[1]فروردین!$N$2:$N$366,7102,[1]فروردین!$D$2:$D$366,$F$9,[1]فروردین!$AA$2:$AA$366,Q3) -> 0 | R9: =SUMIFS([1]فروردین!$AD$2:$AD$366,[1]فروردین!$N$2:$N$366,7102,[1]فروردین!$D$2:$D$366,$F$9,[1]فروردین!$AA$2:$AA$366,R3) -> 0 | S9: =SUMIFS([1]فروردین!$AD$2:$AD$366,[1]فروردین!$N$2:$N$366,7102,[1]فروردین!$D$2:$D$366,$F$9,[1]فروردین!$AA$2:$AA$366,S3) -> 0 | T9: =SUMIFS([1]فروردین!$AD$2:$AD$366,[1]فروردین!$N$2:$N$366,7102,[1]فروردین!$D$2:$D$366,$F$9,[1]فروردین!$AA$2:$AA$366,T3) -> 0 | U9: =SUMIFS([1]فروردین!$AD$2:$AD$366,[1]فروردین!$N$2:$N$366,7102,[1]فروردین!$D$2:$D$366,$F$9,[1]فروردین!$AA$2:$AA$366,U3) -> 0
A10: 3 | B10: فرز | C10: 7103 | D10: 62.5 | E10: سالم | G10: =SUM(O10:T10) -> 0 | H10: =U10 -> 0 | I10: =SUMIFS([1]فروردین!$AF$27:$AF$157,[1]فروردین!$D$27:$D$157,F10) -> 0 | J10: 0 | K10: 0 | L10: 0 | M10: =SUM(G10:L10)-64 -> -64 | N10: ① | O10: =SUMIFS([1]فروردین!$AD$2:$AD$366,[1]فروردین!$N$2:$N$366,7103,[1]فروردین!$D$2:$D$366,$F$10,[1]فروردین!$AA$2:$AA$366,O3) -> 0 | P10: =SUMIFS([1]فروردین!$AD$2:$AD$366,[1]فروردین!$N$2:$N$366,7103,[1]فروردین!$D$2:$D$366,$F$10,[1]فروردین!$AA$2:$AA$366,P3) -> 0 | Q10: =SUMIFS([1]فروردین!$AD$2:$AD$366,[1]فروردین!$N$2:$N$366,7103,[1]فروردین!$D$2:$D$366,$F$10,[1]فروردین!$AA$2:$AA$366,Q3) -> 0 | R10: =SUMIFS([1]فروردین!$AD$2:$AD$366,[1]فروردین!$N$2:$N$366,7103,[1]فروردین!$D$2:$D$366,$F$10,[1]فروردین!$AA$2:$AA$366,R3) -> 0 | S10: =SUMIFS([1]فروردین!$AD$2:$AD$366,[1]فروردین!$N$2:$N$366,7103,[1]فروردین!$D$2:$D$366,$F$10,[1]فروردین!$AA$2:$AA$366,S3) -> 0 | T10: =SUMIFS([1]فروردین!$AD$2:$AD$366,[1]فروردین!$N$2:$N$366,7103,[1]فروردین!$D$2:$D$366,$F$10,[1]فروردین!$AA$2:$AA$366,T3) -> 0 | U10: =SUMIFS([1]فروردین!$AD$2:$AD$366,[1]فروردین!$N$2:$N$366,7103,[1]فروردین!$D$2:$D$366,$F$10,[1]فروردین!$AA$2:$AA$366,U3) -> 0
A11: 4 | B11: CNC | C11: 7201 | D11: 62.5 | E11: خراب | G11: =SUM(O11:T11) -> 0 | H11: =U11 -> 0 | I11: =SUMIFS([1]فروردین!$AF$27:$AF$157,[1]فروردین!$D$27:$D$157,F11) -> 0 | J11: 62 | K11: 0 | L11: 0 | M11: =SUM(G11:J11)-62 -> 0 | N11: ⑤ ③
A12: 5 | B12: CNC | C12: 7202 | D12: 62.5 | E12: سالم | F12: قیطاسوند | G12: =SUM(O12:T12) -> 0 | H12: =U12 -> 0 | I12: =SUMIFS([1]فروردین!$AF$27:$AF$157,[1]فروردین!$D$27:$D$157,F12) -> 61 | J12: 0 | K12: 0 | L12: 0 | M12: =SUM(G12:L12)-62 -> -1 | N12: ② | O12: =SUMIFS([1]فروردین!$AD$2:$AD$366,[1]فروردین!$N$2:$N$366,$C$12,[1]فروردین!$D$2:$D$366,$F$12,[1]فروردین!$AA$2:$AA$366,O3) -> 0 | P12: =SUMIFS([1]فروردین!$AD$2:$AD$366,[1]فروردین!$N$2:$N$366,$C$12,[1]فروردین!$D$2:$D$366,$F$12,[1]فروردین!$AA$2:$AA$366,P3) -> 0 | Q12: =SUMIFS([1]فروردین!$AD$2:$AD$366,[1]فروردین!$N$2:$N$366,$C$12,[1]فروردین!$D$2:$D$366,$F$12,[1]فروردین!$AA$2:$AA$366,Q3) -> 0 | R12: =SUMIFS([1]فروردین!$AD$2:$AD$366,[1]فروردین!$N$2:$N$366,$C$12,[1]فروردین!$D$2:$D$366,$F$12,[1]فروردین!$AA$2:$AA$366,R3) -> 0 | S12: =SUMIFS([1]فروردین!$AD$2:$AD$366,[1]فروردین!$N$2:$N$366,$C$12,[1]فروردین!$D$2:$D$366,$F$12,[1]فروردین!$AA$2:$AA$366,S3) -> 0 | T12: =SUMIFS([1]فروردین!$AD$2:$AD$366,[1]فروردین!$N$2:$N$366,$C$12,[1]فروردین!$D$2:$D$366,$F$12,[1]فروردین!$AA$2:$AA$366,T3) -> 0 | U12: =SUMIFS([1]فروردین!$AD$2:$AD$366,[1]فروردین!$N$2:$N$366,$C$12,[1]فروردین!$D$2:$D$366,$F$12,[1]فروردین!$AA$2:$AA$366,U3) -> 0
A13: 6 | B13: CNC | C13: 7203 | D13: 62.5 | E13: سالم | G13: =SUM(O13:T13) -> 0 | H13: =U13 -> 0 | I13: =SUMIFS([1]فروردین!$AF$27:$AF$157,[1]فروردین!$D$27:$D$157,F13) -> 0 | J13: 0 | K13: 0 | L13: 0 | M13: =(G13+H13+I13+J13+K13)-D13 -> -62.5 | O13: =SUMIFS([1]فروردین!$AD$2:$AD$366,[1]فروردین!$N$2:$N$366,$C$13,[1]فروردین!$D$2:$D$366,$F$13,[1]فروردین!$AA$2:$AA$366,O3) -> 0 | P13: =SUMIFS([1]فروردین!$AD$2:$AD$366,[1]فروردین!$N$2:$N$366,$C$13,[1]فروردین!$D$2:$D$366,$F$13,[1]فروردین!$AA$2:$AA$366,P3) -> 0 | Q13: =SUMIFS([1]فروردین!$AD$2:$AD$366,[1]فروردین!$N$2:$N$366,$C$13,[1]فروردین!$D$2:$D$366,$F$13,[1]فروردین!$AA$2:$AA$366,Q3) -> 0 | R13: =SUMIFS([1]فروردین!$AD$2:$AD$366,[1]فروردین!$N$2:$N$366,$C$13,[1]فروردین!$D$2:$D$366,$F$13,[1]فروردین!$AA$2:$AA$366,R3) -> 0 | S13: =SUMIFS([1]فروردین!$AD$2:$AD$366,[1]فروردین!$N$2:$N$366,$C$13,[1]فروردین!$D$2:$D$366,$F$13,[1]فروردین!$AA$2:$AA$366,S3) -> 0 | T13: =SUMIFS([1]فروردین!$AD$2:$AD$366,[1]فروردین!$N$2:$N$366,$C$13,[1]فروردین!$D$2:$D$366,$F$13,[1]فروردین!$AA$2:$AA$366,T3) -> 0 | U13: =SUMIFS([1]فروردین!$AD$2:$AD$366,[1]فروردین!$N$2:$N$366,$C$13,[1]فروردین!$D$2:$D$366,$F$13,[1]فروردین!$AA$2:$AA$366,U3) -> 0
A14: 7 | B14: CNC | C14: 7204 | D14: 62.5 | E14: سالم | G14: =SUM(O14:T14) -> 0 | H14: =U14 -> 0 | I14: =SUMIFS([1]فروردین!$AF$27:$AF$157,[1]فروردین!$D$27:$D$157,F14) -> 0 | J14: 0 | K14: 0 | L14: 0 | M14: =SUM(G14:J14)-62 -> -62 | O14: =SUMIFS([1]فروردین!$AD$2:$AD$366,[1]فروردین!$N$2:$N$366,$C$14,[1]فروردین!$D$2:$D$366,$F$14,[1]فروردین!$AA$2:$AA$366,O3) -> 0 | P14: =SUMIFS([1]فروردین!$AD$2:$AD$366,[1]فروردین!$N$2:$N$366,$C$14,[1]فروردین!$D$2:$D$366,$F$14,[1]فروردین!$AA$2:$AA$366,P3) -> 0 | Q14: =SUMIFS([1]فروردین!$AD$2:$AD$366,[1]فروردین!$N$2:$N$366,$C$14,[1]فروردین!$D$2:$D$366,$F$14,[1]فروردین!$AA$2:$AA$366,Q3) -> 0 | R14: =SUMIFS([1]فروردین!$AD$2:$AD$366,[1]فروردین!$N$2:$N$366,$C$14,[1]فروردین!$D$2:$D$366,$F$14,[1]فروردین!$AA$2:$AA$366,R3) -> 0 | S14: =SUMIFS([1]فروردین!$AD$2:$AD$366,[1]فروردین!$N$2:$N$366,$C$14,[1]فروردین!$D$2:$D$366,$F$14,[1]فروردین!$AA$2:$AA$366,S3) -> 0 | T14: =SUMIFS([1]فروردین!$AD$2:$AD$366,[1]فروردین!$N$2:$N$366,$C$14,[1]فروردین!$D$2:$D$366,$F$14,[1]فروردین!$AA$2:$AA$366,T3) -> 0 | U14: =SUMIFS([1]فروردین!$AD$2:$AD$366,[1]فروردین!$N$2:$N$366,$C$14,[1]فروردین!$D$2:$D$366,$F$14,[1]فروردین!$AA$2:$AA$366,U3) -> 0
A15: 8 | B15: تراش | C15: 7301 | D15: 62.5 | E15: سالم | F15: کریم پرست | G15: =SUM(O15:T15) -> 0 | H15: =U15 -> 0 | I15: =SUMIFS([1]فروردین!$AF$27:$AF$157,[1]فروردین!$D$27:$D$157,F15) -> 59.5 | J15: 0 | K15: 0 | L15: 0 | M15: =SUM(G15:L15)-D15 -> -3 | N15: ② | O15: =SUMIFS([1]فروردین!$AD$2:$AD$366,[1]فروردین!$N$2:$N$366,$C$15,[1]فروردین!$D$2:$D$366,$F$15,[1]فروردین!$AA$2:$AA$366,O3) -> 0 | P15: =SUMIFS([1]فروردین!$AD$2:$AD$366,[1]فروردین!$N$2:$N$366,$C$15,[1]فروردین!$D$2:$D$366,$F$15,[1]فروردین!$AA$2:$AA$366,P3) -> 0 | Q15: =SUMIFS([1]فروردین!$AD$2:$AD$366,[1]فروردین!$N$2:$N$366,$C$15,[1]فروردین!$D$2:$D$366,$F$15,[1]فروردین!$AA$2:$AA$366,Q3) -> 0 | R15: =SUMIFS([1]فروردین!$AD$2:$AD$366,[1]فروردین!$N$2:$N$366,$C$15,[1]فروردین!$D$2:$D$366,$F$15,[1]فروردین!$AA$2:$AA$366,R3) -> 0 | S15: =SUMIFS([1]فروردین!$AD$2:$AD$366,[1]فروردین!$N$2:$N$366,$C$15,[1]فروردین!$D$2:$D$366,$F$15,[1]فروردین!$AA$2:$AA$366,S3) -> 0 | T15: =SUMIFS([1]فروردین!$AD$2:$AD$366,[1]فروردین!$N$2:$N$366,$C$15,[1]فروردین!$D$2:$D$366,$F$15,[1]فروردین!$AA$2:$AA$366,T3) -> 0 | U15: =SUMIFS([1]فروردین!$AD$2:$AD$366,[1]فروردین!$N$2:$N$366,$C$15,[1]فروردین!$D$2:$D$366,$F$15,[1]فروردین!$AA$2:$AA$366,U3) -> 0
A16: 9 | B16: تراش | C16: 7302 | D16: 62.5 | E16: سالم | G16: =SUM(O16:T16) -> 0 | H16: =U16 -> 0 | I16: =SUMIFS([1]فروردین!$AF$27:$AF$157,[1]فروردین!$D$27:$D$157,F16) -> 0 | J16: 0 | K16: 0 | L16: 0 | N16: ② | O16: =SUMIFS([1]فروردین!$AD$2:$AD$366,[1]فروردین!$N$2:$N$366,$C$16,[1]فروردین!$D$2:$D$366,$F$16,[1]فروردین!$AA$2:$AA$366,O3) -> 0 | P16: =SUMIFS([1]فروردین!$AD$2:$AD$366,[1]فروردین!$N$2:$N$366,$C$16,[1]فروردین!$D$2:$D$366,$F$16,[1]فروردین!$AA$2:$AA$366,P3) -> 0 | Q16: =SUMIFS([1]فروردین!$AD$2:$AD$366,[1]فروردین!$N$2:$N$366,$C$16,[1]فروردین!$D$2:$D$366,$F$16,[1]فروردین!$AA$2:$AA$366,Q3) -> 0 | R16: =SUMIFS([1]فروردین!$AD$2:$AD$366,[1]فروردین!$N$2:$N$366,$C$16,[1]فروردین!$D$2:$D$366,$F$16,[1]فروردین!$AA$2:$AA$366,R3) -> 0 | S16: =SUMIFS([1]فروردین!$AD$2:$AD$366,[1]فروردین!$N$2:$N$366,$C$16,[1]فروردین!$D$2:$D$366,$F$16,[1]فروردین!$AA$2:$AA$366,S3) -> 0 | T16: =SUMIFS([1]فروردین!$AD$2:$AD$366,[1]فروردین!$N$2:$N$366,$C$16,[1]فروردین!$D$2:$D$366,$F$16,[1]فروردین!$AA$2:$AA$366,T3) -> 0 | U16: =SUMIFS([1]فروردین!$AD$2:$AD$366,[1]فروردین!$N$2:$N$366,$C$16,[1]فروردین!$D$2:$D$366,$F$16,[1]فروردین!$AA$2:$AA$366,U3) -> 0
F17: موسوی | G17: =SUM(O17:T17) -> 0 | H17: =U17 -> 0 | I17: =SUMIFS([1]فروردین!$AF$27:$AF$157,[1]فروردین!$D$27:$D$157,F17) -> 56.833333 | J17: 0 | K17: 0 | L17: 0 | M17: =SUM(G16:L18)-D16 -> -5.6666667 | O17: =SUMIFS([1]فروردین!$AD$2:$AD$366,[1]فروردین!$N$2:$N$366,$C$16,[1]فروردین!$D$2:$D$366,$F$17,[1]فروردین!$AA$2:$AA$366,O3) -> 0 | P17: =SUMIFS([1]فروردین!$AD$2:$AD$366,[1]فروردین!$N$2:$N$366,$C$16,[1]فروردین!$D$2:$D$366,$F$17,[1]فروردین!$AA$2:$AA$366,P3) -> 0 | Q17: =SUMIFS([1]فروردین!$AD$2:$AD$366,[1]فروردین!$N$2:$N$366,$C$16,[1]فروردین!$D$2:$D$366,$F$17,[1]فروردین!$AA$2:$AA$366,Q3) -> 0 | R17: =SUMIFS([1]فروردین!$AD$2:$AD$366,[1]فروردین!$N$2:$N$366,$C$16,[1]فروردین!$D$2:$D$366,$F$17,[1]فروردین!$AA$2:$AA$366,R3) -> 0 | S17: =SUMIFS([1]فروردین!$AD$2:$AD$366,[1]فروردین!$N$2:$N$366,$C$16,[1]فروردین!$D$2:$D$366,$F$17,[1]فروردین!$AA$2:$AA$366,S3) -> 0 | T17: =SUMIFS([1]فروردین!$AD$2:$AD$366,[1]فروردین!$N$2:$N$366,$C$16,[1]فروردین!$D$2:$D$366,$F$17,[1]فروردین!$AA$2:$AA$366,T3) -> 0 | U17: =SUMIFS([1]فروردین!$AD$2:$AD$366,[1]فروردین!$N$2:$N$366,$C$16,[1]فروردین!$D$2:$D$366,$F$17,[1]فروردین!$AA$2:$AA$366,U3) -> 0
G18: =SUM(O18:T18) -> 0 | H18: =U18 -> 0 | I18: =SUMIFS([1]فروردین!$AF$27:$AF$157,[1]فروردین!$D$27:$D$157,F18) -> 0 | J18: 0 | K18: 0 | L18: 0 | O18: =SUMIFS([1]فروردین!$AD$2:$AD$366,[1]فروردین!$N$2:$N$366,$C$16,[1]فروردین!$D$2:$D$366,$F$18,[1]فروردین!$AA$2:$AA$366,O3) -> 0 | P18: =SUMIFS([1]فروردین!$AD$2:$AD$366,[1]فروردین!$N$2:$N$366,$C$16,[1]فروردین!$D$2:$D$366,$F$18,[1]فروردین!$AA$2:$AA$366,P3) -> 0 | Q18: =SUMIFS([1]فروردین!$AD$2:$AD$366,[1]فروردین!$N$2:$N$366,$C$16,[1]فروردین!$D$2:$D$366,$F$18,[1]فروردین!$AA$2:$AA$366,Q3) -> 0 | R18: =SUMIFS([1]فروردین!$AD$2:$AD$366,[1]فروردین!$N$2:$N$366,$C$16,[1]فروردین!$D$2:$D$366,$F$18,[1]فروردین!$AA$2:$AA$366,R3) -> 0 | S18: =SUMIFS([1]فروردین!$AD$2:$AD$366,[1]فروردین!$N$2:$N$366,$C$16,[1]فروردین!$D$2:$D$366,$F$18,[1]فروردین!$AA$2:$AA$366,S3) -> 0 | T18: =SUMIFS([1]فروردین!$AD$2:$AD$366,[1]فروردین!$N$2:$N$366,$C$16,[1]فروردین!$D$2:$D$366,$F$18,[1]فروردین!$AA$2:$AA$366,T3) -> 0 | U18: =SUMIFS([1]فروردین!$AD$2:$AD$366,[1]فروردین!$N$2:$N$366,$C$16,[1]فروردین!$D$2:$D$366,$F$18,[1]فروردین!$AA$2:$AA$366,U3) -> 0
A19: 10 | B19: تراش | C19: 7303 | D19: 44 | E19: سالم | F19: صحرایی | G19: =SUM(O19:T19) -> 0 | H19: =U19 -> 0 | I19: =SUMIFS([1]فروردین!$AF$27:$AF$157,[1]فروردین!$D$27:$D$157,F19) -> 34.5 | J19: 0 | K19: 0 | L19: 0 | M19: =SUM(G19:L19)-44 -> -9.5 | N19: ② | O19: =SUMIFS([1]فروردین!$AD$2:$AD$366,[1]فروردین!$N$2:$N$366,$C$19,[1]فروردین!$D$2:$D$366,$F$19,[1]فروردین!$AA$2:$AA$366,O3) -> 0 | P19: =SUMIFS([1]فروردین!$AD$2:$AD$366,[1]فروردین!$N$2:$N$366,$C$19,[1]فروردین!$D$2:$D$366,$F$19,[1]فروردین!$AA$2:$AA$366,P3) -> 0 | Q19: =SUMIFS([1]فروردین!$AD$2:$AD$366,[1]فروردین!$N$2:$N$366,$C$19,[1]فروردین!$D$2:$D$366,$F$19,[1]فروردین!$AA$2:$AA$366,Q3) -> 0 | R19: =SUMIFS([1]فروردین!$AD$2:$AD$366,[1]فروردین!$N$2:$N$366,$C$19,[1]فروردین!$D$2:$D$366,$F$19,[1]فروردین!$AA$2:$AA$366,R3) -> 0 | S19: =SUMIFS([1]فروردین!$AD$2:$AD$366,[1]فروردین!$N$2:$N$366,$C$19,[1]فروردین!$D$2:$D$366,$F$19,[1]فروردین!$AA$2:$AA$366,S3) -> 0 | T19: =SUMIFS([1]فروردین!$AD$2:$AD$366,[1]فروردین!$N$2:$N$366,$C$19,[1]فروردین!$D$2:$D$366,$F$19,[1]فروردین!$AA$2:$AA$366,T3) -> 0 | U19: =SUMIFS([1]فروردین!$AD$2:$AD$366,[1]فروردین!$N$2:$N$366,$C$19,[1]فروردین!$D$2:$D$366,$F$19,[1]فروردین!$AA$2:$AA$366,U3) -> 0
A20: 11 | B20: دریل رادیال | C20: 7401 | D20: 62.5 | E20: سالم | F20: خیرخواه | G20: =SUM(O20:T20) -> 0 | H20: =U20 -> 0 | I20: =SUMIFS([1]فروردین!$AF$27:$AF$157,[1]فروردین!$D$27:$D$157,F20) -> 68 | J20: 0 | K20: 0 | L20: 0 | N20: ⑥ | O20: =SUMIFS([1]فروردین!$AD$2:$AD$366,[1]فروردین!$N$2:$N$366,$C$20,[1]فروردین!$D$2:$D$366,$F$20,[1]فروردین!$AA$2:$AA$366,O3) -> 0 | P20: =SUMIFS([1]فروردین!$AD$2:$AD$366,[1]فروردین!$N$2:$N$366,$C$20,[1]فروردین!$D$2:$D$366,$F$20,[1]فروردین!$AA$2:$AA$366,P3) -> 0 | Q20: =SUMIFS([1]فروردین!$AD$2:$AD$366,[1]فروردین!$N$2:$N$366,$C$20,[1]فروردین!$D$2:$D$366,$F$20,[1]فروردین!$AA$2:$AA$366,Q3) -> 0 | R20: =SUMIFS([1]فروردین!$AD$2:$AD$366,[1]فروردین!$N$2:$N$366,$C$20,[1]فروردین!$D$2:$D$366,$F$20,[1]فروردین!$AA$2:$AA$366,R3) -> 0 | S20: =SUMIFS([1]فروردین!$AD$2:$AD$366,[1]فروردین!$N$2:$N$366,$C$20,[1]فروردین!$D$2:$D$366,$F$20,[1]فروردین!$AA$2:$AA$366,S3) -> 0 | T20: =SUMIFS([1]فروردین!$AD$2:$AD$366,[1]فروردین!$N$2:$N$366,$C$20,[1]فروردین!$D$2:$D$366,$F$20,[1]فروردین!$AA$2:$AA$366,T3) -> 0 | U20: =SUMIFS([1]فروردین!$AD$2:$AD$366,[1]فروردین!$N$2:$N$366,$C$20,[1]فروردین!$D$2:$D$366,$F$20,[1]فروردین!$AA$2:$AA$366,U3) -> 0
F21: هاشم زاده | G21: =SUM(O21:T21) -> 0 | H21: =U21 -> 0 | I21: =SUMIFS([1]فروردین!$AF$27:$AF$157,[1]فروردین!$D$27:$D$157,F21) -> 44 | J21: 0 | K21: 0 | L21: 0 | M21: =SUM(G20:L22)-D20 -> 49.5 | O21: =SUMIFS([1]فروردین!$AD$2:$AD$366,[1]فروردین!$N$2:$N$366,$C$20,[1]فروردین!$D$2:$D$366,$F$21,[1]فروردین!$AA$2:$AA$366,O3) -> 0 | P21: =SUMIFS([1]فروردین!$AD$2:$AD$366,[1]فروردین!$N$2:$N$366,$C$20,[1]فروردین!$D$2:$D$366,$F$21,[1]فروردین!$AA$2:$AA$366,P3) -> 0 | Q21: =SUMIFS([1]فروردین!$AD$2:$AD$366,[1]فروردین!$N$2:$N$366,$C$20,[1]فروردین!$D$2:$D$366,$F$21,[1]فروردین!$AA$2:$AA$366,Q3) -> 0 | R21: =SUMIFS([1]فروردین!$AD$2:$AD$366,[1]فروردین!$N$2:$N$366,$C$20,[1]فروردین!$D$2:$D$366,$F$21,[1]فروردین!$AA$2:$AA$366,R3) -> 0 | S21: =SUMIFS([1]فروردین!$AD$2:$AD$366,[1]فروردین!$N$2:$N$366,$C$20,[1]فروردین!$D$2:$D$366,$F$21,[1]فروردین!$AA$2:$AA$366,S3) -> 0 | T21: =SUMIFS([1]فروردین!$AD$2:$AD$366,[1]فروردین!$N$2:$N$366,$C$20,[1]فروردین!$D$2:$D$366,$F$21,[1]فروردین!$AA$2:$AA$366,T3) -> 0 | U21: =SUMIFS([1]فروردین!$AD$2:$AD$366,[1]فروردین!$N$2:$N$366,$C$20,[1]فروردین!$D$2:$D$366,$F$21,[1]فروردین!$AA$2:$AA$366,U3) -> 0
G22: =SUM(O22:T22) -> 0 | H22: =U22 -> 0 | I22: =SUMIFS([1]فروردین!$AF$27:$AF$157,[1]فروردین!$D$27:$D$157,F22) -> 0 | J22: 0 | K22: 0 | L22: 0 | O22: =SUMIFS([1]فروردین!$AD$2:$AD$366,[1]فروردین!$N$2:$N$366,$C$22,[1]فروردین!$D$2:$D$366,$F$22,[1]فروردین!$AA$2:$AA$366,O3) -> 0 | P22: =SUMIFS([1]فروردین!$AD$2:$AD$366,[1]فروردین!$N$2:$N$366,$C$22,[1]فروردین!$D$2:$D$366,$F$22,[1]فروردین!$AA$2:$AA$366,P3) -> 0 | Q22: =SUMIFS([1]فروردین!$AD$2:$AD$366,[1]فروردین!$N$2:$N$366,$C$22,[1]فروردین!$D$2:$D$366,$F$22,[1]فروردین!$AA$2:$AA$366,Q3) -> 0 | R22: =SUMIFS([1]فروردین!$AD$2:$AD$366,[1]فروردین!$N$2:$N$366,$C$22,[1]فروردین!$D$2:$D$366,$F$22,[1]فروردین!$AA$2:$AA$366,R3) -> 0 | S22: =SUMIFS([1]فروردین!$AD$2:$AD$366,[1]فروردین!$N$2:$N$366,$C$22,[1]فروردین!$D$2:$D$366,$F$22,[1]فروردین!$AA$2:$AA$366,S3) -> 0 | T22: =SUMIFS([1]فروردین!$AD$2:$AD$366,[1]فروردین!$N$2:$N$366,$C$22,[1]فروردین!$D$2:$D$366,$F$22,[1]فروردین!$AA$2:$AA$366,T3) -> 0 | U22: =SUMIFS([1]فروردین!$AD$2:$AD$366,[1]فروردین!$N$2:$N$366,$C$22,[1]فروردین!$D$2:$D$366,$F$22,[1]فروردین!$AA$2:$AA$366,U3) -> 0
A23: 12 | B23: سنگ تخت | C23: 7501 | D23: 62.5 | E23: خراب | G23: =SUM(O23:T23) -> 0 | H23: =U23 -> 0 | I23: =SUMIFS([1]فروردین!$AF$27:$AF$157,[1]فروردین!$D$27:$D$157,F23) -> 0 | J23: 0 | K23: 0 | L23: 0 | N23: ③ | O23: =SUMIFS([1]فروردین!$AD$2:$AD$366,[1]فروردین!$N$2:$N$366,$C$23,[1]فروردین!$D$2:$D$366,$F$23,[1]فروردین!$AA$2:$AA$366,O3) -> 0 | P23: =SUMIFS([1]فروردین!$AD$2:$AD$366,[1]فروردین!$N$2:$N$366,$C$23,[1]فروردین!$D$2:$D$366,$F$23,[1]فروردین!$AA$2:$AA$366,P3) -> 0 | Q23: =SUMIFS([1]فروردین!$AD$2:$AD$366,[1]فروردین!$N$2:$N$366,$C$23,[1]فروردین!$D$2:$D$366,$F$23,[1]فروردین!$AA$2:$AA$366,Q3) -> 0 | R23: =SUMIFS([1]فروردین!$AD$2:$AD$366,[1]فروردین!$N$2:$N$366,$C$23,[1]فروردین!$D$2:$D$366,$F$23,[1]فروردین!$AA$2:$AA$366,R3) -> 0 | S23: =SUMIFS([1]فروردین!$AD$2:$AD$366,[1]فروردین!$N$2:$N$366,$C$23,[1]فروردین!$D$2:$D$366,$F$23,[1]فروردین!$AA$2:$AA$366,S3) -> 0 | T23: =SUMIFS([1]فروردین!$AD$2:$AD$366,[1]فروردین!$N$2:$N$366,$C$23,[1]فروردین!$D$2:$D$366,$F$23,[1]فروردین!$AA$2:$AA$366,T3) -> 0 | U23: =SUMIFS([1]فروردین!$AD$2:$AD$366,[1]فروردین!$N$2:$N$366,$C$23,[1]فروردین!$D$2:$D$366,$F$23,[1]فروردین!$AA$2:$AA$366,U3) -> 0
F24: یاراحمدی | G24: =SUM(O24:T24) -> 0 | H24: =U24 -> 0 | I24: =SUMIFS([1]فروردین!$AF$27:$AF$157,[1]فروردین!$D$27:$D$157,F24) -> 55 | J24: 0 | K24: 0 | L24: 0 | M24: =SUM(G23:L25)-D23 -> -7.5 | O24: =SUMIFS([1]فروردین!$AD$2:$AD$366,[1]فروردین!$N$2:$N$366,$C$23,[1]فروردین!$D$2:$D$366,$F$24,[1]فروردین!$AA$2:$AA$366,O3) -> 0 | P24: =SUMIFS([1]فروردین!$AD$2:$AD$366,[1]فروردین!$N$2:$N$366,$C$23,[1]فروردین!$D$2:$D$366,$F$24,[1]فروردین!$AA$2:$AA$366,P3) -> 0 | Q24: =SUMIFS([1]فروردین!$AD$2:$AD$366,[1]فروردین!$N$2:$N$366,$C$23,[1]فروردین!$D$2:$D$366,$F$24,[1]فروردین!$AA$2:$AA$366,Q3) -> 0 | R24: =SUMIFS([1]فروردین!$AD$2:$AD$366,[1]فروردین!$N$2:$N$366,$C$23,[1]فروردین!$D$2:$D$366,$F$24,[1]فروردین!$AA$2:$AA$366,R3) -> 0 | S24: =SUMIFS([1]فروردین!$AD$2:$AD$366,[1]فروردین!$N$2:$N$366,$C$23,[1]فروردین!$D$2:$D$366,$F$24,[1]فروردین!$AA$2:$AA$366,S3) -> 0 | T24: =SUMIFS([1]فروردین!$AD$2:$AD$366,[1]فروردین!$N$2:$N$366,$C$23,[1]فروردین!$D$2:$D$366,$F$24,[1]فروردین!$AA$2:$AA$366,T3) -> 0 | U24: =SUMIFS([1]فروردین!$AD$2:$AD$366,[1]فروردین!$N$2:$N$366,$C$23,[1]فروردین!$D$2:$D$366,$F$24,[1]فروردین!$AA$2:$AA$366,U3) -> 0
G25: =SUM(O25:T25) -> 0 | H25: =U25 -> 0 | I25: =SUMIFS([1]فروردین!$AF$27:$AF$157,[1]فروردین!$D$27:$D$157,F25) -> 0 | J25: 0 | K25: 0 | L25: 0 | O25: =SUMIFS([1]فروردین!$AD$2:$AD$366,[1]فروردین!$N$2:$N$366,$C$23,[1]فروردین!$D$2:$D$366,$F$25,[1]فروردین!$AA$2:$AA$366,O3) -> 0 | P25: =SUMIFS([1]فروردین!$AD$2:$AD$366,[1]فروردین!$N$2:$N$366,$C$23,[1]فروردین!$D$2:$D$366,$F$25,[1]فروردین!$AA$2:$AA$366,P3) -> 0 | Q25: =SUMIFS([1]فروردین!$AD$2:$AD$366,[1]فروردین!$N$2:$N$366,$C$23,[1]فروردین!$D$2:$D$366,$F$25,[1]فروردین!$AA$2:$AA$366,Q3) -> 0 | R25: =SUMIFS([1]فروردین!$AD$2:$AD$366,[1]فروردین!$N$2:$N$366,$C$23,[1]فروردین!$D$2:$D$366,$F$25,[1]فروردین!$AA$2:$AA$366,R3) -> 0 | S25: =SUMIFS([1]فروردین!$AD$2:$AD$366,[1]فروردین!$N$2:$N$366,$C$23,[1]فروردین!$D$2:$D$366,$F$25,[1]فروردین!$AA$2:$AA$366,S3) -> 0 | T25: =SUMIFS([1]فروردین!$AD$2:$AD$366,[1]فروردین!$N$2:$N$366,$C$23,[1]فروردین!$D$2:$D$366,$F$25,[1]فروردین!$AA$2:$AA$366,T3) -> 0 | U25: =SUMIFS([1]فروردین!$AD$2:$AD$366,[1]فروردین!$N$2:$N$366,$C$23,[1]فروردین!$D$2:$D$366,$F$25,[1]فروردین!$AA$2:$AA$366,U3) -> 0
